Workbook

Sheet InputsNZ
A1: Approximate Equalities
C2: units | D2: Cycle 1 | E2: σ | F2: Cycle 2 | G2: σ | H2: Cycle 3 | I2: σ | J2: Cycle 4 | K2: σ | L2: Cycle 5 | M2: σ
A3: 1 | B3: NPP (14C) | C3: (mmol N m-2 d-1) | D3: 6.9751396 | E3: 2.1054147 | F3: 4.0433304 | G3: 0.782773 | H3: 9.8238143 | I3: 4.5503874 | J3: 5.6894075 | K3: 1.2846958 | L3: 3.1620202 | M3: 0.38276057
A4: 2 | B4: SedTrap Flux (shallow) | C4: (mmol N m-2 d-1) | D4: 0.97868813 | E4: 0.20023276 | F4: 1.634325 | G4: 0.056975159 | H4: 0.46955162 | I4: 0.029864707 | J4: 1.78897 | K4: 0.59585481 | L4: 0.4195884 | M4: 0.18168493
A5: 3 | B5: Pico NPP | C5: (mmol N m-2 d-1) | D5: =D3*NZ_Extra!D6 -> 2.1257041 | E5: =D5*SQRT((E3/D3)^2+(NZ_Extra!E6/NZ_Extra!D6)^2) -> 1.5292454 | F5: =F3*NZ_Extra!F6 -> 3.0867581 | G5: =F5*SQRT((G3/F3)^2+(NZ_Extra!G6/NZ_Extra!F6)^2) -> 0.91836993 | H5: =H3*NZ_Extra!H6 -> 6.4892367 | I5: =H5*SQRT((I3/H3)^2+(NZ_Extra!I6/NZ_Extra!H6)^2) -> 4.7574096 | J5: =J3*NZ_Extra!J6 -> 3.4570988 | K5: =J5*SQRT((K3/J3)^2+(NZ_Extra!K6/NZ_Extra!J6)^2) -> 2.235291 | L5: =L3*NZ_Extra!L6 -> 2.8354624 | M5: =L5*SQRT((M3/L3)^2+(NZ_Extra!M6/NZ_Extra!L6)^2) -> 3.809041
A6: 4 | B6: Flag NPP | C6: (mmol N m-2 d-1) | D6: =D3*NZ_Extra!D7 -> 1.6509193 | E6: =D6*SQRT((E3/D3)^2+(NZ_Extra!E7/NZ_Extra!D7)^2) -> 0.83512694 | F6: =F3*NZ_Extra!F7 -> 0.3456774 | G6: =F6*SQRT((G3/F3)^2+(NZ_Extra!G7/NZ_Extra!F7)^2) -> 0.50067474 | H6: =H3*NZ_Extra!H7 -> 2.7169 | I6: =H6*SQRT((I3/H3)^2+(NZ_Extra!I7/NZ_Extra!H7)^2) -> 3.3405852 | J6: =J3*NZ_Extra!J7 -> 1.9849115 | K6: =J6*SQRT((K3/J3)^2+(NZ_Extra!K7/NZ_Extra!J7)^2) -> 1.9757686 | L6: =L3*NZ_Extra!L7 -> 0.16239399 | M6: =L6*SQRT((M3/L3)^2+(NZ_Extra!M7/NZ_Extra!L7)^2) -> 3.4118451
A7: 5 | B7: Diatom NPP | C7: (mmol N m-2 d-1) | D7: =D3*NZ_Extra!D8 -> 3.1985162 | E7: =D7*SQRT((E3/D3)^2+(NZ_Extra!E8/NZ_Extra!D8)^2) -> 2.0384171 | F7: =F3*NZ_Extra!F8 -> 0.36121242 | G7: =F7*SQRT((G3/F3)^2+(NZ_Extra!G8/NZ_Extra!F8)^2) -> 0.23417384 | H7: =H3*NZ_Extra!H8 -> 0.61767758 | I7: =H7*SQRT((I3/H3)^2+(NZ_Extra!I8/NZ_Extra!H8)^2) -> 0.56187448 | J7: =J3*NZ_Extra!J8 -> 0.24739712 | K7: =J7*SQRT((K3/J3)^2+(NZ_Extra!K8/NZ_Extra!J8)^2) -> 0.15495822 | L7: =L3*NZ_Extra!L8 -> 0.16416388 | M7: =L7*SQRT((M3/L3)^2+(NZ_Extra!M8/NZ_Extra!L8)^2) -> 0.21488912
A8: 6 | B8: Picophyto Mortality | C8: (mmol N m-2 d-1) | D8: =D11*NZ_Extra!D14 -> 0.96803779 | E8: =D8*SQRT((E11/D11)^2+(NZ_Extra!E14/NZ_Extra!D14)^2) -> 0.77464728 | F8: =F11*NZ_Extra!F14 -> 1.8898784 | G8: =F8*SQRT((G11/F11)^2+(NZ_Extra!G14/NZ_Extra!F14)^2) -> 0.73034638 | H8: =H11*NZ_Extra!H14 -> 3.4956498 | I8: =H8*SQRT((I11/H11)^2+(NZ_Extra!I14/NZ_Extra!H14)^2) -> 2.5146744 | J8: =J11*NZ_Extra!J14 -> 2.1195066 | K8: =J8*SQRT((K11/J11)^2+(NZ_Extra!K14/NZ_Extra!J14)^2) -> 1.2931693 | L8: =L11*NZ_Extra!L14 -> 1.249681 | M8: =L8*SQRT((M11/L11)^2+(NZ_Extra!M14/NZ_Extra!L14)^2) -> 0.93631571
A9: 7 | B9: Flagellate Mortality | C9: (mmol N m-2 d-1) | D9: =D11*NZ_Extra!D15 -> 0.93107774 | E9: =D9*SQRT((E11/D11)^2+(NZ_Extra!E15/NZ_Extra!D15)^2) -> 1.0527763 | F9: =F11*NZ_Extra!F15 -> 0.484364 | G9: =F9*SQRT((G11/F11)^2+(NZ_Extra!G15/NZ_Extra!F15)^2) -> 0.53471732 | H9: =H11*NZ_Extra!H15 -> 1.5734107 | I9: =H9*SQRT((I11/H11)^2+(NZ_Extra!I15/NZ_Extra!H15)^2) -> 1.7854607 | J9: =J11*NZ_Extra!J15 -> 2.2956994 | K9: =J9*SQRT((K11/J11)^2+(NZ_Extra!K15/NZ_Extra!J15)^2) -> 1.4378622 | L9: =L11*NZ_Extra!L15 -> 1.5922616 | M9: =L9*SQRT((M11/L11)^2+(NZ_Extra!M15/NZ_Extra!L15)^2) -> 2.3670614
A10: 8 | B10: Diatom Mortality | C10: (mmol N m-2 d-1) | D10: =D11*NZ_Extra!D16 -> 1.6100342 | E10: =D10*SQRT((E11/D11)^2+(NZ_Extra!E16/NZ_Extra!D16)^2) -> 1.1415465 | F10: =F11*NZ_Extra!F16 -> 0.0831399 | G10: =F10*SQRT((G11/F11)^2+(NZ_Extra!G16/NZ_Extra!F16)^2) -> 0.034881401 | H10: =H11*NZ_Extra!H16 -> 0.30286348 | I10: =H10*SQRT((I11/H11)^2+(NZ_Extra!I16/NZ_Extra!H16)^2) -> 0.26697517 | J10: =J11*NZ_Extra!J16 -> 0.18752559 | K10: =J10*SQRT((K11/J11)^2+(NZ_Extra!K16/NZ_Extra!J16)^2) -> 0.12099696 | L10: =L11*NZ_Extra!L16 -> 0.1359202 | M10: =L10*SQRT((M11/L11)^2+(NZ_Extra!M16/NZ_Extra!L16)^2) -> 0.13470708
A11: 9 | B11: Protistan Grazing Rate (14C) | C11: (mmol N m-2 d-1) | D11: 3.5091497 | E11: 1.264978 | F11: 2.6936632 | G11: 0.60951549 | H11: 5.371924 | I11: 2.9742856 | J11: 4.6027316 | K11: 2.1767591 | L11: 2.9778627 | M11: 0.86612577
A12: 10 | B12: Mesozoo Grazing | C12: (mmol N m-2 d-1) | D12: 0.90936712 | E12: 0.18438144 | F12: 0.69786875 | G12: 0.33083743 | H12: 0.24256809 | I12: 0.099091056 | J12: 0.326373 | K12: 0.1143953 | L12: 0.3026578 | M12: 0.16079582
A13: 11 | B13: VMMeso Grazing | C13: (mmol N m-2 d-1) | D13: NA | E13: NA | F13: 0.37867569 | G13: 0.22091414 | H13: 0.13229504 | I13: 0.038642116 | J13: 0.073472457 | K13: 0.10700278 | L13: 0.2096015 | M13: 0.12952208 | P13: =H11/SUM(H12:H15) -> 13.90799
A14: 12 | B14: Macrozoo Grazing | C14: (mmol N m-2 d-1) | D14: 0.027775614 | E14: 0.027788247 | F14: 0.033175155 | G14: 0.075474281 | H14: 0.0078424367 | I14: 0.011119541 | J14: 0.011164564 | K14: 0.01411272 | L14: 0.024892997 | M14: 0.025748037
A15: 13 | B15: VMMacro Grazing | C15: (mmol N m-2 d-1) | D15: 0.0088005357 | E15: 0.012670302 | F15: 0.020797253 | G15: 0.047029264 | H15: 0.0035417564 | I15: 0.0067117834 | J15: 0.0031993794 | K15: 0.0095212134 | L15: 8.8802004e-05 | M15: 0.012747025
A16: 14 | B16: Salp Autotroph Grazing | C16: (mmol N m-2 d-1) | D16: 2.6592087 | E16: 1.9074743 | F16: 1.7577646 | G16: 0.91975507 | H16: 0.024739266 | I16: 0.028097449 | J16: 1.5968294 | K16: 0.97512047 | L16: 0.0072143977 | M16: 0.016218315
A17: 15 | B17: Salp Heterotroph Grazing | C17: (mmol N m-2 d-1) | D17: =(D16/0.58499)*0.41501 -> 1.8865249 | E17: =D17*SQRT((E16/D16)^2+(0.17843/0.58499)^2+(0.17843/0.41501)^2) -> 1.6793412 | F17: =(F16/0.95928)*0.4072 -> 0.74614477 | G17: =F17*SQRT((G16/F16)^2+(0.30768/0.95928)^2+(0.30768/0.04072)^2) -> 5.6564312 | H17: =(H16/0.7689925)*0.23100747 -> 0.0074317438 | I17: =H17*SQRT((I16/H16)^2+(0.28703/0.76899)^2+(0.28703/0.23101)^2) -> 0.012814187 | J17: =(J16/0.81303)*0.18697 -> 0.36721793 | K17: =J17*SQRT((K16/J16)^2+(0.22065/0.81303)^2+(0.22065/0.18697)^2) -> 0.49802123 | L17: =(L16/0.94848)*0.05152 -> 0.00039187518 | M17: =L17*SQRT((M16/L16)^2+(0/0.94848)^2+(0/0.05152)^2) -> 0.00088095433
A18: 16 | B18: PicoTOSalp | C18: (mmol N m-2 d-1) | D18: =(D16+D17) * 0.0144398 -> 0.065639483 | E18: =D18*SQRT((SQRT((E16)^2+(E17^2))/(D16+D17))^2+(0.00000265298/0.0144398)^2) -> 0.036697114 | F18: =(F16+F17) * 0.02786716 -> 0.069776844 | G18: =F18*SQRT((SQRT((G16)^2+(G17^2))/(F16+F17))^2+(6.398304E-19/0.02786716)^2) -> 0.15969892 | H18: =(H16+H17) * 0.08979186 -> 0.0028886948 | I18: =H18*SQRT((SQRT((I16)^2+(I17^2))/(H16+H17))^2+(0/0.08979186)^2) -> 0.0027729117 | J18: =(J16+J17) * 0.0366902 -> 0.07206129 | K18: =J18*SQRT((SQRT((K16)^2+(K17^2))/(J16+J17))^2+(0/0.0366902)^2) -> 0.040173425 | L18: =(L16+L17) * 0.02808958 -> 0.00021365701 | M18: =L18*SQRT((SQRT((M16)^2+(M17^2))/(L16+L17))^2+(0.0000002335522/0.02808958)^2) -> 0.00045623722
A19: 17 | B19: DtmTOSalp | C19: (mmol N m-2 d-1) | D19: =(D16+D17) * 0.1836172 -> 0.83467486 | E19: =D19*SQRT((SQRT((E16)^2+(E17^2))/(D16+D17))^2+(0.001733872/0.1836172)^2) -> 0.46670883 | F19: =(F16+F17) * 0.09318711 -> 0.23333208 | G19: =F19*SQRT((SQRT((G16)^2+(G17^2))/(F16+F17))^2+(0.0006530248/0.09318711)^2) -> 0.53403183 | H19: =(H16+H17) * 0.0004796753 -> 1.5431639e-05 | I19: =H19*SQRT((SQRT((I16)^2+(I17^2))/(H16+H17))^2+(0.00001015141/0.0004796753)^2) -> 1.4816716e-05 | J19: =(J16+J17) * 0.000004663878 -> 9.1600772e-06 | K19: =J19*SQRT((SQRT((K16)^2+(K17^2))/(J16+J17))^2+(0/0.000004663878)^2) -> 5.1066484e-06 | L19: =(L16+L17) * 0.09488286 -> 0.00072170493 | M19: =L19*SQRT((SQRT((M16)^2+(M17^2))/(L16+L17))^2+(0.000609438/0.09488286)^2) -> 0.0015411155
A20: 18 | B20: OtherTOSalp | C20: (mmol N m-2 d-1) | D20: =(D16+D17) * 0.8019303 -> 3.6453615 | E20: =D20*SQRT((SQRT((E16)^2+(E17^2))/(D16+D17))^2+(0.001733677/0.8019303)^2) -> 2.0380301 | F20: =(F16+F17) * 0.8789064 -> 2.200702 | G20: =F20*SQRT((SQRT((G16)^2+(G17^2))/(F16+F17))^2+(0.0006530248/0.8789064)^2) -> 5.0367676 | H20: =(H16+H17) * 0.9097285 -> 0.029266884 | I20: =H20*SQRT((SQRT((I16)^2+(I17^2))/(H16+H17))^2+(0.00001015141/0.9097285)^2) -> 0.028093825 | J20: =(J16+J17) * 0.9633051 -> 1.8919768 | K20: =J20*SQRT((SQRT((K16)^2+(K17^2))/(J16+J17))^2+(0/0.9633051)^2) -> 1.0547575 | L20: =(L16+L17) * 0.8769906 -> 0.0066706299 | M20: =L20*SQRT((SQRT((M16)^2+(M17^2))/(L16+L17))^2+(0.0006094337/0.8769906)^2) -> 0.014244278
A21: 19 | B21: Salp Fecal Pellet Production | C21: (mmol N m-2 d-1) | D21: 0.95731512 | E21: 0.68669075 | F21: 0.63279526 | G21: 0.33111182 | H21: 0.0089061358 | I21: 0.010115082 | J21: 0.57485859 | K21: 0.35104337 | L21: 0.0025971832 | M21: 0.0058385932
A22: 20 | B22: Bacterial Production | C22: (mmol N m-2 d-1) | D22: 0.76851397 | E22: 0.15497851 | F22: 0.51195866 | G22: 0.17726619 | H22: 0.82093159 | I22: 0.1864646 | J22: 0.73073094 | K22: 0.19985947 | L22: 0.44078467 | M22: 0.10558125
A23: 21 | B23: Myct Scaled Meso Consumption | C23: (mmol N m-2 d-1) | D23: 0.058469954 | E23: 0.029234977 | F23: 0.030570928 | G23: 0.015285464 | H23: 0.086478872 | I23: 0.043239436 | J23: 0.042115579 | K23: 0.021057789 | L23: 0.0074863178 | M23: 0.0037431589 | O23: =SUM(D23,D25:D29) -> 0.21638659 | P23: =SUM(F23:F29) -> 0.22829898 | Q23: =SUM(H23:H29) -> 0.20374434 | R23: =SUM(J23:J29) -> 0.17042542 | S23: =SUM(L23:L29) -> 0.082780527
A24: 22 | B24: Myct Scaled VMMeso Consumption | C24: (mmol N m-2 d-1) | D24: NA | E24: NA | F24: 0.099923468 | G24: 0.049961734 | H24: 0.10109392 | I24: 0.050546959 | J24: 0.029976384 | K24: 0.014988192 | L24: 0.065739576 | M24: 0.032869788
A25: 23 | B25: Myct Scaled Macro Consumption | C25: (mmol N m-2 d-1) | D25: 0.0013413623 | E25: 0.00067068114 | F25: 0.0044290992 | G25: 0.0022145496 | H25: 0.0026256933 | I25: 0.0013128466 | J25: 0.0012998958 | K25: 0.00064994789 | L25: 0.0067505401 | M25: 0.0033752701
A26: 24 | B26: Myct Scaled VMMacro Consumption | C26: (mmol N m-2 d-1) | D26: 0.021795859 | E26: 0.01089793 | F26: 0.017501118 | G26: 0.0087505589 | H26: 0.012697541 | I26: 0.0063487703 | J26: 0.0069954704 | K26: 0.0034977352 | L26: 0.0002001868 | M26: 0.0001000934
A27: 25 | B27: Myct Scaled Amph Consumption | C27: (mmol N m-2 d-1) | D27: 0.0018041689 | E27: 0.00090208445 | F27: 7.4452093e-05 | G27: 3.7226046e-05 | H27: 1.9958218e-06 | I27: 9.979109e-07 | J27: 0.00018840562 | K27: 9.4202811e-05 | L27: 0.001810573 | M27: 0.00090528652
A28: 26 | B28: Myct Scaled Salp Consumption | C28: (mmol N m-2 d-1) | D28: 0.13278426 | E28: 0.066392131 | F28: 0.067613192 | G28: 0.033806596 | H28: 0.00063513703 | I28: 0.00031756852 | J28: 0.08928306 | K28: 0.04464153 | L28: 0.00038182328 | M28: 0.00019091164
A29: 27 | B29: Myct Scaled Gel Consumption | C29: (mmol N m-2 d-1) | D29: 0.00019098429 | E29: 9.5492147e-05 | F29: 0.008186727 | G29: 0.0040933635 | H29: 0.0002111813 | I29: 0.00010559065 | J29: 0.00056662382 | K29: 0.00028331191 | L29: 0.00041150921 | M29: 0.0002057546
A30: 28 | B30: PiscivFish Scaled Myct Consumption | C30: (mmol N m-2 d-1) | D30: 0.011091282 | E30: 0.005545641 | F30: 0.011066583 | G30: 0.0055332916 | H30: 0.0092192534 | I30: 0.0046096267 | J30: 0.008526311 | K30: 0.0042631555 | L30: 0.0037655899 | M30: 0.0018827949
A31: 29 | B31: PiscivFish Scaled VMMacro Consumption | C31: (mmol N m-2 d-1) | D31: 0.0020805138 | E31: 0.0010402569 | F31: 0.0016705612 | G31: 0.00083528062 | H31: 0.001212038 | I31: 0.00060601898 | J31: 0.00066774944 | K31: 0.00033387472 | L31: 1.910874e-05 | M31: 9.5543701e-06
A32: 30 | B32: PiscivFish Scaled Amph Consumption | C32: (mmol N m-2 d-1) | D32: 0.00017221612 | E32: 8.6108062e-05 | F32: 7.1067907e-06 | G32: 3.5533953e-06 | H32: 1.9051026e-07 | I32: 9.5255131e-08 | J32: 1.7984173e-05 | K32: 8.9920865e-06 | L32: 0.00017282743 | M32: 8.6413713e-05
A33: 31 | B33: GelativFish Scaled Salp Consumption | C33: (mmol N m-2 d-1) | D33: 0.073086394 | E33: 0.036543197 | F33: 0.037215287 | G33: 0.018607643 | H33: 0.00034958868 | I33: 0.00017479434 | J33: 0.049142698 | K33: 0.024571349 | L33: 0.0002101611 | M33: 0.00010508055
A34: 32 | B34: GelativFish Scaled Gel Consumption | C34: (mmol N m-2 d-1) | D34: 0.00010512054 | E34: 5.256027e-05 | F34: 0.0045060939 | G34: 0.002253047 | H34: 0.00011623727 | I34: 5.8118634e-05 | J34: 0.00031187802 | K34: 0.00015593901 | L34: 0.00022650067 | M34: 0.00011325033
A35: 33 | B35: HTL Scaled Meso Consumption | C35: (mmol N m-2 d-1) | D35: 0.0062117204 | E35: 0.0031058602 | F35: 0.0032477887 | G35: 0.0016238944 | H35: 0.0091873268 | I35: 0.0045936634 | J35: 0.0044742672 | K35: 0.0022371336 | L35: 0.00079533008 | M35: 0.00039766504
A36: 34 | B36: HTL Scaled VMMeso Consumption | C36: (mmol N m-2 d-1) | D36: NA | E36: NA | F36: 0.010615651 | G36: 0.0053078257 | H36: 0.010739997 | I36: 0.0053699987 | J36: 0.0031846257 | K36: 0.0015923128 | L36: 0.0069840292 | M36: 0.0034920146
A37: 35 | B37: HTL Scaled Macro Consumption | C37: (mmol N m-2 d-1) | D37: 0.00043431282 | E37: 0.00021715641 | F37: 0.0014340753 | G37: 0.00071703767 | H37: 0.00085015978 | I37: 0.00042507989 | J37: 0.0004208866 | K37: 0.0002104433 | L37: 0.0021857228 | M37: 0.0010928614
A38: 36 | B38: HTL Scaled VMMacro Consumption | C38: (mmol N m-2 d-1) | D38: 0.0070571696 | E38: 0.0035285848 | F38: 0.0056665973 | G38: 0.0028332987 | H38: 0.0041112716 | I38: 0.0020556358 | J38: 0.0022650275 | K38: 0.0011325138 | L38: 6.481746e-05 | M38: 3.240873e-05
A39: 37 | B39: HTL Scaled Amph Consumption | C39: (mmol N m-2 d-1) | D39: 0.00058416261 | E39: 0.00029208131 | F39: 2.4106462e-05 | G39: 1.2053231e-05 | H39: 6.4621692e-07 | I39: 3.2310846e-07 | J39: 6.1002892e-05 | K39: 3.0501446e-05 | L39: 0.00058623617 | M39: 0.00029311809
A40: 38 | B40: HTL Scaled Salp Consumption | C40: (mmol N m-2 d-1) | D40: 0.066107475 | E40: 0.033053737 | F40: 0.03366165 | G40: 0.016830825 | H40: 0.00031620694 | I40: 0.00015810347 | J40: 0.044450129 | K40: 0.022225065 | L40: 0.00019009311 | M40: 9.5046553e-05
...

Sheet InputsNZ (2)
A1: Approximate Equalities
C2: units | D2: Cycle 1 | E2: σ | F2: Cycle 2 | G2: σ | H2: Cycle 3 | I2: σ | J2: Cycle 4 | K2: σ | L2: Cycle 5 | M2: σ
A3: 1 | B3: NPP (14C) | C3: (mmol N m-2 d-1) | D3: 6.9751396 | E3: 2.1054147 | F3: 4.0433304 | G3: 0.782773 | H3: 9.8238143 | I3: 4.5503874 | J3: 5.6894075 | K3: 1.2846958 | L3: 3.1620202 | M3: 0.38276057
A4: 2 | B4: SedTrap Flux (shallow) | C4: (mmol N m-2 d-1) | D4: 0.97868813 | E4: 0.20023276 | F4: 1.634325 | G4: 0.056975159 | H4: 0.46955162 | I4: 0.029864707 | J4: 1.78897 | K4: 0.59585481 | L4: 0.4195884 | M4: 0.18168493
A5: 3 | B5: Pico NPP | C5: (mmol N m-2 d-1) | D5: =D3*NZ_Extra!D6 -> 2.1257041 | E5: =D5*SQRT((E3/D3)^2+(NZ_Extra!E6/NZ_Extra!D6)^2) -> 1.5292454 | F5: =F3*NZ_Extra!F6 -> 3.0867581 | G5: =F5*SQRT((G3/F3)^2+(NZ_Extra!G6/NZ_Extra!F6)^2) -> 0.91836993 | H5: =H3*NZ_Extra!H6 -> 6.4892367 | I5: =H5*SQRT((I3/H3)^2+(NZ_Extra!I6/NZ_Extra!H6)^2) -> 4.7574096 | J5: =J3*NZ_Extra!J6 -> 3.4570988 | K5: =J5*SQRT((K3/J3)^2+(NZ_Extra!K6/NZ_Extra!J6)^2) -> 2.235291 | L5: =L3*NZ_Extra!L6 -> 2.8354624 | M5: =L5*SQRT((M3/L3)^2+(NZ_Extra!M6/NZ_Extra!L6)^2) -> 3.809041
A6: 4 | B6: Flag NPP | C6: (mmol N m-2 d-1) | D6: =D3*NZ_Extra!D7 -> 1.6509193 | E6: =D6*SQRT((E3/D3)^2+(NZ_Extra!E7/NZ_Extra!D7)^2) -> 0.83512694 | F6: =F3*NZ_Extra!F7 -> 0.3456774 | G6: =F6*SQRT((G3/F3)^2+(NZ_Extra!G7/NZ_Extra!F7)^2) -> 0.50067474 | H6: =H3*NZ_Extra!H7 -> 2.7169 | I6: =H6*SQRT((I3/H3)^2+(NZ_Extra!I7/NZ_Extra!H7)^2) -> 3.3405852 | J6: =J3*NZ_Extra!J7 -> 1.9849115 | K6: =J6*SQRT((K3/J3)^2+(NZ_Extra!K7/NZ_Extra!J7)^2) -> 1.9757686 | L6: =L3*NZ_Extra!L7 -> 0.16239399 | M6: =L6*SQRT((M3/L3)^2+(NZ_Extra!M7/NZ_Extra!L7)^2) -> 3.4118451
A7: 5 | B7: Diatom NPP | C7: (mmol N m-2 d-1) | D7: =D3*NZ_Extra!D8 -> 3.1985162 | E7: =D7*SQRT((E3/D3)^2+(NZ_Extra!E8/NZ_Extra!D8)^2) -> 2.0384171 | F7: =F3*NZ_Extra!F8 -> 0.36121242 | G7: =F7*SQRT((G3/F3)^2+(NZ_Extra!G8/NZ_Extra!F8)^2) -> 0.23417384 | H7: =H3*NZ_Extra!H8 -> 0.61767758 | I7: =H7*SQRT((I3/H3)^2+(NZ_Extra!I8/NZ_Extra!H8)^2) -> 0.56187448 | J7: =J3*NZ_Extra!J8 -> 0.24739712 | K7: =J7*SQRT((K3/J3)^2+(NZ_Extra!K8/NZ_Extra!J8)^2) -> 0.15495822 | L7: =L3*NZ_Extra!L8 -> 0.16416388 | M7: =L7*SQRT((M3/L3)^2+(NZ_Extra!M8/NZ_Extra!L8)^2) -> 0.21488912
A8: 6 | B8: Picophyto Mortality | C8: (mmol N m-2 d-1) | D8: =D11*NZ_Extra!D14 -> 0.96803779 | E8: =D8*SQRT((E11/D11)^2+(NZ_Extra!E14/NZ_Extra!D14)^2) -> 0.77464728 | F8: =F11*NZ_Extra!F14 -> 1.8898784 | G8: =F8*SQRT((G11/F11)^2+(NZ_Extra!G14/NZ_Extra!F14)^2) -> 0.73034638 | H8: =H11*NZ_Extra!H14 -> 3.4956498 | I8: =H8*SQRT((I11/H11)^2+(NZ_Extra!I14/NZ_Extra!H14)^2) -> 2.5146744 | J8: =J11*NZ_Extra!J14 -> 2.1195066 | K8: =J8*SQRT((K11/J11)^2+(NZ_Extra!K14/NZ_Extra!J14)^2) -> 1.2931693 | L8: =L11*NZ_Extra!L14 -> 1.249681 | M8: =L8*SQRT((M11/L11)^2+(NZ_Extra!M14/NZ_Extra!L14)^2) -> 0.93631571
A9: 7 | B9: Flagellate Mortality | C9: (mmol N m-2 d-1) | D9: =D11*NZ_Extra!D15 -> 0.93107774 | E9: =D9*SQRT((E11/D11)^2+(NZ_Extra!E15/NZ_Extra!D15)^2) -> 1.0527763 | F9: =F11*NZ_Extra!F15 -> 0.484364 | G9: =F9*SQRT((G11/F11)^2+(NZ_Extra!G15/NZ_Extra!F15)^2) -> 0.53471732 | H9: =H11*NZ_Extra!H15 -> 1.5734107 | I9: =H9*SQRT((I11/H11)^2+(NZ_Extra!I15/NZ_Extra!H15)^2) -> 1.7854607 | J9: =J11*NZ_Extra!J15 -> 2.2956994 | K9: =J9*SQRT((K11/J11)^2+(NZ_Extra!K15/NZ_Extra!J15)^2) -> 1.4378622 | L9: =L11*NZ_Extra!L15 -> 1.5922616 | M9: =L9*SQRT((M11/L11)^2+(NZ_Extra!M15/NZ_Extra!L15)^2) -> 2.3670614
A10: 8 | B10: Diatom Mortality | C10: (mmol N m-2 d-1) | D10: =D11*NZ_Extra!D16 -> 1.6100342 | E10: =D10*SQRT((E11/D11)^2+(NZ_Extra!E16/NZ_Extra!D16)^2) -> 1.1415465 | F10: =F11*NZ_Extra!F16 -> 0.0831399 | G10: =F10*SQRT((G11/F11)^2+(NZ_Extra!G16/NZ_Extra!F16)^2) -> 0.034881401 | H10: =H11*NZ_Extra!H16 -> 0.30286348 | I10: =H10*SQRT((I11/H11)^2+(NZ_Extra!I16/NZ_Extra!H16)^2) -> 0.26697517 | J10: =J11*NZ_Extra!J16 -> 0.18752559 | K10: =J10*SQRT((K11/J11)^2+(NZ_Extra!K16/NZ_Extra!J16)^2) -> 0.12099696 | L10: =L11*NZ_Extra!L16 -> 0.1359202 | M10: =L10*SQRT((M11/L11)^2+(NZ_Extra!M16/NZ_Extra!L16)^2) -> 0.13470708
A11: 9 | B11: Protistan Grazing Rate (14C) | C11: (mmol N m-2 d-1) | D11: 3.5091497 | E11: 1.264978 | F11: 2.6936632 | G11: 0.60951549 | H11: 5.371924 | I11: 2.9742856 | J11: 4.6027316 | K11: 2.1767591 | L11: 2.9778627 | M11: 0.86612577
A12: 10 | B12: Mesozoo Grazing | C12: (mmol N m-2 d-1) | D12: 0.90936712 | E12: 0.18438144 | F12: 0.69786875 | G12: 0.33083743 | H12: 0.24256809 | I12: 0.099091056 | J12: 0.326373 | K12: 0.1143953 | L12: 0.3026578 | M12: 0.16079582
A13: 11 | B13: VMMeso Grazing | C13: (mmol N m-2 d-1) | D13: NA | E13: NA | F13: 0.37867569 | G13: 0.22091414 | H13: 0.13229504 | I13: 0.038642116 | J13: 0.073472457 | K13: 0.10700278 | L13: 0.2096015 | M13: 0.12952208 | P13: =H11/SUM(H12:H15) -> 13.90799
A14: 12 | B14: Macrozoo Grazing | C14: (mmol N m-2 d-1) | D14: 0.027775614 | E14: 0.027788247 | F14: 0.033175155 | G14: 0.075474281 | H14: 0.0078424367 | I14: 0.011119541 | J14: 0.011164564 | K14: 0.01411272 | L14: 0.024892997 | M14: 0.025748037
A15: 13 | B15: VMMacro Grazing | C15: (mmol N m-2 d-1) | D15: 0.0088005357 | E15: 0.012670302 | F15: 0.020797253 | G15: 0.047029264 | H15: 0.0035417564 | I15: 0.0067117834 | J15: 0.0031993794 | K15: 0.0095212134 | L15: 8.8802004e-05 | M15: 0.012747025
A16: 14 | B16: Salp Autotroph Grazing | C16: (mmol N m-2 d-1) | D16: 2.6592087 | E16: 1.9074743 | F16: 1.7577646 | G16: 0.91975507 | H16: 0.024739266 | I16: 0.028097449 | J16: 1.5968294 | K16: 0.97512047 | L16: 0.0072143977 | M16: 0.016218315
A17: 15 | B17: Salp Heterotroph Grazing | C17: (mmol N m-2 d-1) | D17: =(D16/0.58499)*0.41501 -> 1.8865249 | E17: =D17*SQRT((E16/D16)^2+(0.17843/0.58499)^2+(0.17843/0.41501)^2) -> 1.6793412 | F17: =(F16/0.95928)*0.4072 -> 0.74614477 | G17: =F17*SQRT((G16/F16)^2+(0.30768/0.95928)^2+(0.30768/0.04072)^2) -> 5.6564312 | H17: =(H16/0.7689925)*0.23100747 -> 0.0074317438 | I17: =H17*SQRT((I16/H16)^2+(0.28703/0.76899)^2+(0.28703/0.23101)^2) -> 0.012814187 | J17: =(J16/0.81303)*0.18697 -> 0.36721793 | K17: =J17*SQRT((K16/J16)^2+(0.22065/0.81303)^2+(0.22065/0.18697)^2) -> 0.49802123 | L17: =(L16/0.94848)*0.05152 -> 0.00039187518 | M17: =L17*SQRT((M16/L16)^2+(0/0.94848)^2+(0/0.05152)^2) -> 0.00088095433
A18: 16 | B18: PicoTOSalp | C18: (mmol N m-2 d-1) | D18: =(D16+D17) * 0.0144398 -> 0.065639483 | E18: =D18*SQRT((SQRT((E16)^2+(E17^2))/(D16+D17))^2+(0.00000265298/0.0144398)^2) -> 0.036697114 | F18: =(F16+F17) * 0.02786716 -> 0.069776844 | G18: =F18*SQRT((SQRT((G16)^2+(G17^2))/(F16+F17))^2+(6.398304E-19/0.02786716)^2) -> 0.15969892 | H18: =(H16+H17) * 0.08979186 -> 0.0028886948 | I18: =H18*SQRT((SQRT((I16)^2+(I17^2))/(H16+H17))^2+(0/0.08979186)^2) -> 0.0027729117 | J18: =(J16+J17) * 0.0366902 -> 0.07206129 | K18: =J18*SQRT((SQRT((K16)^2+(K17^2))/(J16+J17))^2+(0/0.0366902)^2) -> 0.040173425 | L18: =(L16+L17) * 0.02808958 -> 0.00021365701 | M18: =L18*SQRT((SQRT((M16)^2+(M17^2))/(L16+L17))^2+(0.0000002335522/0.02808958)^2) -> 0.00045623722
A19: 17 | B19: DtmTOSalp | C19: (mmol N m-2 d-1) | D19: =(D16+D17) * 0.1836172 -> 0.83467486 | E19: =D19*SQRT((SQRT((E16)^2+(E17^2))/(D16+D17))^2+(0.001733872/0.1836172)^2) -> 0.46670883 | F19: =(F16+F17) * 0.09318711 -> 0.23333208 | G19: =F19*SQRT((SQRT((G16)^2+(G17^2))/(F16+F17))^2+(0.0006530248/0.09318711)^2) -> 0.53403183 | H19: =(H16+H17) * 0.0004796753 -> 1.5431639e-05 | I19: =H19*SQRT((SQRT((I16)^2+(I17^2))/(H16+H17))^2+(0.00001015141/0.0004796753)^2) -> 1.4816716e-05 | J19: =(J16+J17) * 0.000004663878 -> 9.1600772e-06 | K19: =J19*SQRT((SQRT((K16)^2+(K17^2))/(J16+J17))^2+(0/0.000004663878)^2) -> 5.1066484e-06 | L19: =(L16+L17) * 0.09488286 -> 0.00072170493 | M19: =L19*SQRT((SQRT((M16)^2+(M17^2))/(L16+L17))^2+(0.000609438/0.09488286)^2) -> 0.0015411155
A20: 18 | B20: OtherTOSalp | C20: (mmol N m-2 d-1) | D20: =(D16+D17) * 0.8019303 -> 3.6453615 | E20: =D20*SQRT((SQRT((E16)^2+(E17^2))/(D16+D17))^2+(0.001733677/0.8019303)^2) -> 2.0380301 | F20: =(F16+F17) * 0.8789064 -> 2.200702 | G20: =F20*SQRT((SQRT((G16)^2+(G17^2))/(F16+F17))^2+(0.0006530248/0.8789064)^2) -> 5.0367676 | H20: =(H16+H17) * 0.9097285 -> 0.029266884 | I20: =H20*SQRT((SQRT((I16)^2+(I17^2))/(H16+H17))^2+(0.00001015141/0.9097285)^2) -> 0.028093825 | J20: =(J16+J17) * 0.9633051 -> 1.8919768 | K20: =J20*SQRT((SQRT((K16)^2+(K17^2))/(J16+J17))^2+(0/0.9633051)^2) -> 1.0547575 | L20: =(L16+L17) * 0.8769906 -> 0.0066706299 | M20: =L20*SQRT((SQRT((M16)^2+(M17^2))/(L16+L17))^2+(0.0006094337/0.8769906)^2) -> 0.014244278
A21: 19 | B21: Salp Fecal Pellet Production | C21: (mmol N m-2 d-1) | D21: 0.95731512 | E21: 0.68669075 | F21: 0.63279526 | G21: 0.33111182 | H21: 0.0089061358 | I21: 0.010115082 | J21: 0.57485859 | K21: 0.35104337 | L21: 0.0025971832 | M21: 0.0058385932
A22: 20 | B22: Bacterial Production | C22: (mmol N m-2 d-1) | D22: 0.76851397 | E22: 0.15497851 | F22: 0.51195866 | G22: 0.17726619 | H22: 0.82093159 | I22: 0.1864646 | J22: 0.73073094 | K22: 0.19985947 | L22: 0.44078467 | M22: 0.10558125
A23: 21 | B23: Myct Scaled Meso Consumption | C23: (mmol N m-2 d-1) | D23: 0.11693991 | E23: 0.058469954 | F23: 0.061141856 | G23: 0.030570928 | H23: 0.17295774 | I23: 0.086478872 | J23: 0.084231157 | K23: 0.042115579 | L23: 0.014972636 | M23: 0.0074863178 | O23: =SUM(D23,D25:D29) -> 0.43277318 | P23: =SUM(F23:F29) -> 0.45659797 | Q23: =SUM(H23:H29) -> 0.40748867 | R23: =SUM(J23:J29) -> 0.34085084 | S23: =SUM(L23:L29) -> 0.16556105
A24: 22 | B24: Myct Scaled VMMeso Consumption | C24: (mmol N m-2 d-1) | D24: NA | E24: NA | F24: 0.19984694 | G24: 0.099923468 | H24: 0.20218783 | I24: 0.10109392 | J24: 0.059952768 | K24: 0.029976384 | L24: 0.13147915 | M24: 0.065739576
A25: 23 | B25: Myct Scaled Macro Consumption | C25: (mmol N m-2 d-1) | D25: 0.0026827246 | E25: 0.0013413623 | F25: 0.0088581984 | G25: 0.0044290992 | H25: 0.0052513866 | I25: 0.0026256933 | J25: 0.0025997916 | K25: 0.0012998958 | L25: 0.01350108 | M25: 0.0067505401
A26: 24 | B26: Myct Scaled VMMacro Consumption | C26: (mmol N m-2 d-1) | D26: 0.043591718 | E26: 0.021795859 | F26: 0.035002236 | G26: 0.017501118 | H26: 0.025395081 | I26: 0.012697541 | J26: 0.013990941 | K26: 0.0069954704 | L26: 0.0004003736 | M26: 0.0002001868
A27: 25 | B27: Myct Scaled Amph Consumption | C27: (mmol N m-2 d-1) | D27: 0.0036083378 | E27: 0.0018041689 | F27: 0.00014890419 | G27: 7.4452093e-05 | H27: 3.9916436e-06 | I27: 1.9958218e-06 | J27: 0.00037681124 | K27: 0.00018840562 | L27: 0.0036211461 | M27: 0.001810573
A28: 26 | B28: Myct Scaled Salp Consumption | C28: (mmol N m-2 d-1) | D28: 0.26556852 | E28: 0.13278426 | F28: 0.13522638 | G28: 0.067613192 | H28: 0.0012702741 | I28: 0.00063513703 | J28: 0.17856612 | K28: 0.08928306 | L28: 0.00076364656 | M28: 0.00038182328
A29: 27 | B29: Myct Scaled Gel Consumption | C29: (mmol N m-2 d-1) | D29: 0.00038196859 | E29: 0.00019098429 | F29: 0.016373454 | G29: 0.008186727 | H29: 0.0004223626 | I29: 0.0002111813 | J29: 0.0011332476 | K29: 0.00056662382 | L29: 0.00082301842 | M29: 0.00041150921
A30: 28 | B30: PiscivFish Scaled Myct Consumption | C30: (mmol N m-2 d-1) | D30: 0.022182564 | E30: 0.011091282 | F30: 0.022133166 | G30: 0.011066583 | H30: 0.018438507 | I30: 0.0092192534 | J30: 0.017052622 | K30: 0.008526311 | L30: 0.0075311797 | M30: 0.0037655899
A31: 29 | B31: PiscivFish Scaled VMMacro Consumption | C31: (mmol N m-2 d-1) | D31: 0.0041610276 | E31: 0.0020805138 | F31: 0.0033411225 | G31: 0.0016705612 | H31: 0.0024240759 | I31: 0.001212038 | J31: 0.0013354989 | K31: 0.00066774944 | L31: 3.821748e-05 | M31: 1.910874e-05
A32: 30 | B32: PiscivFish Scaled Amph Consumption | C32: (mmol N m-2 d-1) | D32: 0.00034443225 | E32: 0.00017221612 | F32: 1.4213581e-05 | G32: 7.1067907e-06 | H32: 3.8102053e-07 | I32: 1.9051026e-07 | J32: 3.5968346e-05 | K32: 1.7984173e-05 | L32: 0.00034565485 | M32: 0.00017282743
A33: 31 | B33: GelativFish Scaled Salp Consumption | C33: (mmol N m-2 d-1) | D33: 0.14617279 | E33: 0.073086394 | F33: 0.074430574 | G33: 0.037215287 | H33: 0.00069917737 | I33: 0.00034958868 | J33: 0.098285396 | K33: 0.049142698 | L33: 0.0004203222 | M33: 0.0002101611
A34: 32 | B34: GelativFish Scaled Gel Consumption | C34: (mmol N m-2 d-1) | D34: 0.00021024108 | E34: 0.00010512054 | F34: 0.0090121878 | G34: 0.0045060939 | H34: 0.00023247453 | I34: 0.00011623727 | J34: 0.00062375603 | K34: 0.00031187802 | L34: 0.00045300134 | M34: 0.00022650067
A35: 33 | B35: HTL Scaled Meso Consumption | C35: (mmol N m-2 d-1) | D35: 0.012423441 | E35: 0.0062117204 | F35: 0.0064955775 | G35: 0.0032477887 | H35: 0.018374654 | I35: 0.0091873268 | J35: 0.0089485345 | K35: 0.0044742672 | L35: 0.0015906602 | M35: 0.00079533008
A36: 34 | B36: HTL Scaled VMMeso Consumption | C36: (mmol N m-2 d-1) | D36: NA | E36: NA | F36: 0.021231303 | G36: 0.010615651 | H36: 0.021479995 | I36: 0.010739997 | J36: 0.0063692514 | K36: 0.0031846257 | L36: 0.013968058 | M36: 0.0069840292
A37: 35 | B37: HTL Scaled Macro Consumption | C37: (mmol N m-2 d-1) | D37: 0.00086862565 | E37: 0.00043431282 | F37: 0.0028681507 | G37: 0.0014340753 | H37: 0.0017003196 | I37: 0.00085015978 | J37: 0.0008417732 | K37: 0.0004208866 | L37: 0.0043714457 | M37: 0.0021857228
A38: 36 | B38: HTL Scaled VMMacro Consumption | C38: (mmol N m-2 d-1) | D38: 0.014114339 | E38: 0.0070571696 | F38: 0.011333195 | G38: 0.0056665973 | H38: 0.0082225433 | I38: 0.0041112716 | J38: 0.0045300551 | K38: 0.0022650275 | L38: 0.00012963492 | M38: 6.481746e-05
A39: 37 | B39: HTL Scaled Amph Consumption | C39: (mmol N m-2 d-1) | D39: 0.0011683252 | E39: 0.00058416261 | F39: 4.8212924e-05 | G39: 2.4106462e-05 | H39: 1.2924338e-06 | I39: 6.4621692e-07 | J39: 0.00012200578 | K39: 6.1002892e-05 | L39: 0.0011724723 | M39: 0.00058623617
A40: 38 | B40: HTL Scaled Salp Consumption | C40: (mmol N m-2 d-1) | D40: 0.13221495 | E40: 0.066107475 | F40: 0.0673233 | G40: 0.03366165 | H40: 0.00063241388 | I40: 0.00031620694 | J40: 0.088900259 | K40: 0.044450129 | L40: 0.00038018621 | M40: 0.00019009311
...

Sheet Sheet1
B2: units | C2: Cycle 1 | D2: σ | E2: Cycle 2 | F2: σ | G2: Cycle 3 | H2: σ | I2: Cycle 4 | J2: σ | K2: Cycle 5 | L2: σ
A3: Meso Daytime Biomass | B3: (mmol N m-2) | C3: 9.913779 | D3: 1.6349767 | E3: 4.799307 | F3: 0.009130156 | G3: 13.576253 | H3: 7.2571895 | I3: 6.611693 | J3: 1.9186138 | K3: 1.1752714 | L3: 0.6314741
A4: Meso Nighttime Biomass | B4: (mmol N m-2) | C4: 8.444529 | D4: 0.17518244 | E4: 20.486217 | F4: 5.1290183 | G4: 29.446911 | H4: 5.2590703 | I4: 11.317663 | J4: 6.5195917 | K4: 11.495678 | L4: 3.3280949
A5: Macro Daytime Biomass | B5: (mmol N m-2) | C5: 0.2395441 | D5: 0.3387665 | E5: 0.7909605 | F5: 0.742375 | G5: 0.4689034 | H5: 0.3975926 | I5: 0.2321389 | J5: 0.1309799 | K5: 1.2055297 | L5: 0.8594286
A6: Macro Nighttime Biomass | B6: (mmol N m-2) | C6: 4.1319075 | D6: 2.6204844 | E6: 3.9163574 | F6: 2.8763821 | G6: 2.7364645 | H6: 0.3570634 | I6: 1.4814089 | J6: 0.6263969 | K6: 1.2412796 | L6: 0.5305407
A8: NVM Meso Biomass | B8: (mmol N m-2) | C8: =C3 -> 9.913779 | D8: =D3 -> 1.6349767 | E8: =E3 -> 4.799307 | F8: =F3 -> 0.009130156 | G8: =G3 -> 13.576253 | H8: =H3 -> 7.2571895 | I8: =I3 -> 6.611693 | J8: =J3 -> 1.9186138 | ... L8: =L3 -> 0.6314741
A9: VM Meso Biomass | B9: (mmol N m-2) | E9: =E4-E3 -> 15.68691 | G9: =G4-G3 -> 15.870658 | I9: =I4-I3 -> 4.70597 | K9: =K4-K3 -> 10.320407
A10: NVM Macro Biomass | B10: (mmol N m-2) | C10: =C5 -> 0.2395441 | E10: =E5 -> 0.7909605 | G10: =G5 -> 0.4689034 | I10: =I5 -> 0.2321389 | K10: =K5 -> 1.2055297
A11: VM Macro Biomass | B11: (mmol N m-2) | C11: =C6-C5 -> 3.8923634 | E11: =E6-E5 -> 3.1253969 | G11: =G6-G5 -> 2.2675611 | I11: =I6-I5 -> 1.24927 | K11: =K6-K5 -> 0.0357499
A13: Total Meso Biomass | B13: (mmol N m-2) | C13: =SUM(C8:C9) -> 9.913779 | E13: =SUM(E8:E9) -> 20.486217 | G13: =SUM(G8:G9) -> 29.446911 | I13: =SUM(I8:I9) -> 11.317663 | K13: =SUM(K8:K9) -> 11.495678
A14: Total Macro Biomass | B14: (mmol N m-2) | C14: =SUM(C10:C11) -> 4.1319075 | E14: =SUM(E10:E11) -> 3.9163574 | G14: =SUM(G10:G11) -> 2.7364645 | I14: =SUM(I10:I11) -> 1.4814089 | K14: =SUM(K10:K11) -> 1.2412796

Sheet InputsNZ_C
A1: Approximate Equalities
C2: units | D2: Cycle 1 | E2: σ | F2: Cycle 2 | G2: σ | H2: Cycle 3 | I2: σ | J2: Cycle 4 | K2: σ | L2: Cycle 5 | M2: σ
A3: 1 | B3: NPP (14C) | C3: (mg C m-2 d-1) | D3: =InputsNZ!D3*(106/16)*12 -> 554.5236 | E3: =InputsNZ!E3*(106/16)*12 -> 167.38047 | F3: =InputsNZ!F3*(106/16)*12 -> 321.44477 | G3: =InputsNZ!G3*(106/16)*12 -> 62.230454 | H3: =InputsNZ!H3*(106/16)*12 -> 780.99324 | I3: =InputsNZ!I3*(106/16)*12 -> 361.7558 | J3: =InputsNZ!J3*(106/16)*12 -> 452.30789 | K3: =InputsNZ!K3*(106/16)*12 -> 102.13332 | ... M3: =InputsNZ!M3*(106/16)*12 -> 30.429465
A4: 2 | B4: SedTrap Flux (shallow) | C4: (mg C m-2 d-1) | D4: =InputsNZ!D4*(106/16)*12 -> 77.805706 | E4: =InputsNZ!E4*(106/16)*12 -> 15.918505 | F4: =InputsNZ!F4*(106/16)*12 -> 129.92884 | G4: =InputsNZ!G4*(106/16)*12 -> 4.5295252 | H4: =InputsNZ!H4*(106/16)*12 -> 37.329353 | I4: =InputsNZ!I4*(106/16)*12 -> 2.3742442 | J4: =InputsNZ!J4*(106/16)*12 -> 142.22312 | K4: =InputsNZ!K4*(106/16)*12 -> 47.370457 | ... M4: =InputsNZ!M4*(106/16)*12 -> 14.443952
A5: 3 | B5: Pico NPP | C5: (mg C m-2 d-1) | D5: =InputsNZ!D5*(106/16)*12 -> 168.99348 | E5: =InputsNZ!E5*(106/16)*12 -> 121.57501 | F5: =InputsNZ!F5*(106/16)*12 -> 245.39727 | G5: =InputsNZ!G5*(106/16)*12 -> 73.010409 | H5: =InputsNZ!H5*(106/16)*12 -> 515.89432 | I5: =InputsNZ!I5*(106/16)*12 -> 378.21406 | J5: =InputsNZ!J5*(106/16)*12 -> 274.83935 | K5: =InputsNZ!K5*(106/16)*12 -> 177.70564 | ... M5: =InputsNZ!M5*(106/16)*12 -> 302.81876
A6: 4 | B6: Flag NPP | C6: (mg C m-2 d-1) | D6: =InputsNZ!D6*(106/16)*12 -> 131.24809 | E6: =InputsNZ!E6*(106/16)*12 -> 66.392591 | F6: =InputsNZ!F6*(106/16)*12 -> 27.481353 | G6: =InputsNZ!G6*(106/16)*12 -> 39.803642 | H6: =InputsNZ!H6*(106/16)*12 -> 215.99355 | I6: =InputsNZ!I6*(106/16)*12 -> 265.57652 | J6: =InputsNZ!J6*(106/16)*12 -> 157.80047 | K6: =InputsNZ!K6*(106/16)*12 -> 157.0736 | ... M6: =InputsNZ!M6*(106/16)*12 -> 271.24169
A7: 5 | B7: Diatom NPP | C7: (mg C m-2 d-1) | D7: =InputsNZ!D7*(106/16)*12 -> 254.28203 | E7: =InputsNZ!E7*(106/16)*12 -> 162.05416 | F7: =InputsNZ!F7*(106/16)*12 -> 28.716387 | G7: =InputsNZ!G7*(106/16)*12 -> 18.616821 | H7: =InputsNZ!H7*(106/16)*12 -> 49.105367 | I7: =InputsNZ!I7*(106/16)*12 -> 44.669022 | J7: =InputsNZ!J7*(106/16)*12 -> 19.668071 | K7: =InputsNZ!K7*(106/16)*12 -> 12.319178 | ... M7: =InputsNZ!M7*(106/16)*12 -> 17.083685
A8: 6 | B8: Picophyto Mortality | C8: (mg C m-2 d-1) | D8: =InputsNZ!D8*(106/16)*12 -> 76.959004 | E8: =InputsNZ!E8*(106/16)*12 -> 61.584459 | F8: =InputsNZ!F8*(106/16)*12 -> 150.24533 | G8: =InputsNZ!G8*(106/16)*12 -> 58.062538 | H8: =InputsNZ!H8*(106/16)*12 -> 277.90416 | I8: =InputsNZ!I8*(106/16)*12 -> 199.91661 | J8: =InputsNZ!J8*(106/16)*12 -> 168.50077 | K8: =InputsNZ!K8*(106/16)*12 -> 102.80696 | ... M8: =InputsNZ!M8*(106/16)*12 -> 74.437099
A9: 7 | B9: Flagellate Mortality | C9: (mg C m-2 d-1) | D9: =InputsNZ!D9*(106/16)*12 -> 74.02068 | E9: =InputsNZ!E9*(106/16)*12 -> 83.695719 | F9: =InputsNZ!F9*(106/16)*12 -> 38.506938 | G9: =InputsNZ!G9*(106/16)*12 -> 42.510027 | H9: =InputsNZ!H9*(106/16)*12 -> 125.08615 | I9: =InputsNZ!I9*(106/16)*12 -> 141.94413 | J9: =InputsNZ!J9*(106/16)*12 -> 182.5081 | K9: =InputsNZ!K9*(106/16)*12 -> 114.31005 | ... M9: =InputsNZ!M9*(106/16)*12 -> 188.18138
A10: 8 | B10: Diatom Mortality | C10: (mg C m-2 d-1) | D10: =InputsNZ!D10*(106/16)*12 -> 127.99772 | E10: =InputsNZ!E10*(106/16)*12 -> 90.752947 | F10: =InputsNZ!F10*(106/16)*12 -> 6.609622 | G10: =InputsNZ!G10*(106/16)*12 -> 2.7730714 | H10: =InputsNZ!H10*(106/16)*12 -> 24.077647 | I10: =InputsNZ!I10*(106/16)*12 -> 21.224526 | J10: =InputsNZ!J10*(106/16)*12 -> 14.908284 | K10: =InputsNZ!K10*(106/16)*12 -> 9.6192584 | ... M10: =InputsNZ!M10*(106/16)*12 -> 10.709213
A11: 9 | B11: Protistan Grazing Rate (14C) | C11: (mg C m-2 d-1) | D11: =InputsNZ!D11*(106/16)*12 -> 278.9774 | E11: =InputsNZ!E11*(106/16)*12 -> 100.56575 | F11: =InputsNZ!F11*(106/16)*12 -> 214.14622 | G11: =InputsNZ!G11*(106/16)*12 -> 48.456482 | H11: =InputsNZ!H11*(106/16)*12 -> 427.06796 | I11: =InputsNZ!I11*(106/16)*12 -> 236.45571 | J11: =InputsNZ!J11*(106/16)*12 -> 365.91716 | K11: =InputsNZ!K11*(106/16)*12 -> 173.05235 | ... M11: =InputsNZ!M11*(106/16)*12 -> 68.856999
A12: 10 | B12: Mesozoo Grazing | C12: (mg C m-2 d-1) | D12: =InputsNZ!D12*(106/16)*12 -> 72.294686 | E12: =InputsNZ!E12*(106/16)*12 -> 14.658324 | F12: =InputsNZ!F12*(106/16)*12 -> 55.480566 | G12: =InputsNZ!G12*(106/16)*12 -> 26.301575 | H12: =InputsNZ!H12*(106/16)*12 -> 19.284163 | I12: =InputsNZ!I12*(106/16)*12 -> 7.8777389 | J12: =InputsNZ!J12*(106/16)*12 -> 25.946654 | K12: =InputsNZ!K12*(106/16)*12 -> 9.094426 | ... M12: =InputsNZ!M12*(106/16)*12 -> 12.783267
A13: 11 | B13: VMMeso Grazing | C13: (mg C m-2 d-1) | D13: =InputsNZ!D13*(106/16)*12 -> #VALUE! | E13: =InputsNZ!E13*(106/16)*12 -> #VALUE! | F13: =InputsNZ!F13*(106/16)*12 -> 30.104717 | G13: =InputsNZ!G13*(106/16)*12 -> 17.562674 | H13: =InputsNZ!H13*(106/16)*12 -> 10.517456 | I13: =InputsNZ!I13*(106/16)*12 -> 3.0720482 | J13: =InputsNZ!J13*(106/16)*12 -> 5.8410603 | K13: =InputsNZ!K13*(106/16)*12 -> 8.5067207 | ... M13: =InputsNZ!M13*(106/16)*12 -> 10.297005 | P13: =H11/SUM(H12:H15) -> 13.90799
A14: 12 | B14: Macrozoo Grazing | C14: (mg C m-2 d-1) | D14: =InputsNZ!D14*(106/16)*12 -> 2.2081613 | E14: =InputsNZ!E14*(106/16)*12 -> 2.2091656 | F14: =InputsNZ!F14*(106/16)*12 -> 2.6374248 | G14: =InputsNZ!G14*(106/16)*12 -> 6.0002054 | H14: =InputsNZ!H14*(106/16)*12 -> 0.62347372 | I14: =InputsNZ!I14*(106/16)*12 -> 0.88400355 | J14: =InputsNZ!J14*(106/16)*12 -> 0.88758287 | K14: =InputsNZ!K14*(106/16)*12 -> 1.1219613 | ... M14: =InputsNZ!M14*(106/16)*12 -> 2.0469689
A15: 13 | B15: VMMacro Grazing | C15: (mg C m-2 d-1) | D15: =InputsNZ!D15*(106/16)*12 -> 0.69964259 | E15: =InputsNZ!E15*(106/16)*12 -> 1.007289 | F15: =InputsNZ!F15*(106/16)*12 -> 1.6533816 | G15: =InputsNZ!G15*(106/16)*12 -> 3.7388265 | H15: =InputsNZ!H15*(106/16)*12 -> 0.28156963 | I15: =InputsNZ!I15*(106/16)*12 -> 0.53358678 | J15: =InputsNZ!J15*(106/16)*12 -> 0.25435066 | K15: =InputsNZ!K15*(106/16)*12 -> 0.75693646 | ... M15: =InputsNZ!M15*(106/16)*12 -> 1.0133885
A16: 14 | B16: Salp Autotroph Grazing | C16: (mg C m-2 d-1) | D16: =InputsNZ!D16*(106/16)*12 -> 211.40709 | E16: =InputsNZ!E16*(106/16)*12 -> 151.64421 | F16: =InputsNZ!F16*(106/16)*12 -> 139.74229 | G16: =InputsNZ!G16*(106/16)*12 -> 73.120528 | H16: =InputsNZ!H16*(106/16)*12 -> 1.9667716 | I16: =InputsNZ!I16*(106/16)*12 -> 2.2337472 | J16: =InputsNZ!J16*(106/16)*12 -> 126.94794 | K16: =InputsNZ!K16*(106/16)*12 -> 77.522077 | ... M16: =InputsNZ!M16*(106/16)*12 -> 1.289356
A17: 15 | B17: Salp Heterotroph Grazing | C17: (mg C m-2 d-1) | D17: =InputsNZ!D17*(106/16)*12 -> 149.97873 | E17: =InputsNZ!E17*(106/16)*12 -> 133.50763 | F17: =InputsNZ!F17*(106/16)*12 -> 59.318509 | G17: =InputsNZ!G17*(106/16)*12 -> 449.68628 | H17: =InputsNZ!H17*(106/16)*12 -> 0.59082363 | I17: =InputsNZ!I17*(106/16)*12 -> 1.0187278 | J17: =InputsNZ!J17*(106/16)*12 -> 29.193826 | K17: =InputsNZ!K17*(106/16)*12 -> 39.592688 | ... M17: =InputsNZ!M17*(106/16)*12 -> 0.07003587
A18: 16 | B18: PicoTOSalp | C18: (mg C m-2 d-1) | D18: =InputsNZ!D18*(106/16)*12 -> 5.2183389 | E18: =InputsNZ!E18*(106/16)*12 -> 2.9174206 | F18: =InputsNZ!F18*(106/16)*12 -> 5.5472591 | G18: =InputsNZ!G18*(106/16)*12 -> 12.696064 | H18: =InputsNZ!H18*(106/16)*12 -> 0.22965124 | I18: =InputsNZ!I18*(106/16)*12 -> 0.22044648 | J18: =InputsNZ!J18*(106/16)*12 -> 5.7288725 | K18: =InputsNZ!K18*(106/16)*12 -> 3.1937873 | ... M18: =InputsNZ!M18*(106/16)*12 -> 0.036270859
A19: 17 | B19: DtmTOSalp | C19: (mg C m-2 d-1) | D19: =InputsNZ!D19*(106/16)*12 -> 66.356652 | E19: =InputsNZ!E19*(106/16)*12 -> 37.103352 | F19: =InputsNZ!F19*(106/16)*12 -> 18.5499 | G19: =InputsNZ!G19*(106/16)*12 -> 42.455531 | H19: =InputsNZ!H19*(106/16)*12 -> 0.0012268153 | I19: =InputsNZ!I19*(106/16)*12 -> 0.0011779289 | J19: =InputsNZ!J19*(106/16)*12 -> 0.00072822614 | K19: =InputsNZ!K19*(106/16)*12 -> 0.00040597855 | ... M19: =InputsNZ!M19*(106/16)*12 -> 0.12251869
A20: 18 | B20: OtherTOSalp | C20: (mg C m-2 d-1) | D20: =InputsNZ!D20*(106/16)*12 -> 289.80624 | E20: =InputsNZ!E20*(106/16)*12 -> 162.02339 | F20: =InputsNZ!F20*(106/16)*12 -> 174.95581 | G20: =InputsNZ!G20*(106/16)*12 -> 400.42303 | H20: =InputsNZ!H20*(106/16)*12 -> 2.3267173 | I20: =InputsNZ!I20*(106/16)*12 -> 2.2334591 | J20: =InputsNZ!J20*(106/16)*12 -> 150.41216 | K20: =InputsNZ!K20*(106/16)*12 -> 83.853224 | ... M20: =InputsNZ!M20*(106/16)*12 -> 1.1324201
A21: 19 | B21: Salp Fecal Pellet Production | C21: (mg C m-2 d-1) | D21: =InputsNZ!D21*(106/16)*12 -> 76.106552 | E21: =InputsNZ!E21*(106/16)*12 -> 54.591915 | F21: =InputsNZ!F21*(106/16)*12 -> 50.307224 | G21: =InputsNZ!G21*(106/16)*12 -> 26.32339 | H21: =InputsNZ!H21*(106/16)*12 -> 0.70803779 | I21: =InputsNZ!I21*(106/16)*12 -> 0.804149 | J21: =InputsNZ!J21*(106/16)*12 -> 45.701258 | K21: =InputsNZ!K21*(106/16)*12 -> 27.907948 | ... M21: =InputsNZ!M21*(106/16)*12 -> 0.46416816
A22: 20 | B22: Bacterial Production | C22: (mg C m-2 d-1) | D22: =InputsNZ!D22*(106/16)*12 -> 61.09686 | E22: =InputsNZ!E22*(106/16)*12 -> 12.320791 | F22: =InputsNZ!F22*(106/16)*12 -> 40.700714 | G22: =InputsNZ!G22*(106/16)*12 -> 14.092662 | H22: =InputsNZ!H22*(106/16)*12 -> 65.264061 | I22: =InputsNZ!I22*(106/16)*12 -> 14.823936 | J22: =InputsNZ!J22*(106/16)*12 -> 58.09311 | K22: =InputsNZ!K22*(106/16)*12 -> 15.888828 | ... M22: =InputsNZ!M22*(106/16)*12 -> 8.3937094
A23: 21 | B23: Myct Scaled Meso Consumption | C23: (mg C m-2 d-1) | D23: =InputsNZ!#REF!*(106/16)*12 -> #REF! | E23: =InputsNZ!#REF!*(106/16)*12 -> #REF! | F23: =InputsNZ!#REF!*(106/16)*12 -> #REF! | G23: =InputsNZ!#REF!*(106/16)*12 -> #REF! | H23: =InputsNZ!#REF!*(106/16)*12 -> #REF! | I23: =InputsNZ!#REF!*(106/16)*12 -> #REF! | J23: =InputsNZ!#REF!*(106/16)*12 -> #REF! | K23: =InputsNZ!#REF!*(106/16)*12 -> #REF! | ... M23: =InputsNZ!#REF!*(106/16)*12 -> #REF!
A24: 22 | B24: Myct Scaled VMMeso Consumption | C24: (mg C m-2 d-1) | D24: =InputsNZ!#REF!*(106/16)*12 -> #REF! | E24: =InputsNZ!#REF!*(106/16)*12 -> #REF! | F24: =InputsNZ!#REF!*(106/16)*12 -> #REF! | G24: =InputsNZ!#REF!*(106/16)*12 -> #REF! | H24: =InputsNZ!#REF!*(106/16)*12 -> #REF! | I24: =InputsNZ!#REF!*(106/16)*12 -> #REF! | J24: =InputsNZ!#REF!*(106/16)*12 -> #REF! | K24: =InputsNZ!#REF!*(106/16)*12 -> #REF! | ... M24: =InputsNZ!#REF!*(106/16)*12 -> #REF!
A25: 23 | B25: Myct Scaled Macro Consumption | C25: (mg C m-2 d-1) | D25: =InputsNZ!#REF!*(106/16)*12 -> #REF! | E25: =InputsNZ!#REF!*(106/16)*12 -> #REF! | F25: =InputsNZ!#REF!*(106/16)*12 -> #REF! | G25: =InputsNZ!#REF!*(106/16)*12 -> #REF! | H25: =InputsNZ!#REF!*(106/16)*12 -> #REF! | I25: =InputsNZ!#REF!*(106/16)*12 -> #REF! | J25: =InputsNZ!#REF!*(106/16)*12 -> #REF! | K25: =InputsNZ!#REF!*(106/16)*12 -> #REF! | ... M25: =InputsNZ!#REF!*(106/16)*12 -> #REF!
A26: 24 | B26: Myct Scaled VMMacro Consumption | C26: (mg C m-2 d-1) | D26: =InputsNZ!#REF!*(106/16)*12 -> #REF! | E26: =InputsNZ!#REF!*(106/16)*12 -> #REF! | F26: =InputsNZ!#REF!*(106/16)*12 -> #REF! | G26: =InputsNZ!#REF!*(106/16)*12 -> #REF! | H26: =InputsNZ!#REF!*(106/16)*12 -> #REF! | I26: =InputsNZ!#REF!*(106/16)*12 -> #REF! | J26: =InputsNZ!#REF!*(106/16)*12 -> #REF! | K26: =InputsNZ!#REF!*(106/16)*12 -> #REF! | ... M26: =InputsNZ!#REF!*(106/16)*12 -> #REF!
A27: 25 | B27: Myct Scaled Amph Consumption | C27: (mg C m-2 d-1) | D27: =InputsNZ!#REF!*(106/16)*12 -> #REF! | E27: =InputsNZ!#REF!*(106/16)*12 -> #REF! | F27: =InputsNZ!#REF!*(106/16)*12 -> #REF! | G27: =InputsNZ!#REF!*(106/16)*12 -> #REF! | H27: =InputsNZ!#REF!*(106/16)*12 -> #REF! | I27: =InputsNZ!#REF!*(106/16)*12 -> #REF! | J27: =InputsNZ!#REF!*(106/16)*12 -> #REF! | K27: =InputsNZ!#REF!*(106/16)*12 -> #REF! | ... M27: =InputsNZ!#REF!*(106/16)*12 -> #REF!
A28: 26 | B28: Myct Scaled Salp Consumption | C28: (mg C m-2 d-1) | D28: =InputsNZ!#REF!*(106/16)*12 -> #REF! | E28: =InputsNZ!#REF!*(106/16)*12 -> #REF! | F28: =InputsNZ!#REF!*(106/16)*12 -> #REF! | G28: =InputsNZ!#REF!*(106/16)*12 -> #REF! | H28: =InputsNZ!#REF!*(106/16)*12 -> #REF! | I28: =InputsNZ!#REF!*(106/16)*12 -> #REF! | J28: =InputsNZ!#REF!*(106/16)*12 -> #REF! | K28: =InputsNZ!#REF!*(106/16)*12 -> #REF! | ... M28: =InputsNZ!#REF!*(106/16)*12 -> #REF!
A29: 27 | B29: Myct Scaled Gel Consumption | C29: (mg C m-2 d-1) | D29: =InputsNZ!#REF!*(106/16)*12 -> #REF! | E29: =InputsNZ!#REF!*(106/16)*12 -> #REF! | F29: =InputsNZ!#REF!*(106/16)*12 -> #REF! | G29: =InputsNZ!#REF!*(106/16)*12 -> #REF! | H29: =InputsNZ!#REF!*(106/16)*12 -> #REF! | I29: =InputsNZ!#REF!*(106/16)*12 -> #REF! | J29: =InputsNZ!#REF!*(106/16)*12 -> #REF! | K29: =InputsNZ!#REF!*(106/16)*12 -> #REF! | ... M29: =InputsNZ!#REF!*(106/16)*12 -> #REF!
A30: 28 | B30: PiscivFish Scaled Myct Consumption | C30: (mg C m-2 d-1) | D30: =InputsNZ!#REF!*(106/16)*12 -> #REF! | E30: =InputsNZ!#REF!*(106/16)*12 -> #REF! | F30: =InputsNZ!#REF!*(106/16)*12 -> #REF! | G30: =InputsNZ!#REF!*(106/16)*12 -> #REF! | H30: =InputsNZ!#REF!*(106/16)*12 -> #REF! | I30: =InputsNZ!#REF!*(106/16)*12 -> #REF! | J30: =InputsNZ!#REF!*(106/16)*12 -> #REF! | K30: =InputsNZ!#REF!*(106/16)*12 -> #REF! | ... M30: =InputsNZ!#REF!*(106/16)*12 -> #REF!
A31: 29 | B31: PiscivFish Scaled Macro Consumption | C31: (mg C m-2 d-1) | D31: =InputsNZ!#REF!*(106/16)*12 -> #REF! | E31: =InputsNZ!#REF!*(106/16)*12 -> #REF! | F31: =InputsNZ!#REF!*(106/16)*12 -> #REF! | G31: =InputsNZ!#REF!*(106/16)*12 -> #REF! | H31: =InputsNZ!#REF!*(106/16)*12 -> #REF! | I31: =InputsNZ!#REF!*(106/16)*12 -> #REF! | J31: =InputsNZ!#REF!*(106/16)*12 -> #REF! | K31: =InputsNZ!#REF!*(106/16)*12 -> #REF! | ... M31: =InputsNZ!#REF!*(106/16)*12 -> #REF!
A32: 30 | B32: PiscivFish Scaled VMMacro Consumption | C32: (mg C m-2 d-1) | D32: =InputsNZ!#REF!*(106/16)*12 -> #REF! | E32: =InputsNZ!#REF!*(106/16)*12 -> #REF! | F32: =InputsNZ!#REF!*(106/16)*12 -> #REF! | G32: =InputsNZ!#REF!*(106/16)*12 -> #REF! | H32: =InputsNZ!#REF!*(106/16)*12 -> #REF! | I32: =InputsNZ!#REF!*(106/16)*12 -> #REF! | J32: =InputsNZ!#REF!*(106/16)*12 -> #REF! | K32: =InputsNZ!#REF!*(106/16)*12 -> #REF! | ... M32: =InputsNZ!#REF!*(106/16)*12 -> #REF!
A33: 31 | B33: PiscivFish Scaled Amph Consumption | C33: (mg C m-2 d-1) | D33: =InputsNZ!#REF!*(106/16)*12 -> #REF! | E33: =InputsNZ!#REF!*(106/16)*12 -> #REF! | F33: =InputsNZ!#REF!*(106/16)*12 -> #REF! | G33: =InputsNZ!#REF!*(106/16)*12 -> #REF! | H33: =InputsNZ!#REF!*(106/16)*12 -> #REF! | I33: =InputsNZ!#REF!*(106/16)*12 -> #REF! | J33: =InputsNZ!#REF!*(106/16)*12 -> #REF! | K33: =InputsNZ!#REF!*(106/16)*12 -> #REF! | ... M33: =InputsNZ!#REF!*(106/16)*12 -> #REF!
A34: 32 | B34: GelativFish Scaled Salp Consumption | C34: (mg C m-2 d-1) | D34: =InputsNZ!#REF!*(106/16)*12 -> #REF! | E34: =InputsNZ!#REF!*(106/16)*12 -> #REF! | F34: =InputsNZ!#REF!*(106/16)*12 -> #REF! | G34: =InputsNZ!#REF!*(106/16)*12 -> #REF! | H34: =InputsNZ!#REF!*(106/16)*12 -> #REF! | I34: =InputsNZ!#REF!*(106/16)*12 -> #REF! | J34: =InputsNZ!#REF!*(106/16)*12 -> #REF! | K34: =InputsNZ!#REF!*(106/16)*12 -> #REF! | ... M34: =InputsNZ!#REF!*(106/16)*12 -> #REF!
A35: 33 | B35: GelativFish Scaled Gel Consumption | C35: (mg C m-2 d-1) | D35: =InputsNZ!#REF!*(106/16)*12 -> #REF! | E35: =InputsNZ!#REF!*(106/16)*12 -> #REF! | F35: =InputsNZ!#REF!*(106/16)*12 -> #REF! | G35: =InputsNZ!#REF!*(106/16)*12 -> #REF! | H35: =InputsNZ!#REF!*(106/16)*12 -> #REF! | I35: =InputsNZ!#REF!*(106/16)*12 -> #REF! | J35: =InputsNZ!#REF!*(106/16)*12 -> #REF! | K35: =InputsNZ!#REF!*(106/16)*12 -> #REF! | ... M35: =InputsNZ!#REF!*(106/16)*12 -> #REF!
A37: Inequality Inputs
A38: 1 | B38: Temperature (0-70) | C38: deg C | D38: 10.240493 | E38: 0.5896211 | F38: 9.897492 | G38: 0.4112118 | H38: 13.090224 | I38: 0.3273925 | J38: 12.122057 | K38: 0.5916513 | L38: 10.688394 | M38: 0.5750481
A39: 2 | B39: Temperature (200) | C39: deg C | D39: 9.397415 | F39: 7.915702 | H39: 11.465439 | J39: 9.652742 | L39: 7.9416
A40: 3 | B40: Temperature (bottom 100) | C40: deg C | D40: 5.73695 | F40: 2.882 | H40: 4.9304 | J40: 8.341335 | L40: 1.8084
A41: 4 | B41: Bottom Depth | C41: m | D41: 884.2632 | F41: 1501.6923 | H41: 1046.5 | J41: 449.5 | L41: 2635.1
...

Sheet Sheet3
B1: units | C1: Cycle 1 | D1: σ | E1: Cycle 2 | F1: σ | G1: Cycle 3 | H1: σ | I1: Cycle 4 | J1: σ | K1: Cycle 5 | L1: σ
A2: NPP (14C) | B2: (mg C m-2 d-1) | C2: =ROUND(InputsNZ_C!D3,1) -> 554.5 | D2: =ROUND(InputsNZ_C!E3,1) -> 167.4 | E2: =ROUND(InputsNZ_C!F3,1) -> 321.4 | F2: =ROUND(InputsNZ_C!G3,1) -> 62.2 | G2: =ROUND(InputsNZ_C!H3,1) -> 781 | H2: =ROUND(InputsNZ_C!I3,1) -> 361.8 | I2: =ROUND(InputsNZ_C!J3,1) -> 452.3 | J2: =ROUND(InputsNZ_C!K3,1) -> 102.1 | ... L2: =ROUND(InputsNZ_C!M3,1) -> 30.4
A3: SedTrap Flux (shallow) | B3: (mg C m-2 d-1) | C3: =ROUND(InputsNZ_C!D4,1) -> 77.8 | D3: =ROUND(InputsNZ_C!E4,1) -> 15.9 | E3: =ROUND(InputsNZ_C!F4,1) -> 129.9 | F3: =ROUND(InputsNZ_C!G4,1) -> 4.5 | G3: =ROUND(InputsNZ_C!H4,1) -> 37.3 | H3: =ROUND(InputsNZ_C!I4,1) -> 2.4 | I3: =ROUND(InputsNZ_C!J4,1) -> 142.2 | J3: =ROUND(InputsNZ_C!K4,1) -> 47.4 | ... L3: =ROUND(InputsNZ_C!M4,1) -> 14.4
A4: Pico NPP | B4: (mg C m-2 d-1) | C4: =ROUND(InputsNZ_C!D5,1) -> 169 | D4: =ROUND(InputsNZ_C!E5,1) -> 121.6 | E4: =ROUND(InputsNZ_C!F5,1) -> 245.4 | F4: =ROUND(InputsNZ_C!G5,1) -> 73 | G4: =ROUND(InputsNZ_C!H5,1) -> 515.9 | H4: =ROUND(InputsNZ_C!I5,1) -> 378.2 | I4: =ROUND(InputsNZ_C!J5,1) -> 274.8 | J4: =ROUND(InputsNZ_C!K5,1) -> 177.7 | ... L4: =ROUND(InputsNZ_C!M5,1) -> 302.8
A5: Flag NPP | B5: (mg C m-2 d-1) | C5: =ROUND(InputsNZ_C!D6,1) -> 131.2 | D5: =ROUND(InputsNZ_C!E6,1) -> 66.4 | E5: =ROUND(InputsNZ_C!F6,1) -> 27.5 | F5: =ROUND(InputsNZ_C!G6,1) -> 39.8 | G5: =ROUND(InputsNZ_C!H6,1) -> 216 | H5: =ROUND(InputsNZ_C!I6,1) -> 265.6 | I5: =ROUND(InputsNZ_C!J6,1) -> 157.8 | J5: =ROUND(InputsNZ_C!K6,1) -> 157.1 | ... L5: =ROUND(InputsNZ_C!M6,1) -> 271.2
A6: Diatom NPP | B6: (mg C m-2 d-1) | C6: =ROUND(InputsNZ_C!D7,1) -> 254.3 | D6: =ROUND(InputsNZ_C!E7,1) -> 162.1 | E6: =ROUND(InputsNZ_C!F7,1) -> 28.7 | F6: =ROUND(InputsNZ_C!G7,1) -> 18.6 | G6: =ROUND(InputsNZ_C!H7,1) -> 49.1 | H6: =ROUND(InputsNZ_C!I7,1) -> 44.7 | I6: =ROUND(InputsNZ_C!J7,1) -> 19.7 | J6: =ROUND(InputsNZ_C!K7,1) -> 12.3 | ... L6: =ROUND(InputsNZ_C!M7,1) -> 17.1
A7: Picophyto Mortality | B7: (mg C m-2 d-1) | C7: =ROUND(InputsNZ_C!D8,1) -> 77 | D7: =ROUND(InputsNZ_C!E8,1) -> 61.6 | E7: =ROUND(InputsNZ_C!F8,1) -> 150.2 | F7: =ROUND(InputsNZ_C!G8,1) -> 58.1 | G7: =ROUND(InputsNZ_C!H8,1) -> 277.9 | H7: =ROUND(InputsNZ_C!I8,1) -> 199.9 | I7: =ROUND(InputsNZ_C!J8,1) -> 168.5 | J7: =ROUND(InputsNZ_C!K8,1) -> 102.8 | ... L7: =ROUND(InputsNZ_C!M8,1) -> 74.4
A8: Flagellate Mortality | B8: (mg C m-2 d-1) | C8: =ROUND(InputsNZ_C!D9,1) -> 74 | D8: =ROUND(InputsNZ_C!E9,1) -> 83.7 | E8: =ROUND(InputsNZ_C!F9,1) -> 38.5 | F8: =ROUND(InputsNZ_C!G9,1) -> 42.5 | G8: =ROUND(InputsNZ_C!H9,1) -> 125.1 | H8: =ROUND(InputsNZ_C!I9,1) -> 141.9 | I8: =ROUND(InputsNZ_C!J9,1) -> 182.5 | J8: =ROUND(InputsNZ_C!K9,1) -> 114.3 | ... L8: =ROUND(InputsNZ_C!M9,1) -> 188.2
A9: Diatom Mortality | B9: (mg C m-2 d-1) | C9: =ROUND(InputsNZ_C!D10,1) -> 128 | D9: =ROUND(InputsNZ_C!E10,1) -> 90.8 | E9: =ROUND(InputsNZ_C!F10,1) -> 6.6 | F9: =ROUND(InputsNZ_C!G10,1) -> 2.8 | G9: =ROUND(InputsNZ_C!H10,1) -> 24.1 | H9: =ROUND(InputsNZ_C!I10,1) -> 21.2 | I9: =ROUND(InputsNZ_C!J10,1) -> 14.9 | J9: =ROUND(InputsNZ_C!K10,1) -> 9.6 | ... L9: =ROUND(InputsNZ_C!M10,1) -> 10.7
A10: Protistan Grazing Rate (14C) | B10: (mg C m-2 d-1) | C10: =ROUND(InputsNZ_C!D11,1) -> 279 | D10: =ROUND(InputsNZ_C!E11,1) -> 100.6 | E10: =ROUND(InputsNZ_C!F11,1) -> 214.1 | F10: =ROUND(InputsNZ_C!G11,1) -> 48.5 | G10: =ROUND(InputsNZ_C!H11,1) -> 427.1 | H10: =ROUND(InputsNZ_C!I11,1) -> 236.5 | I10: =ROUND(InputsNZ_C!J11,1) -> 365.9 | J10: =ROUND(InputsNZ_C!K11,1) -> 173.1 | ... L10: =ROUND(InputsNZ_C!M11,1) -> 68.9
A11: Mesozoo Grazing | B11: (mg C m-2 d-1) | C11: =ROUND(InputsNZ_C!D12,1) -> 72.3 | D11: =ROUND(InputsNZ_C!E12,1) -> 14.7 | E11: =ROUND(InputsNZ_C!F12,1) -> 55.5 | F11: =ROUND(InputsNZ_C!G12,1) -> 26.3 | G11: =ROUND(InputsNZ_C!H12,1) -> 19.3 | H11: =ROUND(InputsNZ_C!I12,1) -> 7.9 | I11: =ROUND(InputsNZ_C!J12,1) -> 25.9 | J11: =ROUND(InputsNZ_C!K12,1) -> 9.1 | ... L11: =ROUND(InputsNZ_C!M12,1) -> 12.8
A12: VMMeso Grazing | B12: (mg C m-2 d-1) | C12: NA | D12: NA | E12: =ROUND(InputsNZ_C!F13,1) -> 30.1 | F12: =ROUND(InputsNZ_C!G13,1) -> 17.6 | G12: =ROUND(InputsNZ_C!H13,1) -> 10.5 | H12: =ROUND(InputsNZ_C!I13,1) -> 3.1 | I12: =ROUND(InputsNZ_C!J13,1) -> 5.8 | J12: =ROUND(InputsNZ_C!K13,1) -> 8.5 | K12: =ROUND(InputsNZ_C!L13,1) -> 16.7 | L12: =ROUND(InputsNZ_C!M13,1) -> 10.3
A13: Macrozoo Grazing | B13: (mg C m-2 d-1) | C13: =ROUND(InputsNZ_C!D14,1) -> 2.2 | D13: =ROUND(InputsNZ_C!E14,1) -> 2.2 | E13: =ROUND(InputsNZ_C!F14,1) -> 2.6 | F13: =ROUND(InputsNZ_C!G14,1) -> 6 | G13: =ROUND(InputsNZ_C!H14,1) -> 0.6 | H13: =ROUND(InputsNZ_C!I14,1) -> 0.9 | I13: =ROUND(InputsNZ_C!J14,1) -> 0.9 | J13: =ROUND(InputsNZ_C!K14,1) -> 1.1 | ... L13: =ROUND(InputsNZ_C!M14,1) -> 2
A14: VMMacro Grazing | B14: (mg C m-2 d-1) | C14: =ROUND(InputsNZ_C!D15,1) -> 0.7 | D14: =ROUND(InputsNZ_C!E15,1) -> 1 | E14: =ROUND(InputsNZ_C!F15,1) -> 1.7 | F14: =ROUND(InputsNZ_C!G15,1) -> 3.7 | G14: =ROUND(InputsNZ_C!H15,1) -> 0.3 | H14: =ROUND(InputsNZ_C!I15,1) -> 0.5 | I14: =ROUND(InputsNZ_C!J15,1) -> 0.3 | J14: =ROUND(InputsNZ_C!K15,1) -> 0.8 | ... L14: =ROUND(InputsNZ_C!M15,1) -> 1
A15: Salp Autotroph Grazing | B15: (mg C m-2 d-1) | C15: =ROUND(InputsNZ_C!D16,1) -> 211.4 | D15: =ROUND(InputsNZ_C!E16,1) -> 151.6 | E15: =ROUND(InputsNZ_C!F16,1) -> 139.7 | F15: =ROUND(InputsNZ_C!G16,1) -> 73.1 | G15: =ROUND(InputsNZ_C!H16,1) -> 2 | H15: =ROUND(InputsNZ_C!I16,1) -> 2.2 | I15: =ROUND(InputsNZ_C!J16,1) -> 126.9 | J15: =ROUND(InputsNZ_C!K16,1) -> 77.5 | ... L15: =ROUND(InputsNZ_C!M16,1) -> 1.3
A16: Salp Heterotroph Grazing | B16: (mg C m-2 d-1) | C16: =ROUND(InputsNZ_C!D17,1) -> 150 | D16: =ROUND(InputsNZ_C!E17,1) -> 133.5 | E16: =ROUND(InputsNZ_C!F17,1) -> 59.3 | F16: =ROUND(InputsNZ_C!G17,1) -> 449.7 | G16: =ROUND(InputsNZ_C!H17,1) -> 0.6 | H16: =ROUND(InputsNZ_C!I17,1) -> 1 | I16: =ROUND(InputsNZ_C!J17,1) -> 29.2 | J16: =ROUND(InputsNZ_C!K17,1) -> 39.6 | ... L16: =ROUND(InputsNZ_C!M17,1) -> 0.1
A17: PicoTOSalp | B17: (mg C m-2 d-1) | C17: =ROUND(InputsNZ_C!D18,1) -> 5.2 | D17: =ROUND(InputsNZ_C!E18,1) -> 2.9 | E17: =ROUND(InputsNZ_C!F18,1) -> 5.5 | F17: =ROUND(InputsNZ_C!G18,1) -> 12.7 | G17: =ROUND(InputsNZ_C!H18,1) -> 0.2 | H17: =ROUND(InputsNZ_C!I18,1) -> 0.2 | I17: =ROUND(InputsNZ_C!J18,1) -> 5.7 | J17: =ROUND(InputsNZ_C!K18,1) -> 3.2 | ... L17: =ROUND(InputsNZ_C!M18,1) -> 0
A18: DtmTOSalp | B18: (mg C m-2 d-1) | C18: =ROUND(InputsNZ_C!D19,1) -> 66.4 | D18: =ROUND(InputsNZ_C!E19,1) -> 37.1 | E18: =ROUND(InputsNZ_C!F19,1) -> 18.5 | F18: =ROUND(InputsNZ_C!G19,1) -> 42.5 | G18: =ROUND(InputsNZ_C!H19,1) -> 0 | H18: =ROUND(InputsNZ_C!I19,1) -> 0 | I18: =ROUND(InputsNZ_C!J19,1) -> 0 | J18: =ROUND(InputsNZ_C!K19,1) -> 0 | ... L18: =ROUND(InputsNZ_C!M19,1) -> 0.1
A19: OtherTOSalp | B19: (mg C m-2 d-1) | C19: =ROUND(InputsNZ_C!D20,1) -> 289.8 | D19: =ROUND(InputsNZ_C!E20,1) -> 162 | E19: =ROUND(InputsNZ_C!F20,1) -> 175 | F19: =ROUND(InputsNZ_C!G20,1) -> 400.4 | G19: =ROUND(InputsNZ_C!H20,1) -> 2.3 | H19: =ROUND(InputsNZ_C!I20,1) -> 2.2 | I19: =ROUND(InputsNZ_C!J20,1) -> 150.4 | J19: =ROUND(InputsNZ_C!K20,1) -> 83.9 | ... L19: =ROUND(InputsNZ_C!M20,1) -> 1.1
A20: Salp Fecal Pellet Production | B20: (mg C m-2 d-1) | C20: =ROUND(InputsNZ_C!D21,1) -> 76.1 | D20: =ROUND(InputsNZ_C!E21,1) -> 54.6 | E20: =ROUND(InputsNZ_C!F21,1) -> 50.3 | F20: =ROUND(InputsNZ_C!G21,1) -> 26.3 | G20: =ROUND(InputsNZ_C!H21,1) -> 0.7 | H20: =ROUND(InputsNZ_C!I21,1) -> 0.8 | I20: =ROUND(InputsNZ_C!J21,1) -> 45.7 | J20: =ROUND(InputsNZ_C!K21,1) -> 27.9 | ... L20: =ROUND(InputsNZ_C!M21,1) -> 0.5
A21: Bacterial Production | B21: (mg C m-2 d-1) | C21: =ROUND(InputsNZ_C!D22,1) -> 61.1 | D21: =ROUND(InputsNZ_C!E22,1) -> 12.3 | E21: =ROUND(InputsNZ_C!F22,1) -> 40.7 | F21: =ROUND(InputsNZ_C!G22,1) -> 14.1 | G21: =ROUND(InputsNZ_C!H22,1) -> 65.3 | H21: =ROUND(InputsNZ_C!I22,1) -> 14.8 | I21: =ROUND(InputsNZ_C!J22,1) -> 58.1 | J21: =ROUND(InputsNZ_C!K22,1) -> 15.9 | ... L21: =ROUND(InputsNZ_C!M22,1) -> 8.4
A22: Myct Scaled Meso Consumption | B22: (ug C m-2 d-1) | C22: =ROUND(InputsNZ_C!D23*1000,1) -> #REF! | D22: =ROUND(InputsNZ_C!E23*1000,1) -> #REF! | E22: =ROUND(InputsNZ_C!F23*1000,1) -> #REF! | F22: =ROUND(InputsNZ_C!G23*1000,1) -> #REF! | G22: =ROUND(InputsNZ_C!H23*1000,1) -> #REF! | H22: =ROUND(InputsNZ_C!I23*1000,1) -> #REF! | I22: =ROUND(InputsNZ_C!J23*1000,1) -> #REF! | J22: =ROUND(InputsNZ_C!K23*1000,1) -> #REF! | ... L22: =ROUND(InputsNZ_C!M23*1000,1) -> #REF!
A23: Myct Scaled VMMeso Consumption | B23: (ug C m-2 d-1) | C23: =ROUND(InputsNZ_C!D24*1000,1) -> #REF! | D23: =ROUND(InputsNZ_C!E24*1000,1) -> #REF! | E23: =ROUND(InputsNZ_C!F24*1000,1) -> #REF! | F23: =ROUND(InputsNZ_C!G24*1000,1) -> #REF! | G23: =ROUND(InputsNZ_C!H24*1000,1) -> #REF! | H23: =ROUND(InputsNZ_C!I24*1000,1) -> #REF! | I23: =ROUND(InputsNZ_C!J24*1000,1) -> #REF! | J23: =ROUND(InputsNZ_C!K24*1000,1) -> #REF! | ... L23: =ROUND(InputsNZ_C!M24*1000,1) -> #REF!
A24: Myct Scaled Macro Consumption | B24: (ug C m-2 d-1) | C24: =ROUND(InputsNZ_C!D25*1000,1) -> #REF! | D24: =ROUND(InputsNZ_C!E25*1000,1) -> #REF! | E24: =ROUND(InputsNZ_C!F25*1000,1) -> #REF! | F24: =ROUND(InputsNZ_C!G25*1000,1) -> #REF! | G24: =ROUND(InputsNZ_C!H25*1000,1) -> #REF! | H24: =ROUND(InputsNZ_C!I25*1000,1) -> #REF! | I24: =ROUND(InputsNZ_C!J25*1000,1) -> #REF! | J24: =ROUND(InputsNZ_C!K25*1000,1) -> #REF! | ... L24: =ROUND(InputsNZ_C!M25*1000,1) -> #REF!
A25: Myct Scaled VMMacro Consumption | B25: (ug C m-2 d-1) | C25: =ROUND(InputsNZ_C!D26*1000,1) -> #REF! | D25: =ROUND(InputsNZ_C!E26*1000,1) -> #REF! | E25: =ROUND(InputsNZ_C!F26*1000,1) -> #REF! | F25: =ROUND(InputsNZ_C!G26*1000,1) -> #REF! | G25: =ROUND(InputsNZ_C!H26*1000,1) -> #REF! | H25: =ROUND(InputsNZ_C!I26*1000,1) -> #REF! | I25: =ROUND(InputsNZ_C!J26*1000,1) -> #REF! | J25: =ROUND(InputsNZ_C!K26*1000,1) -> #REF! | ... L25: =ROUND(InputsNZ_C!M26*1000,1) -> #REF!
A26: Myct Scaled Amph Consumption | B26: (ug C m-2 d-1) | C26: =ROUND(InputsNZ_C!D27*1000,1) -> #REF! | D26: =ROUND(InputsNZ_C!E27*1000,1) -> #REF! | E26: =ROUND(InputsNZ_C!F27*1000,1) -> #REF! | F26: =ROUND(InputsNZ_C!G27*1000,1) -> #REF! | G26: =ROUND(InputsNZ_C!H27*1000,1) -> #REF! | H26: =ROUND(InputsNZ_C!I27*1000,1) -> #REF! | I26: =ROUND(InputsNZ_C!J27*1000,1) -> #REF! | J26: =ROUND(InputsNZ_C!K27*1000,1) -> #REF! | ... L26: =ROUND(InputsNZ_C!M27*1000,1) -> #REF!
A27: Myct Scaled Salp Consumption | B27: (ug C m-2 d-1) | C27: =ROUND(InputsNZ_C!D28*1000,1) -> #REF! | D27: =ROUND(InputsNZ_C!E28*1000,1) -> #REF! | E27: =ROUND(InputsNZ_C!F28*1000,1) -> #REF! | F27: =ROUND(InputsNZ_C!G28*1000,1) -> #REF! | G27: =ROUND(InputsNZ_C!H28*1000,1) -> #REF! | H27: =ROUND(InputsNZ_C!I28*1000,1) -> #REF! | I27: =ROUND(InputsNZ_C!J28*1000,1) -> #REF! | J27: =ROUND(InputsNZ_C!K28*1000,1) -> #REF! | ... L27: =ROUND(InputsNZ_C!M28*1000,1) -> #REF!
A28: Myct Scaled Gel Consumption | B28: (ug C m-2 d-1) | C28: =ROUND(InputsNZ_C!D29*1000,1) -> #REF! | D28: =ROUND(InputsNZ_C!E29*1000,1) -> #REF! | E28: =ROUND(InputsNZ_C!F29*1000,1) -> #REF! | F28: =ROUND(InputsNZ_C!G29*1000,1) -> #REF! | G28: =ROUND(InputsNZ_C!H29*1000,1) -> #REF! | H28: =ROUND(InputsNZ_C!I29*1000,1) -> #REF! | I28: =ROUND(InputsNZ_C!J29*1000,1) -> #REF! | J28: =ROUND(InputsNZ_C!K29*1000,1) -> #REF! | ... L28: =ROUND(InputsNZ_C!M29*1000,1) -> #REF!
A29: PiscivFish Scaled Myct Consumption | B29: (ug C m-2 d-1) | C29: =ROUND(InputsNZ_C!D30*1000,1) -> #REF! | D29: =ROUND(InputsNZ_C!E30*1000,1) -> #REF! | E29: =ROUND(InputsNZ_C!F30*1000,1) -> #REF! | F29: =ROUND(InputsNZ_C!G30*1000,1) -> #REF! | G29: =ROUND(InputsNZ_C!H30*1000,1) -> #REF! | H29: =ROUND(InputsNZ_C!I30*1000,1) -> #REF! | I29: =ROUND(InputsNZ_C!J30*1000,1) -> #REF! | J29: =ROUND(InputsNZ_C!K30*1000,1) -> #REF! | ... L29: =ROUND(InputsNZ_C!M30*1000,1) -> #REF!
A30: PiscivFish Scaled Macro Consumption | B30: (ug C m-2 d-1) | C30: =ROUND(InputsNZ_C!D31*1000,1) -> #REF! | D30: =ROUND(InputsNZ_C!E31*1000,1) -> #REF! | E30: =ROUND(InputsNZ_C!F31*1000,1) -> #REF! | F30: =ROUND(InputsNZ_C!G31*1000,1) -> #REF! | G30: =ROUND(InputsNZ_C!H31*1000,1) -> #REF! | H30: =ROUND(InputsNZ_C!I31*1000,1) -> #REF! | I30: =ROUND(InputsNZ_C!J31*1000,1) -> #REF! | J30: =ROUND(InputsNZ_C!K31*1000,1) -> #REF! | ... L30: =ROUND(InputsNZ_C!M31*1000,1) -> #REF!
A31: PiscivFish Scaled VMMacro Consumption | B31: (ug C m-2 d-1) | C31: =ROUND(InputsNZ_C!D32*1000,1) -> #REF! | D31: =ROUND(InputsNZ_C!E32*1000,1) -> #REF! | E31: =ROUND(InputsNZ_C!F32*1000,1) -> #REF! | F31: =ROUND(InputsNZ_C!G32*1000,1) -> #REF! | G31: =ROUND(InputsNZ_C!H32*1000,1) -> #REF! | H31: =ROUND(InputsNZ_C!I32*1000,1) -> #REF! | I31: =ROUND(InputsNZ_C!J32*1000,1) -> #REF! | J31: =ROUND(InputsNZ_C!K32*1000,1) -> #REF! | ... L31: =ROUND(InputsNZ_C!M32*1000,1) -> #REF!
A32: PiscivFish Scaled Amph Consumption | B32: (ug C m-2 d-1) | C32: =ROUND(InputsNZ_C!D33*1000,1) -> #REF! | D32: =ROUND(InputsNZ_C!E33*1000,1) -> #REF! | E32: =ROUND(InputsNZ_C!F33*1000,1) -> #REF! | F32: =ROUND(InputsNZ_C!G33*1000,1) -> #REF! | G32: =ROUND(InputsNZ_C!H33*1000,1) -> #REF! | H32: =ROUND(InputsNZ_C!I33*1000,1) -> #REF! | I32: =ROUND(InputsNZ_C!J33*1000,1) -> #REF! | J32: =ROUND(InputsNZ_C!K33*1000,1) -> #REF! | ... L32: =ROUND(InputsNZ_C!M33*1000,1) -> #REF!
