Workbook

Sheet InputsNZ
A1: Approximate Equalities
C2: units | D2: Cycle 1 | E2: σ | F2: Cycle 2 | G2: σ | H2: Cycle 3 | I2: σ | J2: Cycle 4 | K2: σ | L2: Cycle 5 | M2: σ
A3: 1 | B3: NPP (14C) | C3: (mmol N m-2 d-1) | D3: 6.9751396 | E3: 2.1054147 | F3: 4.0433304 | G3: 0.782773 | H3: 9.8238143 | I3: 4.5503874 | J3: 5.6894075 | K3: 1.2846958 | L3: 3.1620202 | M3: 0.38276057
A4: 2 | B4: SedTrap Flux (shallow) | C4: (mmol N m-2 d-1) | D4: 0.97868813 | E4: 0.20023276 | F4: 1.634325 | G4: 0.056975159 | H4: 0.46955162 | I4: 0.029864707 | J4: 1.78897 | K4: 0.59585481 | L4: 0.4195884 | M4: 0.18168493
A5: 3 | B5: Pico NPP | C5: (mmol N m-2 d-1) | D5: =D3*NZ_Extra!D6 -> 2.1257041 | E5: =D5*SQRT((E3/D3)^2+(NZ_Extra!E6/NZ_Extra!D6)^2) -> 1.5292454 | F5: =F3*NZ_Extra!F6 -> 3.0867581 | G5: =F5*SQRT((G3/F3)^2+(NZ_Extra!G6/NZ_Extra!F6)^2) -> 0.91836993 | H5: =H3*NZ_Extra!H6 -> 6.4892367 | I5: =H5*SQRT((I3/H3)^2+(NZ_Extra!I6/NZ_Extra!H6)^2) -> 4.7574096 | J5: =J3*NZ_Extra!J6 -> 3.4570988 | K5: =J5*SQRT((K3/J3)^2+(NZ_Extra!K6/NZ_Extra!J6)^2) -> 2.235291 | L5: =L3*NZ_Extra!L6 -> 2.8354624 | M5: =L5*SQRT((M3/L3)^2+(NZ_Extra!M6/NZ_Extra!L6)^2) -> 3.809041
A6: 4 | B6: Flag NPP | C6: (mmol N m-2 d-1) | D6: =D3*NZ_Extra!D7 -> 1.6509193 | E6: =D6*SQRT((E3/D3)^2+(NZ_Extra!E7/NZ_Extra!D7)^2) -> 0.83512694 | F6: =F3*NZ_Extra!F7 -> 0.3456774 | G6: =F6*SQRT((G3/F3)^2+(NZ_Extra!G7/NZ_Extra!F7)^2) -> 0.50067474 | H6: =H3*NZ_Extra!H7 -> 2.7169 | I6: =H6*SQRT((I3/H3)^2+(NZ_Extra!I7/NZ_Extra!H7)^2) -> 3.3405852 | J6: =J3*NZ_Extra!J7 -> 1.9849115 | K6: =J6*SQRT((K3/J3)^2+(NZ_Extra!K7/NZ_Extra!J7)^2) -> 1.9757686 | L6: =L3*NZ_Extra!L7 -> 0.16239399 | M6: =L6*SQRT((M3/L3)^2+(NZ_Extra!M7/NZ_Extra!L7)^2) -> 3.4118451
A7: 5 | B7: Diatom NPP | C7: (mmol N m-2 d-1) | D7: =D3*NZ_Extra!D8 -> 3.1985162 | E7: =D7*SQRT((E3/D3)^2+(NZ_Extra!E8/NZ_Extra!D8)^2) -> 2.0384171 | F7: =F3*NZ_Extra!F8 -> 0.36121242 | G7: =F7*SQRT((G3/F3)^2+(NZ_Extra!G8/NZ_Extra!F8)^2) -> 0.23417384 | H7: =H3*NZ_Extra!H8 -> 0.61767758 | I7: =H7*SQRT((I3/H3)^2+(NZ_Extra!I8/NZ_Extra!H8)^2) -> 0.56187448 | J7: =J3*NZ_Extra!J8 -> 0.24739712 | K7: =J7*SQRT((K3/J3)^2+(NZ_Extra!K8/NZ_Extra!J8)^2) -> 0.15495822 | L7: =L3*NZ_Extra!L8 -> 0.16416388 | M7: =L7*SQRT((M3/L3)^2+(NZ_Extra!M8/NZ_Extra!L8)^2) -> 0.21488912
A8: 6 | B8: Picophyto Mortality | C8: (mmol N m-2 d-1) | D8: =D11*NZ_Extra!D14 -> 0.96803779 | E8: =D8*SQRT((E11/D11)^2+(NZ_Extra!E14/NZ_Extra!D14)^2) -> 0.77464728 | F8: =F11*NZ_Extra!F14 -> 1.8898784 | G8: =F8*SQRT((G11/F11)^2+(NZ_Extra!G14/NZ_Extra!F14)^2) -> 0.73034638 | H8: =H11*NZ_Extra!H14 -> 3.4956498 | I8: =H8*SQRT((I11/H11)^2+(NZ_Extra!I14/NZ_Extra!H14)^2) -> 2.5146744 | J8: =J11*NZ_Extra!J14 -> 2.1195066 | K8: =J8*SQRT((K11/J11)^2+(NZ_Extra!K14/NZ_Extra!J14)^2) -> 1.2931693 | L8: =L11*NZ_Extra!L14 -> 1.249681 | M8: =L8*SQRT((M11/L11)^2+(NZ_Extra!M14/NZ_Extra!L14)^2) -> 0.93631571
A9: 7 | B9: Flagellate Mortality | C9: (mmol N m-2 d-1) | D9: =D11*NZ_Extra!D15 -> 0.93107774 | E9: =D9*SQRT((E11/D11)^2+(NZ_Extra!E15/NZ_Extra!D15)^2) -> 1.0527763 | F9: =F11*NZ_Extra!F15 -> 0.484364 | G9: =F9*SQRT((G11/F11)^2+(NZ_Extra!G15/NZ_Extra!F15)^2) -> 0.53471732 | H9: =H11*NZ_Extra!H15 -> 1.5734107 | I9: =H9*SQRT((I11/H11)^2+(NZ_Extra!I15/NZ_Extra!H15)^2) -> 1.7854607 | J9: =J11*NZ_Extra!J15 -> 2.2956994 | K9: =J9*SQRT((K11/J11)^2+(NZ_Extra!K15/NZ_Extra!J15)^2) -> 1.4378622 | L9: =L11*NZ_Extra!L15 -> 1.5922616 | M9: =L9*SQRT((M11/L11)^2+(NZ_Extra!M15/NZ_Extra!L15)^2) -> 2.3670614
A10: 8 | B10: Diatom Mortality | C10: (mmol N m-2 d-1) | D10: =D11*NZ_Extra!D16 -> 1.6100342 | E10: =D10*SQRT((E11/D11)^2+(NZ_Extra!E16/NZ_Extra!D16)^2) -> 1.1415465 | F10: =F11*NZ_Extra!F16 -> 0.0831399 | G10: =F10*SQRT((G11/F11)^2+(NZ_Extra!G16/NZ_Extra!F16)^2) -> 0.034881401 | H10: =H11*NZ_Extra!H16 -> 0.30286348 | I10: =H10*SQRT((I11/H11)^2+(NZ_Extra!I16/NZ_Extra!H16)^2) -> 0.26697517 | J10: =J11*NZ_Extra!J16 -> 0.18752559 | K10: =J10*SQRT((K11/J11)^2+(NZ_Extra!K16/NZ_Extra!J16)^2) -> 0.12099696 | L10: =L11*NZ_Extra!L16 -> 0.1359202 | M10: =L10*SQRT((M11/L11)^2+(NZ_Extra!M16/NZ_Extra!L16)^2) -> 0.13470708
A11: 9 | B11: Protistan Grazing Rate (14C) | C11: (mmol N m-2 d-1) | D11: 3.5091497 | E11: 1.264978 | F11: 2.6936632 | G11: 0.60951549 | H11: 5.371924 | I11: 2.9742856 | J11: 4.6027316 | K11: 2.1767591 | L11: 2.9778627 | M11: 0.86612577
A12: 10 | B12: Mesozoo Grazing | C12: (mmol N m-2 d-1) | D12: 0.90936712 | E12: 0.18438144 | F12: 0.69786875 | G12: 0.33083743 | H12: 0.24256809 | I12: 0.099091056 | J12: 0.326373 | K12: 0.1143953 | L12: 0.3026578 | M12: 0.16079582 | P12: NPP-Herb
A13: 11 | B13: Macrozoo Grazing | C13: (mmol N m-2 d-1) | D13: 0.027775614 | E13: 0.027788247 | F13: 0.033175155 | G13: 0.075474281 | H13: 0.0078424367 | I13: 0.011119541 | J13: 0.011164564 | K13: 0.01411272 | L13: 0.024892997 | M13: 0.025748037 | O13: 1 | P13: =D3-SUM(D11:D15) -> -0.1391621
A14: 12 | B14: VMMacro Grazing | C14: (mmol N m-2 d-1) | D14: 0.0088005357 | E14: 0.012670302 | F14: 0.020797253 | G14: 0.047029264 | H14: 0.0035417564 | I14: 0.0067117834 | J14: 0.0031993794 | K14: 0.0095212134 | L14: 8.8802004e-05 | M14: 0.012747025 | O14: 2 | P14: =F3-SUM(F11:F15) -> -1.1599386
A15: 13 | B15: Salp Autotroph Grazing | C15: (mmol N m-2 d-1) | D15: 2.6592087 | E15: 1.9074743 | F15: 1.7577646 | G15: 0.91975507 | H15: 0.024739266 | I15: 0.028097449 | J15: 1.5968294 | K15: 0.97512047 | L15: 0.0072143977 | M15: 0.016218315 | O15: 3 | P15: =H3-SUM(H11:H15) -> 4.1731988
A16: 14 | B16: Salp Heterotroph Grazing | C16: (mmol N m-2 d-1) | D16: =(D15/0.58499)*0.41501 -> 1.8865249 | E16: =D16*SQRT((E15/D15)^2+(0.17843/0.58499)^2+(0.17843/0.41501)^2) -> 1.6793412 | F16: =(F15/0.95928)*0.4072 -> 0.74614477 | G16: =F16*SQRT((G15/F15)^2+(0.30768/0.95928)^2+(0.30768/0.04072)^2) -> 5.6564312 | H16: =(H15/0.7689925)*0.23100747 -> 0.0074317438 | I16: =H16*SQRT((I15/H15)^2+(0.28703/0.76899)^2+(0.28703/0.23101)^2) -> 0.012814187 | J16: =(J15/0.81303)*0.18697 -> 0.36721793 | K16: =J16*SQRT((K15/J15)^2+(0.22065/0.81303)^2+(0.22065/0.18697)^2) -> 0.49802123 | L16: =(L15/0.94848)*0.05152 -> 0.00039187518 | M16: =L16*SQRT((M15/L15)^2+(0/0.94848)^2+(0/0.05152)^2) -> 0.00088095433 | O16: 4 | P16: =J3-SUM(J11:J15) -> -0.85089048
A17: 15 | B17: PicoTOSalp | C17: (mmol N m-2 d-1) | D17: =(D15+D16) * 0.0144398 -> 0.065639483 | E17: =D17*SQRT((SQRT((E15)^2+(E16^2))/(D15+D16))^2+(0.00000265298/0.0144398)^2) -> 0.036697114 | F17: =(F15+F16) * 0.02786716 -> 0.069776844 | G17: =F17*SQRT((SQRT((G15)^2+(G16^2))/(F15+F16))^2+(6.398304E-19/0.02786716)^2) -> 0.15969892 | H17: =(H15+H16) * 0.08979186 -> 0.0028886948 | I17: =H17*SQRT((SQRT((I15)^2+(I16^2))/(H15+H16))^2+(0/0.08979186)^2) -> 0.0027729117 | J17: =(J15+J16) * 0.0366902 -> 0.07206129 | K17: =J17*SQRT((SQRT((K15)^2+(K16^2))/(J15+J16))^2+(0/0.0366902)^2) -> 0.040173425 | L17: =(L15+L16) * 0.02808958 -> 0.00021365701 | M17: =L17*SQRT((SQRT((M15)^2+(M16^2))/(L15+L16))^2+(0.0000002335522/0.02808958)^2) -> 0.00045623722 | O17: 5 | P17: =L3-SUM(L11:L15) -> -0.15069648
A18: 16 | B18: DtmTOSalp | C18: (mmol N m-2 d-1) | D18: =(D15+D16) * 0.1836172 -> 0.83467486 | E18: =D18*SQRT((SQRT((E15)^2+(E16^2))/(D15+D16))^2+(0.001733872/0.1836172)^2) -> 0.46670883 | F18: =(F15+F16) * 0.09318711 -> 0.23333208 | G18: =F18*SQRT((SQRT((G15)^2+(G16^2))/(F15+F16))^2+(0.0006530248/0.09318711)^2) -> 0.53403183 | H18: =(H15+H16) * 0.0004796753 -> 1.5431639e-05 | I18: =H18*SQRT((SQRT((I15)^2+(I16^2))/(H15+H16))^2+(0.00001015141/0.0004796753)^2) -> 1.4816716e-05 | J18: =(J15+J16) * 0.000004663878 -> 9.1600772e-06 | K18: =J18*SQRT((SQRT((K15)^2+(K16^2))/(J15+J16))^2+(0/0.000004663878)^2) -> 5.1066484e-06 | L18: =(L15+L16) * 0.09488286 -> 0.00072170493 | M18: =L18*SQRT((SQRT((M15)^2+(M16^2))/(L15+L16))^2+(0.000609438/0.09488286)^2) -> 0.0015411155
A19: 17 | B19: OtherTOSalp | C19: (mmol N m-2 d-1) | D19: =(D15+D16) * 0.8019303 -> 3.6453615 | E19: =D19*SQRT((SQRT((E15)^2+(E16^2))/(D15+D16))^2+(0.001733677/0.8019303)^2) -> 2.0380301 | F19: =(F15+F16) * 0.8789064 -> 2.200702 | G19: =F19*SQRT((SQRT((G15)^2+(G16^2))/(F15+F16))^2+(0.0006530248/0.8789064)^2) -> 5.0367676 | H19: =(H15+H16) * 0.9097285 -> 0.029266884 | I19: =H19*SQRT((SQRT((I15)^2+(I16^2))/(H15+H16))^2+(0.00001015141/0.9097285)^2) -> 0.028093825 | J19: =(J15+J16) * 0.9633051 -> 1.8919768 | K19: =J19*SQRT((SQRT((K15)^2+(K16^2))/(J15+J16))^2+(0/0.9633051)^2) -> 1.0547575 | L19: =(L15+L16) * 0.8769906 -> 0.0066706299 | M19: =L19*SQRT((SQRT((M15)^2+(M16^2))/(L15+L16))^2+(0.0006094337/0.8769906)^2) -> 0.014244278
A20: 18 | B20: Salp Fecal Pellet Production | C20: (mmol N m-2 d-1) | D20: 0.95731512 | E20: 0.68669075 | F20: 0.63279526 | G20: 0.33111182 | H20: 0.0089061358 | I20: 0.010115082 | J20: 0.57485859 | K20: 0.35104337 | L20: 0.0025971832 | M20: 0.0058385932
A21: 19 | B21: Bacterial Production | C21: (mmol N m-2 d-1) | D21: 0.76851397 | E21: 0.15497851 | F21: 0.51195866 | G21: 0.17726619 | H21: 0.82093159 | I21: 0.1864646 | J21: 0.73073094 | K21: 0.19985947 | L21: 0.44078467 | M21: 0.10558125
A22: 20 | B22: Myct Scaled Meso Consumption | C22: (mmol N m-2 d-1) | D22: 0.058469954 | E22: 0.029234977 | F22: 0.030570928 | G22: 0.015285464 | H22: 0.086478872 | I22: 0.043239436 | J22: 0.042115579 | K22: 0.021057789 | L22: 0.0074863178 | M22: 0.0037431589 | O22: =SUM(D22,D23:D27) -> 0.21638659 | P22: =SUM(F22:F27) -> 0.12837552 | Q22: =SUM(H22:H27) -> 0.10265042 | R22: =SUM(J22:J27) -> 0.14044903 | S22: =SUM(L22:L27) -> 0.01704095
A23: 21 | B23: Myct Scaled Macro Consumption | C23: (mmol N m-2 d-1) | D23: 0.0013413623 | E23: 0.00067068114 | F23: 0.0044290992 | G23: 0.0022145496 | H23: 0.0026256933 | I23: 0.0013128466 | J23: 0.0012998958 | K23: 0.00064994789 | L23: 0.0067505401 | M23: 0.0033752701
A24: 22 | B24: Myct Scaled VMMacro Consumption | C24: (mmol N m-2 d-1) | D24: 0.021795859 | E24: 0.01089793 | F24: 0.017501118 | G24: 0.0087505589 | H24: 0.012697541 | I24: 0.0063487703 | J24: 0.0069954704 | K24: 0.0034977352 | L24: 0.0002001868 | M24: 0.0001000934
A25: 23 | B25: Myct Scaled Amph Consumption | C25: (mmol N m-2 d-1) | D25: 0.0018041689 | E25: 0.00090208445 | F25: 7.4452093e-05 | G25: 3.7226046e-05 | H25: 1.9958218e-06 | I25: 9.979109e-07 | J25: 0.00018840562 | K25: 9.4202811e-05 | L25: 0.001810573 | M25: 0.00090528652
A26: 24 | B26: Myct Scaled Salp Consumption | C26: (mmol N m-2 d-1) | D26: 0.13278426 | E26: 0.066392131 | F26: 0.067613192 | G26: 0.033806596 | H26: 0.00063513703 | I26: 0.00031756852 | J26: 0.08928306 | K26: 0.04464153 | L26: 0.00038182328 | M26: 0.00019091164
A27: 25 | B27: Myct Scaled Gel Consumption | C27: (mmol N m-2 d-1) | D27: 0.00019098429 | E27: 9.5492147e-05 | F27: 0.008186727 | G27: 0.0040933635 | H27: 0.0002111813 | I27: 0.00010559065 | J27: 0.00056662382 | K27: 0.00028331191 | L27: 0.00041150921 | M27: 0.0002057546
A28: 26 | B28: PiscivFish Scaled Myct Consumption | C28: (mmol N m-2 d-1) | D28: 0.011091282 | E28: 0.005545641 | F28: 0.011066583 | G28: 0.0055332916 | H28: 0.0092192534 | I28: 0.0046096267 | J28: 0.008526311 | K28: 0.0042631555 | L28: 0.0037655899 | M28: 0.0018827949
A29: 27 | B29: PiscivFish Scaled VMMacro Consumption | C29: (mmol N m-2 d-1) | D29: 0.0020805138 | E29: 0.0010402569 | F29: 0.0016705612 | G29: 0.00083528062 | H29: 0.001212038 | I29: 0.00060601898 | J29: 0.00066774944 | K29: 0.00033387472 | L29: 1.910874e-05 | M29: 9.5543701e-06
A30: 28 | B30: PiscivFish Scaled Amph Consumption | C30: (mmol N m-2 d-1) | D30: 0.00017221612 | E30: 8.6108062e-05 | F30: 7.1067907e-06 | G30: 3.5533953e-06 | H30: 1.9051026e-07 | I30: 9.5255131e-08 | J30: 1.7984173e-05 | K30: 8.9920865e-06 | L30: 0.00017282743 | M30: 8.6413713e-05
A31: 29 | B31: GelativFish Scaled Salp Consumption | C31: (mmol N m-2 d-1) | D31: 0.073086394 | E31: 0.036543197 | F31: 0.037215287 | G31: 0.018607643 | H31: 0.00034958868 | I31: 0.00017479434 | J31: 0.049142698 | K31: 0.024571349 | L31: 0.0002101611 | M31: 0.00010508055
A32: 30 | B32: GelativFish Scaled Gel Consumption | C32: (mmol N m-2 d-1) | D32: 0.00010512054 | E32: 5.256027e-05 | F32: 0.0045060939 | G32: 0.002253047 | H32: 0.00011623727 | I32: 5.8118634e-05 | J32: 0.00031187802 | K32: 0.00015593901 | L32: 0.00022650067 | M32: 0.00011325033
A33: 31 | B33: HTL Scaled Meso Consumption | C33: (mmol N m-2 d-1) | D33: 0.0062117204 | E33: 0.0031058602 | F33: 0.0032477887 | G33: 0.0016238944 | H33: 0.0091873268 | I33: 0.0045936634 | J33: 0.0044742672 | K33: 0.0022371336 | L33: 0.00079533008 | M33: 0.00039766504
A34: 32 | B34: HTL Scaled Macro Consumption | C34: (mmol N m-2 d-1) | D34: 0.00043431282 | E34: 0.00021715641 | F34: 0.0014340753 | G34: 0.00071703767 | H34: 0.00085015978 | I34: 0.00042507989 | J34: 0.0004208866 | K34: 0.0002104433 | L34: 0.0021857228 | M34: 0.0010928614
... A38: 36 | B38: HTL Scaled Gel Consumption | C38: (mmol N m-2 d-1) | D38: 9.5082724e-05 | E38: 4.7541362e-05 | F38: 0.0040758132 | G38: 0.0020379066 | H38: 0.00010513793 | I38: 5.2568965e-05 | J38: 0.00028209721 | K38: 0.00014104861 | L38: 0.00020487243 | M38: 0.00010243622
A40: Inequality Inputs
A41: 1 | B41: Temperature (0-70) | C41: deg C | D41: 10.240493 | E41: 0.5896211 | F41: 9.897492 | G41: 0.4112118 | H41: 13.090224 | I41: 0.3273925 | J41: 12.122057 | K41: 0.5916513 | L41: 10.688394 | M41: 0.5750481
A42: 2 | B42: Temperature (200) | C42: deg C | D42: 9.397415 | F42: 7.915702 | H42: 11.465439 | J42: 9.652742 | L42: 7.9416
A43: 3 | B43: Temperature (bottom 100) | C43: deg C | D43: 5.73695 | F43: 2.882 | H43: 4.9304 | J43: 8.341335 | L43: 1.8084
A44: 4 | B44: Bottom Depth | C44: m | D44: 884.2632 | F44: 1501.6923 | H44: 1046.5 | J44: 449.5 | L44: 2635.1
...

Sheet InputsNZ (2)
A1: Approximate Equalities
C2: units | D2: Cycle 1 | E2: σ | F2: Cycle 2 | G2: σ | H2: Cycle 3 | I2: σ | J2: Cycle 4 | K2: σ | L2: Cycle 5 | M2: σ
A3: 1 | B3: NPP (14C) | C3: (mmol N m-2 d-1) | D3: 6.9751396 | E3: 2.1054147 | F3: 4.0433304 | G3: 0.782773 | H3: 9.8238143 | I3: 4.5503874 | J3: 5.6894075 | K3: 1.2846958 | L3: 3.1620202 | M3: 0.38276057
A4: 2 | B4: SedTrap Flux (shallow) | C4: (mmol N m-2 d-1) | D4: 0.97868813 | E4: 0.20023276 | F4: 1.634325 | G4: 0.056975159 | H4: 0.46955162 | I4: 0.029864707 | J4: 1.78897 | K4: 0.59585481 | L4: 0.4195884 | M4: 0.18168493
A5: 3 | B5: Pico NPP | C5: (mmol N m-2 d-1) | D5: =D3*NZ_Extra!D6 -> 2.1257041 | E5: =D5*SQRT((E3/D3)^2+(NZ_Extra!E6/NZ_Extra!D6)^2) -> 1.5292454 | F5: =F3*NZ_Extra!F6 -> 3.0867581 | G5: =F5*SQRT((G3/F3)^2+(NZ_Extra!G6/NZ_Extra!F6)^2) -> 0.91836993 | H5: =H3*NZ_Extra!H6 -> 6.4892367 | I5: =H5*SQRT((I3/H3)^2+(NZ_Extra!I6/NZ_Extra!H6)^2) -> 4.7574096 | J5: =J3*NZ_Extra!J6 -> 3.4570988 | K5: =J5*SQRT((K3/J3)^2+(NZ_Extra!K6/NZ_Extra!J6)^2) -> 2.235291 | L5: =L3*NZ_Extra!L6 -> 2.8354624 | M5: =L5*SQRT((M3/L3)^2+(NZ_Extra!M6/NZ_Extra!L6)^2) -> 3.809041
A6: 4 | B6: Flag NPP | C6: (mmol N m-2 d-1) | D6: =D3*NZ_Extra!D7 -> 1.6509193 | E6: =D6*SQRT((E3/D3)^2+(NZ_Extra!E7/NZ_Extra!D7)^2) -> 0.83512694 | F6: =F3*NZ_Extra!F7 -> 0.3456774 | G6: =F6*SQRT((G3/F3)^2+(NZ_Extra!G7/NZ_Extra!F7)^2) -> 0.50067474 | H6: =H3*NZ_Extra!H7 -> 2.7169 | I6: =H6*SQRT((I3/H3)^2+(NZ_Extra!I7/NZ_Extra!H7)^2) -> 3.3405852 | J6: =J3*NZ_Extra!J7 -> 1.9849115 | K6: =J6*SQRT((K3/J3)^2+(NZ_Extra!K7/NZ_Extra!J7)^2) -> 1.9757686 | L6: =L3*NZ_Extra!L7 -> 0.16239399 | M6: =L6*SQRT((M3/L3)^2+(NZ_Extra!M7/NZ_Extra!L7)^2) -> 3.4118451
A7: 5 | B7: Diatom NPP | C7: (mmol N m-2 d-1) | D7: =D3*NZ_Extra!D8 -> 3.1985162 | E7: =D7*SQRT((E3/D3)^2+(NZ_Extra!E8/NZ_Extra!D8)^2) -> 2.0384171 | F7: =F3*NZ_Extra!F8 -> 0.36121242 | G7: =F7*SQRT((G3/F3)^2+(NZ_Extra!G8/NZ_Extra!F8)^2) -> 0.23417384 | H7: =H3*NZ_Extra!H8 -> 0.61767758 | I7: =H7*SQRT((I3/H3)^2+(NZ_Extra!I8/NZ_Extra!H8)^2) -> 0.56187448 | J7: =J3*NZ_Extra!J8 -> 0.24739712 | K7: =J7*SQRT((K3/J3)^2+(NZ_Extra!K8/NZ_Extra!J8)^2) -> 0.15495822 | L7: =L3*NZ_Extra!L8 -> 0.16416388 | M7: =L7*SQRT((M3/L3)^2+(NZ_Extra!M8/NZ_Extra!L8)^2) -> 0.21488912
A8: 6 | B8: Picophyto Mortality | C8: (mmol N m-2 d-1) | D8: =D11*NZ_Extra!D14 -> 0.96803779 | E8: =D8*SQRT((E11/D11)^2+(NZ_Extra!E14/NZ_Extra!D14)^2) -> 0.77464728 | F8: =F11*NZ_Extra!F14 -> 1.8898784 | G8: =F8*SQRT((G11/F11)^2+(NZ_Extra!G14/NZ_Extra!F14)^2) -> 0.73034638 | H8: =H11*NZ_Extra!H14 -> 3.4956498 | I8: =H8*SQRT((I11/H11)^2+(NZ_Extra!I14/NZ_Extra!H14)^2) -> 2.5146744 | J8: =J11*NZ_Extra!J14 -> 2.1195066 | K8: =J8*SQRT((K11/J11)^2+(NZ_Extra!K14/NZ_Extra!J14)^2) -> 1.2931693 | L8: =L11*NZ_Extra!L14 -> 1.249681 | M8: =L8*SQRT((M11/L11)^2+(NZ_Extra!M14/NZ_Extra!L14)^2) -> 0.93631571
A9: 7 | B9: Flagellate Mortality | C9: (mmol N m-2 d-1) | D9: =D11*NZ_Extra!D15 -> 0.93107774 | E9: =D9*SQRT((E11/D11)^2+(NZ_Extra!E15/NZ_Extra!D15)^2) -> 1.0527763 | F9: =F11*NZ_Extra!F15 -> 0.484364 | G9: =F9*SQRT((G11/F11)^2+(NZ_Extra!G15/NZ_Extra!F15)^2) -> 0.53471732 | H9: =H11*NZ_Extra!H15 -> 1.5734107 | I9: =H9*SQRT((I11/H11)^2+(NZ_Extra!I15/NZ_Extra!H15)^2) -> 1.7854607 | J9: =J11*NZ_Extra!J15 -> 2.2956994 | K9: =J9*SQRT((K11/J11)^2+(NZ_Extra!K15/NZ_Extra!J15)^2) -> 1.4378622 | L9: =L11*NZ_Extra!L15 -> 1.5922616 | M9: =L9*SQRT((M11/L11)^2+(NZ_Extra!M15/NZ_Extra!L15)^2) -> 2.3670614
A10: 8 | B10: Diatom Mortality | C10: (mmol N m-2 d-1) | D10: =D11*NZ_Extra!D16 -> 1.6100342 | E10: =D10*SQRT((E11/D11)^2+(NZ_Extra!E16/NZ_Extra!D16)^2) -> 1.1415465 | F10: =F11*NZ_Extra!F16 -> 0.0831399 | G10: =F10*SQRT((G11/F11)^2+(NZ_Extra!G16/NZ_Extra!F16)^2) -> 0.034881401 | H10: =H11*NZ_Extra!H16 -> 0.30286348 | I10: =H10*SQRT((I11/H11)^2+(NZ_Extra!I16/NZ_Extra!H16)^2) -> 0.26697517 | J10: =J11*NZ_Extra!J16 -> 0.18752559 | K10: =J10*SQRT((K11/J11)^2+(NZ_Extra!K16/NZ_Extra!J16)^2) -> 0.12099696 | L10: =L11*NZ_Extra!L16 -> 0.1359202 | M10: =L10*SQRT((M11/L11)^2+(NZ_Extra!M16/NZ_Extra!L16)^2) -> 0.13470708
A11: 9 | B11: Protistan Grazing Rate (14C) | C11: (mmol N m-2 d-1) | D11: 3.5091497 | E11: 1.264978 | F11: 2.6936632 | G11: 0.60951549 | H11: 5.371924 | I11: 2.9742856 | J11: 4.6027316 | K11: 2.1767591 | L11: 2.9778627 | M11: 0.86612577
A12: 10 | B12: Mesozoo Grazing | C12: (mmol N m-2 d-1) | D12: 0.90936712 | E12: 0.18438144 | F12: 0.69786875 | G12: 0.33083743 | H12: 0.24256809 | I12: 0.099091056 | J12: 0.326373 | K12: 0.1143953 | L12: 0.3026578 | M12: 0.16079582 | P12: NPP-Herb
A13: 11 | B13: Macrozoo Grazing | C13: (mmol N m-2 d-1) | D13: 0.027775614 | E13: 0.027788247 | F13: 0.033175155 | G13: 0.075474281 | H13: 0.0078424367 | I13: 0.011119541 | J13: 0.011164564 | K13: 0.01411272 | L13: 0.024892997 | M13: 0.025748037 | O13: 1 | P13: =D3-SUM(D11:D15) -> -0.1391621
A14: 12 | B14: VMMacro Grazing | C14: (mmol N m-2 d-1) | D14: 0.0088005357 | E14: 0.012670302 | F14: 0.020797253 | G14: 0.047029264 | H14: 0.0035417564 | I14: 0.0067117834 | J14: 0.0031993794 | K14: 0.0095212134 | L14: 8.8802004e-05 | M14: 0.012747025 | O14: 2 | P14: =F3-SUM(F11:F15) -> -1.1599386
A15: 13 | B15: Salp Autotroph Grazing | C15: (mmol N m-2 d-1) | D15: 2.6592087 | E15: 1.9074743 | F15: 1.7577646 | G15: 0.91975507 | H15: 0.024739266 | I15: 0.028097449 | J15: 1.5968294 | K15: 0.97512047 | L15: 0.0072143977 | M15: 0.016218315 | O15: 3 | P15: =H3-SUM(H11:H15) -> 4.1731988
A16: 14 | B16: Salp Heterotroph Grazing | C16: (mmol N m-2 d-1) | D16: =(D15/0.58499)*0.41501 -> 1.8865249 | E16: =D16*SQRT((E15/D15)^2+(0.17843/0.58499)^2+(0.17843/0.41501)^2) -> 1.6793412 | F16: =(F15/0.95928)*0.4072 -> 0.74614477 | G16: =F16*SQRT((G15/F15)^2+(0.30768/0.95928)^2+(0.30768/0.04072)^2) -> 5.6564312 | H16: =(H15/0.7689925)*0.23100747 -> 0.0074317438 | I16: =H16*SQRT((I15/H15)^2+(0.28703/0.76899)^2+(0.28703/0.23101)^2) -> 0.012814187 | J16: =(J15/0.81303)*0.18697 -> 0.36721793 | K16: =J16*SQRT((K15/J15)^2+(0.22065/0.81303)^2+(0.22065/0.18697)^2) -> 0.49802123 | L16: =(L15/0.94848)*0.05152 -> 0.00039187518 | M16: =L16*SQRT((M15/L15)^2+(0/0.94848)^2+(0/0.05152)^2) -> 0.00088095433 | O16: 4 | P16: =J3-SUM(J11:J15) -> -0.85089048
A17: 15 | B17: PicoTOSalp | C17: (mmol N m-2 d-1) | D17: =(D15+D16) * 0.0144398 -> 0.065639483 | E17: =D17*SQRT((SQRT((E15)^2+(E16^2))/(D15+D16))^2+(0.00000265298/0.0144398)^2) -> 0.036697114 | F17: =(F15+F16) * 0.02786716 -> 0.069776844 | G17: =F17*SQRT((SQRT((G15)^2+(G16^2))/(F15+F16))^2+(6.398304E-19/0.02786716)^2) -> 0.15969892 | H17: =(H15+H16) * 0.08979186 -> 0.0028886948 | I17: =H17*SQRT((SQRT((I15)^2+(I16^2))/(H15+H16))^2+(0/0.08979186)^2) -> 0.0027729117 | J17: =(J15+J16) * 0.0366902 -> 0.07206129 | K17: =J17*SQRT((SQRT((K15)^2+(K16^2))/(J15+J16))^2+(0/0.0366902)^2) -> 0.040173425 | L17: =(L15+L16) * 0.02808958 -> 0.00021365701 | M17: =L17*SQRT((SQRT((M15)^2+(M16^2))/(L15+L16))^2+(0.0000002335522/0.02808958)^2) -> 0.00045623722 | O17: 5 | P17: =L3-SUM(L11:L15) -> -0.15069648
A18: 16 | B18: DtmTOSalp | C18: (mmol N m-2 d-1) | D18: =(D15+D16) * 0.1836172 -> 0.83467486 | E18: =D18*SQRT((SQRT((E15)^2+(E16^2))/(D15+D16))^2+(0.001733872/0.1836172)^2) -> 0.46670883 | F18: =(F15+F16) * 0.09318711 -> 0.23333208 | G18: =F18*SQRT((SQRT((G15)^2+(G16^2))/(F15+F16))^2+(0.0006530248/0.09318711)^2) -> 0.53403183 | H18: =(H15+H16) * 0.0004796753 -> 1.5431639e-05 | I18: =H18*SQRT((SQRT((I15)^2+(I16^2))/(H15+H16))^2+(0.00001015141/0.0004796753)^2) -> 1.4816716e-05 | J18: =(J15+J16) * 0.000004663878 -> 9.1600772e-06 | K18: =J18*SQRT((SQRT((K15)^2+(K16^2))/(J15+J16))^2+(0/0.000004663878)^2) -> 5.1066484e-06 | L18: =(L15+L16) * 0.09488286 -> 0.00072170493 | M18: =L18*SQRT((SQRT((M15)^2+(M16^2))/(L15+L16))^2+(0.000609438/0.09488286)^2) -> 0.0015411155
A19: 17 | B19: OtherTOSalp | C19: (mmol N m-2 d-1) | D19: =(D15+D16) * 0.8019303 -> 3.6453615 | E19: =D19*SQRT((SQRT((E15)^2+(E16^2))/(D15+D16))^2+(0.001733677/0.8019303)^2) -> 2.0380301 | F19: =(F15+F16) * 0.8789064 -> 2.200702 | G19: =F19*SQRT((SQRT((G15)^2+(G16^2))/(F15+F16))^2+(0.0006530248/0.8789064)^2) -> 5.0367676 | H19: =(H15+H16) * 0.9097285 -> 0.029266884 | I19: =H19*SQRT((SQRT((I15)^2+(I16^2))/(H15+H16))^2+(0.00001015141/0.9097285)^2) -> 0.028093825 | J19: =(J15+J16) * 0.9633051 -> 1.8919768 | K19: =J19*SQRT((SQRT((K15)^2+(K16^2))/(J15+J16))^2+(0/0.9633051)^2) -> 1.0547575 | L19: =(L15+L16) * 0.8769906 -> 0.0066706299 | M19: =L19*SQRT((SQRT((M15)^2+(M16^2))/(L15+L16))^2+(0.0006094337/0.8769906)^2) -> 0.014244278
A20: 18 | B20: Salp Fecal Pellet Production | C20: (mmol N m-2 d-1) | D20: 0.95731512 | E20: 0.68669075 | F20: 0.63279526 | G20: 0.33111182 | H20: 0.0089061358 | I20: 0.010115082 | J20: 0.57485859 | K20: 0.35104337 | L20: 0.0025971832 | M20: 0.0058385932
A21: 19 | B21: Bacterial Production | C21: (mmol N m-2 d-1) | D21: 0.76851397 | E21: 0.15497851 | F21: 0.51195866 | G21: 0.17726619 | H21: 0.82093159 | I21: 0.1864646 | J21: 0.73073094 | K21: 0.19985947 | L21: 0.44078467 | M21: 0.10558125
A22: 20 | B22: Myct Scaled Meso Consumption | C22: (mmol N m-2 d-1) | D22: 0.11693991 | E22: 0.058469954 | F22: 0.061141856 | G22: 0.030570928 | H22: 0.17295774 | I22: 0.086478872 | J22: 0.084231157 | K22: 0.042115579 | L22: 0.014972636 | M22: 0.0074863178 | O22: =SUM(D22,D23:D27) -> 0.43277318 | P22: =SUM(F22:F27) -> 0.25675103 | Q22: =SUM(H22:H27) -> 0.20530084 | R22: =SUM(J22:J27) -> 0.28089807 | S22: =SUM(L22:L27) -> 0.034081901
A23: 21 | B23: Myct Scaled Macro Consumption | C23: (mmol N m-2 d-1) | D23: 0.0026827246 | E23: 0.0013413623 | F23: 0.0088581984 | G23: 0.0044290992 | H23: 0.0052513866 | I23: 0.0026256933 | J23: 0.0025997916 | K23: 0.0012998958 | L23: 0.01350108 | M23: 0.0067505401
A24: 22 | B24: Myct Scaled VMMacro Consumption | C24: (mmol N m-2 d-1) | D24: 0.043591718 | E24: 0.021795859 | F24: 0.035002236 | G24: 0.017501118 | H24: 0.025395081 | I24: 0.012697541 | J24: 0.013990941 | K24: 0.0069954704 | L24: 0.0004003736 | M24: 0.0002001868
A25: 23 | B25: Myct Scaled Amph Consumption | C25: (mmol N m-2 d-1) | D25: 0.0036083378 | E25: 0.0018041689 | F25: 0.00014890419 | G25: 7.4452093e-05 | H25: 3.9916436e-06 | I25: 1.9958218e-06 | J25: 0.00037681124 | K25: 0.00018840562 | L25: 0.0036211461 | M25: 0.001810573
A26: 24 | B26: Myct Scaled Salp Consumption | C26: (mmol N m-2 d-1) | D26: 0.26556852 | E26: 0.13278426 | F26: 0.13522638 | G26: 0.067613192 | H26: 0.0012702741 | I26: 0.00063513703 | J26: 0.17856612 | K26: 0.08928306 | L26: 0.00076364656 | M26: 0.00038182328
A27: 25 | B27: Myct Scaled Gel Consumption | C27: (mmol N m-2 d-1) | D27: 0.00038196859 | E27: 0.00019098429 | F27: 0.016373454 | G27: 0.008186727 | H27: 0.0004223626 | I27: 0.0002111813 | J27: 0.0011332476 | K27: 0.00056662382 | L27: 0.00082301842 | M27: 0.00041150921
A28: 26 | B28: PiscivFish Scaled Myct Consumption | C28: (mmol N m-2 d-1) | D28: 0.022182564 | E28: 0.011091282 | F28: 0.022133166 | G28: 0.011066583 | H28: 0.018438507 | I28: 0.0092192534 | J28: 0.017052622 | K28: 0.008526311 | L28: 0.0075311797 | M28: 0.0037655899
A29: 27 | B29: PiscivFish Scaled VMMacro Consumption | C29: (mmol N m-2 d-1) | D29: 0.0041610276 | E29: 0.0020805138 | F29: 0.0033411225 | G29: 0.0016705612 | H29: 0.0024240759 | I29: 0.001212038 | J29: 0.0013354989 | K29: 0.00066774944 | L29: 3.821748e-05 | M29: 1.910874e-05
A30: 28 | B30: PiscivFish Scaled Amph Consumption | C30: (mmol N m-2 d-1) | D30: 0.00034443225 | E30: 0.00017221612 | F30: 1.4213581e-05 | G30: 7.1067907e-06 | H30: 3.8102053e-07 | I30: 1.9051026e-07 | J30: 3.5968346e-05 | K30: 1.7984173e-05 | L30: 0.00034565485 | M30: 0.00017282743
A31: 29 | B31: GelativFish Scaled Salp Consumption | C31: (mmol N m-2 d-1) | D31: 0.14617279 | E31: 0.073086394 | F31: 0.074430574 | G31: 0.037215287 | H31: 0.00069917737 | I31: 0.00034958868 | J31: 0.098285396 | K31: 0.049142698 | L31: 0.0004203222 | M31: 0.0002101611
A32: 30 | B32: GelativFish Scaled Gel Consumption | C32: (mmol N m-2 d-1) | D32: 0.00021024108 | E32: 0.00010512054 | F32: 0.0090121878 | G32: 0.0045060939 | H32: 0.00023247453 | I32: 0.00011623727 | J32: 0.00062375603 | K32: 0.00031187802 | L32: 0.00045300134 | M32: 0.00022650067
A33: 31 | B33: HTL Scaled Meso Consumption | C33: (mmol N m-2 d-1) | D33: 0.012423441 | E33: 0.0062117204 | F33: 0.0064955775 | G33: 0.0032477887 | H33: 0.018374654 | I33: 0.0091873268 | J33: 0.0089485345 | K33: 0.0044742672 | L33: 0.0015906602 | M33: 0.00079533008
A34: 32 | B34: HTL Scaled Macro Consumption | C34: (mmol N m-2 d-1) | D34: 0.00086862565 | E34: 0.00043431282 | F34: 0.0028681507 | G34: 0.0014340753 | H34: 0.0017003196 | I34: 0.00085015978 | J34: 0.0008417732 | K34: 0.0004208866 | L34: 0.0043714457 | M34: 0.0021857228
... A38: 36 | B38: HTL Scaled Gel Consumption | C38: (mmol N m-2 d-1) | D38: 0.00019016545 | E38: 9.5082724e-05 | F38: 0.0081516264 | G38: 0.0040758132 | H38: 0.00021027586 | I38: 0.00010513793 | J38: 0.00056419443 | K38: 0.00028209721 | L38: 0.00040974486 | M38: 0.00020487243
A40: Inequality Inputs
A41: 1 | B41: Temperature (0-70) | C41: deg C | D41: 10.240493 | E41: 0.5896211 | F41: 9.897492 | G41: 0.4112118 | H41: 13.090224 | I41: 0.3273925 | J41: 12.122057 | K41: 0.5916513 | L41: 10.688394 | M41: 0.5750481
A42: 2 | B42: Temperature (200) | C42: deg C | D42: 9.397415 | F42: 7.915702 | H42: 11.465439 | J42: 9.652742 | L42: 7.9416
A43: 3 | B43: Temperature (bottom 100) | C43: deg C | D43: 5.73695 | F43: 2.882 | H43: 4.9304 | J43: 8.341335 | L43: 1.8084
A44: 4 | B44: Bottom Depth | C44: m | D44: 884.2632 | F44: 1501.6923 | H44: 1046.5 | J44: 449.5 | L44: 2635.1
...

Sheet InputsNZ Old
A1: Approximate Equalities
C2: units | D2: Cycle 1 | E2: σ | F2: Cycle 2 | G2: σ | H2: Cycle 3 | I2: σ | J2: Cycle 4 | K2: σ | L2: Cycle 5 | M2: σ
A3: 1 | B3: NPP (14C) | C3: (mmol N m-2 d-1) | D3: 6.9847902 | E3: 1.4592868 | F3: 4.0048803 | G3: 0.84743941 | H3: 9.3827998 | I3: 4.876599 | J3: 5.6894075 | K3: 1.2846958 | L3: 2.9328239 | M3: 0.55150633
A4: 2 | B4: SedTrap Flux (shallow) | C4: (mmol N m-2 d-1) | D4: 0.97868813 | E4: 0.20023276 | F4: 1.634325 | G4: 0.056975159 | H4: 0.46955162 | I4: 0.029864707 | J4: 1.78897 | K4: 0.59585481 | L4: 0.4195884 | M4: 0.18168493
A5: 3 | B5: Pico NPP | C5: (mmol N m-2 d-1) | D5: =D3*NZ_Extra!D6 -> 2.1286452 | E5: =D5*SQRT((E3/D3)^2+(NZ_Extra!E6/NZ_Extra!D6)^2) -> 1.4594561 | F5: =F3*NZ_Extra!F6 -> 3.0574045 | G5: =F5*SQRT((G3/F3)^2+(NZ_Extra!G6/NZ_Extra!F6)^2) -> 0.94638163 | H5: =H3*NZ_Extra!H6 -> 6.1979193 | I5: =H5*SQRT((I3/H3)^2+(NZ_Extra!I6/NZ_Extra!H6)^2) -> 4.7729749 | J5: =J3*NZ_Extra!J6 -> 3.4570988 | K5: =J5*SQRT((K3/J3)^2+(NZ_Extra!K6/NZ_Extra!J6)^2) -> 2.235291 | L5: =L3*NZ_Extra!L6 -> 2.6299363 | M5: =L5*SQRT((M3/L3)^2+(NZ_Extra!M6/NZ_Extra!L6)^2) -> 3.5531589
A6: 4 | B6: Flag NPP | C6: (mmol N m-2 d-1) | D6: =D3*NZ_Extra!D7 -> 1.6532035 | E6: =D6*SQRT((E3/D3)^2+(NZ_Extra!E7/NZ_Extra!D7)^2) -> 0.75475264 | F6: =F3*NZ_Extra!F7 -> 0.34239017 | G6: =F6*SQRT((G3/F3)^2+(NZ_Extra!G7/NZ_Extra!F7)^2) -> 0.49677515 | H6: =H3*NZ_Extra!H7 -> 2.5949319 | I6: =H6*SQRT((I3/H3)^2+(NZ_Extra!I7/NZ_Extra!H7)^2) -> 3.2487322 | J6: =J3*NZ_Extra!J7 -> 1.9849115 | K6: =J6*SQRT((K3/J3)^2+(NZ_Extra!K7/NZ_Extra!J7)^2) -> 1.9757686 | L6: =L3*NZ_Extra!L7 -> 0.150623 | M6: =L6*SQRT((M3/L3)^2+(NZ_Extra!M7/NZ_Extra!L7)^2) -> 3.1646147
A7: 5 | B7: Diatom NPP | C7: (mmol N m-2 d-1) | D7: =D3*NZ_Extra!D8 -> 3.2029415 | E7: =D7*SQRT((E3/D3)^2+(NZ_Extra!E8/NZ_Extra!D8)^2) -> 1.9182671 | F7: =F3*NZ_Extra!F8 -> 0.35777746 | G7: =F7*SQRT((G3/F3)^2+(NZ_Extra!G8/NZ_Extra!F8)^2) -> 0.23395147 | H7: =H3*NZ_Extra!H8 -> 0.58994855 | I7: =H7*SQRT((I3/H3)^2+(NZ_Extra!I8/NZ_Extra!H8)^2) -> 0.55437869 | J7: =J3*NZ_Extra!J8 -> 0.24739712 | K7: =J7*SQRT((K3/J3)^2+(NZ_Extra!K8/NZ_Extra!J8)^2) -> 0.15495822 | L7: =L3*NZ_Extra!L8 -> 0.15226461 | M7: =L7*SQRT((M3/L3)^2+(NZ_Extra!M8/NZ_Extra!L8)^2) -> 0.20051387
A8: 6 | B8: Picophyto Mortality | C8: (mmol N m-2 d-1) | D8: =D11*NZ_Extra!D14 -> 0.67907805 | E8: =D8*SQRT((E11/D11)^2+(NZ_Extra!E14/NZ_Extra!D14)^2) -> 0.48623447 | F8: =F11*NZ_Extra!F14 -> 1.8898784 | G8: =F8*SQRT((G11/F11)^2+(NZ_Extra!G14/NZ_Extra!F14)^2) -> 0.73034638 | H8: =H11*NZ_Extra!H14 -> 3.4956498 | I8: =H8*SQRT((I11/H11)^2+(NZ_Extra!I14/NZ_Extra!H14)^2) -> 2.5146744 | J8: =J11*NZ_Extra!J14 -> 2.1195066 | K8: =J8*SQRT((K11/J11)^2+(NZ_Extra!K14/NZ_Extra!J14)^2) -> 1.2931693 | L8: =L11*NZ_Extra!L14 -> 1.249681 | M8: =L8*SQRT((M11/L11)^2+(NZ_Extra!M14/NZ_Extra!L14)^2) -> 0.93631571
A9: 7 | B9: Flagellate Mortality | C9: (mmol N m-2 d-1) | D9: =D11*NZ_Extra!D15 -> 0.65315059 | E9: =D9*SQRT((E11/D11)^2+(NZ_Extra!E15/NZ_Extra!D15)^2) -> 0.70067773 | F9: =F11*NZ_Extra!F15 -> 0.484364 | G9: =F9*SQRT((G11/F11)^2+(NZ_Extra!G15/NZ_Extra!F15)^2) -> 0.53471732 | H9: =H11*NZ_Extra!H15 -> 1.5734107 | I9: =H9*SQRT((I11/H11)^2+(NZ_Extra!I15/NZ_Extra!H15)^2) -> 1.7854607 | J9: =J11*NZ_Extra!J15 -> 2.2956994 | K9: =J9*SQRT((K11/J11)^2+(NZ_Extra!K15/NZ_Extra!J15)^2) -> 1.4378622 | L9: =L11*NZ_Extra!L15 -> 1.5922616 | M9: =L9*SQRT((M11/L11)^2+(NZ_Extra!M15/NZ_Extra!L15)^2) -> 2.3670614
A10: 8 | B10: Diatom Mortality | C10: (mmol N m-2 d-1) | D10: =D11*NZ_Extra!D16 -> 1.1294382 | E10: =D10*SQRT((E11/D11)^2+(NZ_Extra!E16/NZ_Extra!D16)^2) -> 0.69167129 | F10: =F11*NZ_Extra!F16 -> 0.0831399 | G10: =F10*SQRT((G11/F11)^2+(NZ_Extra!G16/NZ_Extra!F16)^2) -> 0.034881401 | H10: =H11*NZ_Extra!H16 -> 0.30286348 | I10: =H10*SQRT((I11/H11)^2+(NZ_Extra!I16/NZ_Extra!H16)^2) -> 0.26697517 | J10: =J11*NZ_Extra!J16 -> 0.18752559 | K10: =J10*SQRT((K11/J11)^2+(NZ_Extra!K16/NZ_Extra!J16)^2) -> 0.12099696 | L10: =L11*NZ_Extra!L16 -> 0.1359202 | M10: =L10*SQRT((M11/L11)^2+(NZ_Extra!M16/NZ_Extra!L16)^2) -> 0.13470708
A11: 9 | B11: Protistan Grazing Rate (14C) | C11: (mmol N m-2 d-1) | D11: 2.4616669 | E11: 0.11738151 | F11: 2.6936632 | G11: 0.60951549 | H11: 5.371924 | I11: 2.9742856 | J11: 4.6027316 | K11: 2.1767591 | L11: 2.9778627 | M11: 0.86612577
A12: 10 | B12: Mesozoo Grazing | C12: (mmol N m-2 d-1) | D12: 0.95678559 | E12: 0.18954805 | F12: 0.5606786 | G12: 0.24599088 | H12: 0.26710772 | I12: 0.10616426 | J12: 0.39431444 | K12: 0.12405842 | L12: 0.11835133 | M12: 0.036291902 | P12: NPP-Herb
A13: 11 | B13: Macrozoo Grazing | C13: (mmol N m-2 d-1) | D13: 0.029318503 | E13: 0.029955162 | F13: 0.026653435 | G13: 0.060445396 | H13: 0.0086358244 | I13: 0.012199522 | J13: 0.013488705 | K13: 0.016856884 | L13: 0.0097341595 | M13: 0.0092154497 | O13: 1 | P13: =D3-SUM(D11:D15) -> 0.86839944
A14: 12 | B14: VMMacro Grazing | C14: (mmol N m-2 d-1) | D14: 0.0094111235 | E14: 0.013073073 | F14: 0.016708837 | G14: 0.037687482 | H14: 0.0039000616 | I14: 0.0073649812 | J14: 0.0038653978 | K14: 0.0073795082 | L14: 3.4725143e-05 | M14: 0.004983912 | O14: 2 | P14: =F3-SUM(F11:F15) -> -1.0505884
A15: 13 | B15: Salp Autotroph Grazing | C15: (mmol N m-2 d-1) | D15: 2.6592087 | E15: 1.9074743 | F15: 1.7577646 | G15: 0.91975507 | H15: 0.024739266 | I15: 0.028097449 | J15: 1.5968294 | K15: 0.97512047 | L15: 0.0072143977 | M15: 0.016218315 | O15: 3 | P15: =H3-SUM(H11:H15) -> 3.7064929
A16: 14 | B16: Salp Heterotroph Grazing | C16: (mmol N m-2 d-1) | D16: =(D15/0.58499)*0.41501 -> 1.8865249 | E16: =D16*SQRT((E15/D15)^2+(0.17843/0.58499)^2+(0.17843/0.41501)^2) -> 1.6793412 | F16: =(F15/0.95928)*0.4072 -> 0.74614477 | G16: =F16*SQRT((G15/F15)^2+(0.30768/0.95928)^2+(0.30768/0.04072)^2) -> 5.6564312 | H16: =(H15/0.7689925)*0.23100747 -> 0.0074317438 | I16: =H16*SQRT((I15/H15)^2+(0.28703/0.76899)^2+(0.28703/0.23101)^2) -> 0.012814187 | J16: =(J15/0.81303)*0.18697 -> 0.36721793 | K16: =J16*SQRT((K15/J15)^2+(0.22065/0.81303)^2+(0.22065/0.18697)^2) -> 0.49802123 | L16: =(L15/0.94848)*0.05152 -> 0.00039187518 | M16: =L16*SQRT((M15/L15)^2+(0/0.94848)^2+(0/0.05152)^2) -> 0.00088095433 | O16: 4 | P16: =J3-SUM(J11:J15) -> -0.92182208
A17: 15 | B17: PicoTOSalp | C17: (mmol N m-2 d-1) | D17: =(D15+D16) * 0.0144398 -> 0.065639483 | E17: =D17*SQRT((SQRT((E15)^2+(E16^2))/(D15+D16))^2+(0.00000265298/0.0144398)^2) -> 0.036697114 | F17: =(F15+F16) * 0.02786716 -> 0.069776844 | G17: =F17*SQRT((SQRT((G15)^2+(G16^2))/(F15+F16))^2+(6.398304E-19/0.02786716)^2) -> 0.15969892 | H17: =(H15+H16) * 0.08979186 -> 0.0028886948 | I17: =H17*SQRT((SQRT((I15)^2+(I16^2))/(H15+H16))^2+(0/0.08979186)^2) -> 0.0027729117 | J17: =(J15+J16) * 0.0366902 -> 0.07206129 | K17: =J17*SQRT((SQRT((K15)^2+(K16^2))/(J15+J16))^2+(0/0.0366902)^2) -> 0.040173425 | L17: =(L15+L16) * 0.02808958 -> 0.00021365701 | M17: =L17*SQRT((SQRT((M15)^2+(M16^2))/(L15+L16))^2+(0.0000002335522/0.02808958)^2) -> 0.00045623722 | O17: 5 | P17: =L3-SUM(L11:L15) -> -0.18037343
A18: 16 | B18: DtmTOSalp | C18: (mmol N m-2 d-1) | D18: =(D15+D16) * 0.1836172 -> 0.83467486 | E18: =D18*SQRT((SQRT((E15)^2+(E16^2))/(D15+D16))^2+(0.001733872/0.1836172)^2) -> 0.46670883 | F18: =(F15+F16) * 0.09318711 -> 0.23333208 | G18: =F18*SQRT((SQRT((G15)^2+(G16^2))/(F15+F16))^2+(0.0006530248/0.09318711)^2) -> 0.53403183 | H18: =(H15+H16) * 0.0004796753 -> 1.5431639e-05 | I18: =H18*SQRT((SQRT((I15)^2+(I16^2))/(H15+H16))^2+(0.00001015141/0.0004796753)^2) -> 1.4816716e-05 | J18: =(J15+J16) * 0.000004663878 -> 9.1600772e-06 | K18: =J18*SQRT((SQRT((K15)^2+(K16^2))/(J15+J16))^2+(0/0.000004663878)^2) -> 5.1066484e-06 | L18: =(L15+L16) * 0.09488286 -> 0.00072170493 | M18: =L18*SQRT((SQRT((M15)^2+(M16^2))/(L15+L16))^2+(0.000609438/0.09488286)^2) -> 0.0015411155
A19: 17 | B19: OtherTOSalp | C19: (mmol N m-2 d-1) | D19: =(D15+D16) * 0.8019303 -> 3.6453615 | E19: =D19*SQRT((SQRT((E15)^2+(E16^2))/(D15+D16))^2+(0.001733677/0.8019303)^2) -> 2.0380301 | F19: =(F15+F16) * 0.8789064 -> 2.200702 | G19: =F19*SQRT((SQRT((G15)^2+(G16^2))/(F15+F16))^2+(0.0006530248/0.8789064)^2) -> 5.0367676 | H19: =(H15+H16) * 0.9097285 -> 0.029266884 | I19: =H19*SQRT((SQRT((I15)^2+(I16^2))/(H15+H16))^2+(0.00001015141/0.9097285)^2) -> 0.028093825 | J19: =(J15+J16) * 0.9633051 -> 1.8919768 | K19: =J19*SQRT((SQRT((K15)^2+(K16^2))/(J15+J16))^2+(0/0.9633051)^2) -> 1.0547575 | L19: =(L15+L16) * 0.8769906 -> 0.0066706299 | M19: =L19*SQRT((SQRT((M15)^2+(M16^2))/(L15+L16))^2+(0.0006094337/0.8769906)^2) -> 0.014244278
A20: 18 | B20: Salp Fecal Pellet Production | C20: (mmol N m-2 d-1) | D20: 0.95731512 | E20: 0.68669075 | F20: 0.63279526 | G20: 0.33111182 | H20: 0.0089061358 | I20: 0.010115082 | J20: 0.57485859 | K20: 0.35104337 | L20: 0.0025971832 | M20: 0.0058385932
A21: 19 | B21: Bacterial Production | C21: (mmol N m-2 d-1) | D21: 0.76851397 | E21: 0.15497851 | F21: 0.51195866 | G21: 0.17726619 | H21: 0.82093159 | I21: 0.1864646 | J21: 0.73073094 | K21: 0.19985947 | L21: 0.44078467 | M21: 0.10558125
A23: Inequality Inputs
A24: 1 | B24: Temperature (0-70) | C24: deg C | D24: 10.240493 | E24: 0.5896211 | F24: 9.897492 | G24: 0.4112118 | H24: 13.090224 | I24: 0.3273925 | J24: 12.122057 | K24: 0.5916513 | L24: 10.688394 | M24: 0.5750481
A25: 2 | B25: Temperature (200) | C25: deg C | D25: 9.397415 | F25: 7.915702 | H25: 11.465439 | J25: 9.652742 | L25: 7.9416
A26: 3 | B26: Temperature (bottom 100) | C26: deg C | D26: 5.73695 | F26: 2.882 | H26: 4.9304 | J26: 8.341335 | L26: 1.8084
A27: 4 | B27: Bottom Depth | C27: m | D27: 884.2632 | F27: 1501.6923 | H27: 1046.5 | J27: 449.5 | L27: 2635.1
A28: 5 | B28: Salp FP Flux | C28: (mmol N m-2 d-1) | D28: 0.32656759 | E28: 0.16437855 | F28: 0.31045976 | G28: 0.078558799 | H28: 0.0073162576 | I28: 0.0070528902 | J28: 0.47390571 | K28: 0.16146131 | L28: 0.00019337845 | M28: 0.00061151635
A29: 6 | B29: Pico Biomass | C29: (mmol N m-2) | D29: 2.4323502 | F29: 3.7253042 | H29: 4.8385682 | J29: 1.3939279 | L29: 8.6175825
A30: 7 | B30: Diatom Biomass | C30: (mmol N m-2) | D30: 8.4716316 | F30: 1.1232474 | H30: 0.51240455 | J30: 0.35273312 | L30: 0.46975683
A31: 8 | B31: Flag Biomass | C31: (mmol N m-2) | D31: 5.3577987 | F31: 3.4577517 | H31: 4.2948953 | J31: 3.9405854 | L31: 3.0408447
A32: 9 | B32: HNF Biomass | C32: (mmol N m-2) | D32: 0.9080092 | F32: 1.1168358 | H32: 2.0222311 | J32: 1.7585174 | L32: 0.81948829
A33: 10 | B33: MIC Biomass | C33: (mmol N m-2) | D33: 1.0521292 | F33: 0.20896668 | H33: 0.26691986 | J33: 2.3268684 | L33: 0.55378937
A34: 11 | B34: Meso Biomass | C34: (mmol N m-2) | D34: 9.179154 | E34: 1.273124 | F34: 4.799307 | G34: 0.009130156 | H34: 13.576253 | I34: 7.2571895 | J34: 6.611693 | K34: 1.9186138 | L34: 1.1752714 | M34: 0.6314741
A35: 12 | B35: Macro Daytime Biomass | C35: (mmol N m-2) | D35: 0.2395441 | E35: 0.3387665 | F35: 0.7909605 | G35: 0.742375 | H35: 0.4689034 | I35: 0.3975926 | J35: 0.2321389 | K35: 0.1309799 | L35: 1.2055297 | M35: 0.8594286
A36: 13 | B36: Macro Nighttime Biomass | C36: (mmol N m-2) | D36: 4.1319075 | E36: 2.6204844 | F36: 3.9163574 | G36: 2.8763821 | H36: 2.7364645 | I36: 0.3570634 | J36: 1.4814089 | K36: 0.6263969 | L36: 1.2412796 | M36: 0.5305407
A37: 14 | B37: Amph Biomass | C37: (mmol N m-2) | D37: =AVERAGE(NZ_Extra!D18:D19) -> 0.32219336 | E37: =SQRT((NZ_Extra!E18)^2+(NZ_Extra!E19)^2)/2 -> 0.4232218 | F37: =AVERAGE(NZ_Extra!F18:F19) -> 0.013295856 | G37: =SQRT((NZ_Extra!G18)^2+(NZ_Extra!G19)^2)/2 -> 0.018296867 | H37: =AVERAGE(NZ_Extra!H18:H19) -> 0.00035641925 | I37: =SQRT((NZ_Extra!I18)^2+(NZ_Extra!I19)^2)/2 -> 0.00036584107 | J37: 0.00462 | L37: 0.00035641925
A38: 15 | B38: Gel Biomass | C38: (mmol N m-2) | D38: =AVERAGE(NZ_Extra!D20:D21) -> 0.03509511 | E38: =SQRT((NZ_Extra!E20)^2+(NZ_Extra!E21)^2)/2 -> 0.0010511961 | F38: =AVERAGE(NZ_Extra!F20:F21) -> 1.5556847 | G38: =SQRT((NZ_Extra!G20)^2+(NZ_Extra!G21)^2)/2 -> 0.017630899 | H38: =AVERAGE(NZ_Extra!H20:H21) -> 0.024393612 | I38: =SQRT((NZ_Extra!I20)^2+(NZ_Extra!I21)^2)/2 -> 0.0011153616 | J38: =J39*0.1 -> 0.76321475 | L38: 0.024393612
A39: 16 | B39: Salp Daytime Biomass | C39: (mmol N m-2) | D39: 10.558088 | E39: 8.4812445 | F39: 3.5113963 | G39: 3.2785496 | H39: 0.075097617 | I39: 0.093705091 | J39: 7.6321475 | K39: 8.6550229 | L39: 0.001770607 | M39: 0.004337083
A40: 17 | B40: Salp Nighttime Biomass | C40: (mmol N m-2) | D40: 18.989587 | E40: 18.100778 | F40: 12.853549 | G40: 15.547954 | H40: 0.1207422 | I40: 0.17997649 | J40: 16.973082 | K40: 11.787042 | L40: 0.072586196 | M40: 0.15708615
A41: 18 | B41: Myct Biomass | C41: (mmol N m-2) | D41: 1.5434567 | F41: 1.4416238 | H41: 1.3536079 | J41: 1.3335088 | L41: 0.44393055
...

Sheet NZ_Extra
C1: units | D1: Cycle 1 | E1: σ | F1: Cycle 2 | G1: σ | H1: Cycle 3 | I1: σ | J1: Cycle 4 | K1: σ | L1: Cycle 5 | M1: σ
B2: Pico Fcyt NPP | C2: (mmol N m-2 d-1) | D2: 1.7962238 | E2: 1.0500833 | F2: 1.941133 | G2: 0.25928628 | H2: 2.8889079 | I2: 1.166368 | J2: 1.4407557 | K2: 0.64308169 | L2: 1.5787136 | M2: 0.93205888
B3: Flag Fcyt NPP | C3: (mmol N m-2 d-1) | D3: 1.3950298 | E3: 0.39484143 | F3: 0.21738205 | G3: 0.30950426 | H3: 1.2095219 | I3: 1.2899133 | J3: 0.8272175 | K3: 0.72680912 | L3: 0.090416854 | M3: 1.8964932
B4: Diatom Fcyt NPP | C4: (mmol N m-2 d-1) | D4: 2.7027519 | E4: 1.297239 | F4: 0.38416626 | G4: 0.22715137 | H4: 0.27498052 | I4: 0.18507877 | J4: 0.10310345 | K4: 0.042943839 | L4: 0.091402289 | M4: 0.046373485
B5: Summed Fcyt NPP | C5: (mmol N m-2 d-1) | D5: =SUM(D2:D4) -> 5.8940055 | E5: =SQRT((E2)^2+(E3)^2+(E4)^2) -> 1.7150521 | F5: =SUM(F2:F4) -> 2.5426813 | G5: =SQRT((G2)^2+(G3)^2+(G4)^2) -> 0.46327099 | H5: =SUM(H2:H4) -> 4.3734104 | I5: =SQRT((I2)^2+(I3)^2+(I4)^2) -> 1.7488696 | J5: =SUM(J2:J4) -> 2.3710766 | K5: =SQRT((K2)^2+(K3)^2+(K4)^2) -> 0.97141635 | L5: =SUM(L2:L4) -> 1.7605327 | M5: =SQRT((M2)^2+(M3)^2+(M4)^2) -> 2.1136628
B6: Pico Prop | D6: =D2/D5 -> 0.30475434 | E6: =D6*SQRT((E2/D2)^2+(E5/D5)^2) -> 0.19901066 | F6: =F2/F5 -> 0.7634197 | G6: =F6*SQRT((G2/F2)^2+(G5/F5)^2) -> 0.17246908 | H6: =H2/H5 -> 0.66056183 | I6: =H6*SQRT((I2/H2)^2+(I5/H5)^2) -> 0.37536865 | J6: =J2/J5 -> 0.60763776 | K6: =J6*SQRT((K2/J2)^2+(K5/J5)^2) -> 0.36814921 | L6: =L2/L5 -> 0.89672493 | M6: =L6*SQRT((M2/L2)^2+(M5/L5)^2) -> 1.199722
B7: Flag Prop | D7: =D3/D5 -> 0.23668621 | E7: =D7*SQRT((E3/D3)^2+(E5/D5)^2) -> 0.096078059 | F7: =F3/F5 -> 0.085493236 | G7: =F7*SQRT((G3/F3)^2+(G5/F5)^2) -> 0.12271619 | H7: =H3/H5 -> 0.27656264 | I7: =H7*SQRT((I3/H3)^2+(I5/H5)^2) -> 0.31499721 | J7: =J3/J5 -> 0.34887843 | K7: =J7*SQRT((K3/J3)^2+(K5/J5)^2) -> 0.33821797 | L7: =L3/L5 -> 0.051357668 | M7: =L7*SQRT((M3/L3)^2+(M5/L5)^2) -> 1.0789901
B8: Diatom Prop | D8: =D4/D5 -> 0.45855945 | E8: =D8*SQRT((E4/D4)^2+(E5/D5)^2) -> 0.25738288 | F8: =G4/F5 -> 0.08933537 | G8: =F8*SQRT((G4/F4)^2+(G5/F5)^2) -> 0.055273465 | H8: =H4/H5 -> 0.062875535 | I8: =H8*SQRT((I4/H4)^2+(I5/H5)^2) -> 0.049224806 | J8: =J4/J5 -> 0.043483812 | K8: =J8*SQRT((K4/J4)^2+(K5/J5)^2) -> 0.025404808 | L8: =L4/L5 -> 0.051917405 | M8: =L8*SQRT((M4/L4)^2+(M5/L5)^2) -> 0.067668231
B10: Pico Fcyt Mort | C10: (mmol N m-2 d-1) | D10: 1.1064976 | E10: 0.66792432 | F10: 1.6410396 | G10: 0.33256632 | H10: 2.1673371 | I10: 0.66886728 | J10: 0.89024825 | K10: 0.2789012 | L10: 0.7270511 | M10: 0.040511997
B11: Flag Fcyt Mort | C11: (mmol N m-2 d-1) | D11: 1.0642511 | E11: 1.0655908 | F11: 0.42058819 | G11: 0.44320636 | H11: 0.97553008 | I11: 0.9075313 | J11: 0.96425383 | K11: 0.33148356 | L11: 0.92636085 | M11: 1.190555
B12: Diatom Fcyt Mort | C12: (mmol N m-2 d-1) | D12: 1.8403196 | E12: 0.8762894 | F12: 0.27736292 | G12: 0.072192936 | H12: 0.18777833 | I12: 0.11184922 | J12: 0.078765655 | K12: 0.02970335 | L12: 0.079076927 | M12: 0.051489207
B13: Summed Fcyt Mort | C13: (mmol N m-2 d-1) | D13: =SUM(D10:D12) -> 4.0110683 | E13: =SQRT((E10)^2+(E11)^2+(E12)^2) -> 1.5328045 | F13: =SUM(F10:F12) -> 2.3389908 | G13: =SQRT((G10)^2+(G11)^2+(G12)^2) -> 0.55878802 | H13: =SUM(H10:H12) -> 3.3306455 | I13: =SQRT((I10)^2+(I11)^2+(I12)^2) -> 1.1329196 | J13: =SUM(J10:J12) -> 1.9332677 | K13: =SQRT((K10)^2+(K11)^2+(K12)^2) -> 0.43422289 | L13: =SUM(L10:L12) -> 1.7324889 | M13: =SQRT((M10)^2+(M11)^2+(M12)^2) -> 1.1923563
B14: Pico Prop | D14: =D10/D13 -> 0.27586106 | E14: =D14*SQRT((E10/D10)^2+(E13/D13)^2) -> 0.19708396 | F14: =F10/F13 -> 0.70160159 | G14: =F14*SQRT((G10/F10)^2+(G13/F13)^2) -> 0.21979651 | H14: =H10/H13 -> 0.65072584 | I14: =H14*SQRT((I10/H10)^2+(I13/H13)^2) -> 0.29886938 | J14: =J10/J13 -> 0.46048886 | K14: =J14*SQRT((K10/J10)^2+(K13/J13)^2) -> 0.17750937 | L14: =L10/L13 -> 0.41965701 | M14: =L14*SQRT((M10/L10)^2+(M13/L13)^2) -> 0.28976693
B15: Flag Prop | D15: =D11/D13 -> 0.26532859 | E15: =D15*SQRT((E11/D11)^2+(E13/D13)^2) -> 0.28435416 | F15: =F11/F13 -> 0.1798161 | G15: =F15*SQRT((G11/F11)^2+(G13/F13)^2) -> 0.19429467 | H15: =H11/H13 -> 0.2928952 | I15: =H15*SQRT((I11/H11)^2+(I13/H13)^2) -> 0.29012181 | J15: =J11/J13 -> 0.4987689 | K15: =J15*SQRT((K11/J11)^2+(K13/J13)^2) -> 0.20481553 | L15: =L11/L13 -> 0.53469945 | M15: =L15*SQRT((M11/L11)^2+(M13/L13)^2) -> 0.77952376
B16: Diatom Prop | D16: =D12/D13 -> 0.45881035 | E16: =D16*SQRT((E12/D12)^2+(E13/D13)^2) -> 0.28012377 | F16: =G12/F13 -> 0.030864994 | G16: =F16*SQRT((G12/F12)^2+(G13/F13)^2) -> 0.010904618 | H16: =H12/H13 -> 0.056378958 | I16: =H16*SQRT((I12/H12)^2+(I13/H13)^2) -> 0.038671818 | J16: =J12/J13 -> 0.040742239 | K16: =J16*SQRT((K12/J12)^2+(K13/J13)^2) -> 0.017883011 | L16: =L12/L13 -> 0.045643541 | M16: =L16*SQRT((M12/L12)^2+(M13/L13)^2) -> 0.043244279
B18: Amph Daytime Biomass | C18: (mmol N m-2) | D18: 0.003064117 | E18: 0.003704478 | F18: 0.02642608 | G18: 0.03659327 | H18: 0.0004389118 | I18: 0.000620715 | J18: 0.004619734 | K18: 0.008001613
B19: Amph Nighttime Biomass | C19: (mmol N m-2) | D19: 0.6413226 | E19: 0.8464355 | F19: 0.0001656318 | G19: 0.0001841023 | H19: 0.0002739267 | I19: 0.0003873908
B20: Gel Daytime Biomass | C20: (mmol N m-2) | D20: 0.03219829 | E20: 0.001468186 | F20: 0.06255547 | G20: 0.001990349 | H20: 0.04864934 | I20: 0.002230721 | J20: 0.01952339
B21: Gel Nighttime Biomass | C21: (mmol N m-2) | D21: 0.03799193 | E21: 0.00150482 | F21: 3.048814 | G21: 0.03520558 | H21: 0.0001378842 | I21: 3.175943e-06

Sheet Sheet1
B1: units | C1: Cycle 1-Min | D1: Cycle 1-Max | E1: Cycle 2-Min | F1: Cycle 2-Max | G1: Cycle 3-Min | H1: Cycle 3-Max | I1: Cycle 4-Min | J1: Cycle 4-Max | K1: Cycle 5-Min | L1: Cycle 5-Max
A2: Meso Daytime Biomass | B2: (mmol N m-2) | C2: ='InputsNZ Old'!D34-('InputsNZ Old'!E34*2) -> 6.632906 | D2: ='InputsNZ Old'!D34+('InputsNZ Old'!E34*2) -> 11.725402 | E2: ='InputsNZ Old'!F34-('InputsNZ Old'!G34*2) -> 4.7810467 | F2: ='InputsNZ Old'!F34+('InputsNZ Old'!G34*2) -> 4.8175673 | G2: ='InputsNZ Old'!H34-('InputsNZ Old'!I34*2) -> -0.93812596 | H2: ='InputsNZ Old'!H34+('InputsNZ Old'!I34*2) -> 28.090632 | I2: ='InputsNZ Old'!J34-('InputsNZ Old'!K34*2) -> 2.7744654 | J2: ='InputsNZ Old'!J34+('InputsNZ Old'!K34*2) -> 10.448921 | K2: ='InputsNZ Old'!L34-('InputsNZ Old'!M34*2) -> -0.087676792 | L2: ='InputsNZ Old'!L34+('InputsNZ Old'!M34*2) -> 2.4382196
A3: Meso Nighttime Biomass | B3: (mmol N m-2) | C3: ='InputsNZ Old'!#REF!-('InputsNZ Old'!#REF!*2) -> #REF! | D3: ='InputsNZ Old'!#REF!+('InputsNZ Old'!#REF!*2) -> #REF! | E3: ='InputsNZ Old'!#REF!-('InputsNZ Old'!#REF!*2) -> #REF! | F3: ='InputsNZ Old'!#REF!+('InputsNZ Old'!#REF!*2) -> #REF! | G3: ='InputsNZ Old'!#REF!-('InputsNZ Old'!#REF!*2) -> #REF! | H3: ='InputsNZ Old'!#REF!+('InputsNZ Old'!#REF!*2) -> #REF! | I3: ='InputsNZ Old'!#REF!-('InputsNZ Old'!#REF!*2) -> #REF! | J3: ='InputsNZ Old'!#REF!+('InputsNZ Old'!#REF!*2) -> #REF! | K3: ='InputsNZ Old'!#REF!-('InputsNZ Old'!#REF!*2) -> #REF! | L3: ='InputsNZ Old'!#REF!+('InputsNZ Old'!#REF!*2) -> #REF!
A4: Macro Daytime Biomass | B4: (mmol N m-2) | C4: ='InputsNZ Old'!D35-('InputsNZ Old'!E35*2) -> -0.4379889 | D4: ='InputsNZ Old'!D35+('InputsNZ Old'!E35*2) -> 0.9170771 | E4: ='InputsNZ Old'!F35-('InputsNZ Old'!G35*2) -> -0.6937895 | F4: ='InputsNZ Old'!F35+('InputsNZ Old'!G35*2) -> 2.2757105 | G4: ='InputsNZ Old'!H35-('InputsNZ Old'!I35*2) -> -0.3262818 | H4: ='InputsNZ Old'!H35+('InputsNZ Old'!I35*2) -> 1.2640886 | I4: ='InputsNZ Old'!J35-('InputsNZ Old'!K35*2) -> -0.0298209 | J4: ='InputsNZ Old'!J35+('InputsNZ Old'!K35*2) -> 0.4940987 | K4: ='InputsNZ Old'!L35-('InputsNZ Old'!M35*2) -> -0.5133275 | L4: ='InputsNZ Old'!L35+('InputsNZ Old'!M35*2) -> 2.9243869 | O4: =non overlap of 95% CI
A5: Macro Nighttime Biomass | B5: (mmol N m-2) | C5: ='InputsNZ Old'!D36-('InputsNZ Old'!E36*2) -> -1.1090613 | D5: ='InputsNZ Old'!D36+('InputsNZ Old'!E36*2) -> 9.3728763 | E5: ='InputsNZ Old'!F36-('InputsNZ Old'!G36*2) -> -1.8364068 | F5: ='InputsNZ Old'!F36+('InputsNZ Old'!G36*2) -> 9.6691216 | G5: ='InputsNZ Old'!H36-('InputsNZ Old'!I36*2) -> 2.0223377 | H5: ='InputsNZ Old'!H36+('InputsNZ Old'!I36*2) -> 3.4505913 | I5: ='InputsNZ Old'!J36-('InputsNZ Old'!K36*2) -> 0.2286151 | J5: ='InputsNZ Old'!J36+('InputsNZ Old'!K36*2) -> 2.7342027 | K5: ='InputsNZ Old'!L36-('InputsNZ Old'!M36*2) -> 0.1801982 | L5: ='InputsNZ Old'!L36+('InputsNZ Old'!M36*2) -> 2.302361
A6: Salp Daytime Biomass | B6: (mmol N m-2) | C6: ='InputsNZ Old'!D39-('InputsNZ Old'!E39*2) -> -6.4044005 | D6: ='InputsNZ Old'!D39+('InputsNZ Old'!E39*2) -> 27.520577 | E6: ='InputsNZ Old'!F39-('InputsNZ Old'!G39*2) -> -3.0457028 | F6: ='InputsNZ Old'!F39+('InputsNZ Old'!G39*2) -> 10.068495 | G6: ='InputsNZ Old'!H39-('InputsNZ Old'!I39*2) -> -0.11231257 | H6: ='InputsNZ Old'!H39+('InputsNZ Old'!I39*2) -> 0.2625078 | I6: ='InputsNZ Old'!J39-('InputsNZ Old'!K39*2) -> -9.6778983 | J6: ='InputsNZ Old'!J39+('InputsNZ Old'!K39*2) -> 24.942193 | K6: ='InputsNZ Old'!L39-('InputsNZ Old'!M39*2) -> -0.006903559 | L6: ='InputsNZ Old'!L39+('InputsNZ Old'!M39*2) -> 0.010444773
A7: Salp Nighttime Biomass | B7: (mmol N m-2) | C7: ='InputsNZ Old'!D40-('InputsNZ Old'!E40*2) -> -17.211968 | D7: ='InputsNZ Old'!D40+('InputsNZ Old'!E40*2) -> 55.191142 | E7: ='InputsNZ Old'!F40-('InputsNZ Old'!G40*2) -> -18.242359 | F7: ='InputsNZ Old'!F40+('InputsNZ Old'!G40*2) -> 43.949458 | G7: ='InputsNZ Old'!H40-('InputsNZ Old'!I40*2) -> -0.23921078 | H7: ='InputsNZ Old'!H40+('InputsNZ Old'!I40*2) -> 0.48069517 | I7: ='InputsNZ Old'!J40-('InputsNZ Old'!K40*2) -> -6.6010026 | J7: ='InputsNZ Old'!J40+('InputsNZ Old'!K40*2) -> 40.547166 | K7: ='InputsNZ Old'!L40-('InputsNZ Old'!M40*2) -> -0.2415861 | L7: ='InputsNZ Old'!L40+('InputsNZ Old'!M40*2) -> 0.38675849

Sheet InputsGoM
A1: Approximate Equalities
C2: units | D2: Cycle 1 | E2: σ | F2: Cycle 2 | G2: σ | H2: Cycle 3 | I2: σ | J2: Cycle 4 | K2: σ | L2: Cycle 5 | M2: σ
A3: 1 | B3: NPP (shallow) | C3: (mmol N m-2 d-1) | D3: 2.2329248 | E3: 0.13172254 | F3: 1.9283162 | G3: 0.14673387 | H3: 2.4606589 | I3: 0.25933511 | J3: 2.3995215 | K3: 0.11430696 | L3: 3.0786664 | M3: 0.14435739
A4: 2 | B4: NPP (deep) | C4: (mmol N m-2 d-1) | D4: 1.6382198 | E4: 0.069593666 | F4: 1.7470766 | G4: 0.080316618 | H4: 1.3029279 | I4: 0.079118249 | J4: 1.9238949 | K4: 0.053269012 | L4: 1.3401135 | M4: 0.049844449
A5: 3 | B5: f-ratio (shallow) | C5: (mmol N m-2 d-1) | D5: 0.062294146 | E5: 0.041992261 | F5: 0.01219571 | G5: 0.0044924266 | H5: 0.038778995 | I5: 0.038778995 | J5: 0.055621528 | K5: 0.01730513 | L5: 0.13742101 | M5: 0.03689724
A6: 4 | B6: f-ratio (deep) | C6: (mmol N m-2 d-1) | D6: 0.43983739 | E6: 0.29649281 | F6: 0.026383357 | G6: 0.0097186054 | H6: 0.072350572 | I6: 0.072350572 | J6: 0.067714922 | K6: 0.021067662 | L6: 0.08793973 | M6: 0.023611625
A7: 5 | B7: Protistan Grazing Rate (shallow) | C7: (mmol N m-2 d-1) | D7: 1.723072 | E7: 0.60188276 | F7: 1.8606081 | G7: 0.91678692 | H7: 1.9843654 | I7: 0.53716303 | J7: 1.753319 | K7: 0.36945195 | L7: 2.5784524 | M7: 0.14195563
A8: 6 | B8: Protistan Grazing Rate (deep) | C8: (mmol N m-2 d-1) | D8: 1.4401792 | E8: 0.48465547 | F8: 2.8732688 | G8: 1.4157604 | H8: 0.6111834 | I8: 0.17647198 | J8: 1.1788914 | K8: 0.21341762 | L8: 0.65577444 | M8: 0.18287541
A9: 7 | B9: Picophyto NPP (shallow) | C9: (mmol N m-2 d-1) | D9: 1.147709 | E9: 0.21039802 | L9: 2.3767991 | M9: 0.37262912
A10: 8 | B10: Picophyto NPP (deep) | C10: (mmol N m-2 d-1) | D10: 0.78221536 | E10: 0.15006335 | L10: 1.0164363 | M10: 0.17072999
A11: 9 | B11: Flagellate NPP (shallow) | C11: (mmol N m-2 d-1) | D11: 1.0075775 | E11: 0.37100501 | L11: 0.69307865 | M11: 0.17378771
A12: 10 | B12: Flagellate NPP (deep) | C12: (mmol N m-2 d-1) | D12: 0.83287425 | E12: 0.34955766 | L12: 0.32034754 | M12: 0.13453466
A13: 11 | B13: Diatom NPP (shallow) | C13: (mmol N m-2 d-1) | D13: 0.077638331 | E13: 0.027224847 | L13: 0.0087886314 | M13: 0.0019691453
A14: 12 | B14: Diatom NPP (deep) | C14: (mmol N m-2 d-1) | D14: 0.023130147 | E14: 0.017051733 | L14: 0.0033296153 | M14: 0.001551409
A15: 13 | B15: Picophyto Mortality (shallow) | C15: (mmol N m-2 d-1) | D15: 0.70857998 | E15: 0.31922056 | L15: 1.6032266 | M15: 0.12427733
A16: 14 | B16: Picophyto Mortality (deep) | C16: (mmol N m-2 d-1) | D16: 0.43324558 | E16: 0.068085926 | L16: 0.34152828 | M16: 0.094361057
A17: 15 | B17: Flagellate Mortality (shallow) | C17: (mmol N m-2 d-1) | D17: 0.85893448 | E17: 0.26197643 | L17: 0.18742381 | M17: 0.11148251
A18: 16 | B18: Flagellate Mortality (deep) | C18: (mmol N m-2 d-1) | D18: 0.60031879 | E18: 0.16713771 | L18: 0.035968037 | M18: 0.021486961 | P18: =SUM(D15,D17,D19) -> 1.60886
A19: 17 | B19: Diatom Mortality (shallow) | C19: (mmol N m-2 d-1) | D19: 0.041345588 | E19: 0.015944957 | L19: 0.0097847636 | M19: 0.0044883973 | P19: =SUM(D16,D18,D20) -> 1.0410446
A20: 18 | B20: Diatom Mortality (deep) | C20: (mmol N m-2 d-1) | D20: 0.0074801872 | E20: 0.0057976766 | L20: 0.0037504794 | M20: 0.00088941517
A21: 19 | B21: NVM Mesozoo Grazing | C21: (mmol N m-2 d-1) | D21: 0.39262737 | E21: 0.10410631 | F21: 0.14526121 | G21: 0.016449862 | H21: 0.45533492 | I21: 0.053561542 | J21: 0.20755597 | K21: 0.040408163 | L21: 0.52233099 | M21: 0.10268711
A22: 20 | B22: VM Mesozoo Grazing | C22: (mmol N m-2 d-1) | D22: 0.028318441 | E22: 0.05788828 | F22: 0.13048976 | G22: 0.062108398 | H22: 0.08566292 | I22: 0.046799843 | J22: 0.02447408 | K22: 0.022821176 | L22: 0.1457047 | M22: 0.080998094
A23: 21 | B23: SedTrap Flux (shallow) | C23: (mmol N m-2 d-1) | D23: 1.5254872 | E23: 0.54896819 | F23: 0.82116704 | G23: 0.048665046 | H23: 0.97972777 | I23: 0.25826531 | J23: 0.5867111 | K23: 0.041525241 | L23: 1.0789254 | M23: 0.072986394
A24: 22 | B24: SedTrap Flux (deep) | C24: (mmol N m-2 d-1) | D24: 0.46220361 | E24: 0.023855849 | F24: 0.51737967 | G24: 0.17613659 | H24: 1.1437933 | I24: 0.17605707 | J24: 0.47090312 | K24: 0.095136531 | L24: 0.87099463 | M24: 0.18499252
A25: 23 | B25: Thorium Flux (shallow) | C25: (mmol N m-2 d-1) | D25: NaN | E25: NaN | F25: NaN | G25: NaN | H25: NaN | I25: NaN | J25: NaN | K25: NaN | L25: NaN | M25: NaN
A26: 24 | B26: Thorium Flux (deep) | C26: (mmol N m-2 d-1) | D26: NaN | E26: NaN | F26: NaN | G26: NaN | H26: NaN | I26: NaN | J26: NaN | K26: NaN | L26: NaN | M26: NaN
A27: 25 | B27: Chl Sinking (shallow) | C27: (mmol N m-2 d-1) | D27: 0.024215547 | E27: 0.016283247 | F27: 0.021892051 | G27: 0.0098242137 | H27: NaN | I27: NaN | J27: 0.0062693574 | K27: 0.004368352 | L27: 0.026825777 | M27: 0.017142775
A28: 26 | B28: Chl Sinking (deep) | C28: (mmol N m-2 d-1) | D28: 0.019431071 | E28: 0.01073278 | F28: 0.060639853 | G28: 0.023479797 | H28: NaN | I28: NaN | J28: 0.015659181 | K28: 0.020799846 | L28: 0.045497096 | M28: 0.035031316
A29: 27 | B29: Fecal Pellet Sinking (shallow) | C29: (mmol N m-2 d-1) | D29: 0.032490633 | E29: 0.031548741 | F29: 0.006161405 | G29: 0.0053418972 | H29: NaN | I29: NaN | J29: 0.0042087847 | K29: 0.0028798977 | L29: 0.019904471 | M29: 0.017051591
A30: 28 | B30: Fecal Pellet Sinking (deep) | C30: (mmol N m-2 d-1) | D30: 0.13285093 | E30: 0.063483055 | F30: 0.088514769 | G30: 0.060200143 | H30: NaN | I30: NaN | J30: 0.14496991 | K30: 0.1373382 | L30: 0.24599805 | M30: 0.19890878
A31: 29 | B31: Microzoo to Preflex | C31: (mmol N m-2 d-1) | D31: 3.4022642e-07 | E31: 1.6323076e-07 | L31: 0 | M31: 1e-08
A32: 30 | B32: Microzoo to Postflex | C32: (mmol N m-2 d-1) | D32: 5.4470126e-06 | E32: 8.8447287e-07 | L32: 0 | M32: 1e-08
A33: 31 | B33: Appendicularian to Preflex | C33: (mmol N m-2 d-1) | D33: 7.6550943e-07 | E33: 3.1597126e-07 | L33: 4.2528302e-08 | M33: 3.0265243e-08
A34: 32 | B34: Appendicularian to Postflex | C34: (mmol N m-2 d-1) | D34: 6.7542956e-06 | E34: 4.7107636e-07 | L34: 1.8845849e-06 | M34: 1.9865269e-07
A35: 33 | B35: Cladoceran to Preflex | C35: (mmol N m-2 d-1) | D35: 2.9769811e-07 | E35: 2.9769811e-07 | L35: 1.3183774e-06 | M35: 4.201161e-07
A36: 34 | B36: Cladoceran to Postflex | C36: (mmol N m-2 d-1) | D36: 5.2509201e-05 | E36: 5.0610971e-06 | L36: 4.9991094e-05 | M36: 5.269524e-06
A37: 35 | B37: Calanoids to Preflex | C37: (mmol N m-2 d-1) | D37: 3.6149057e-06 | E37: 1.3393527e-06 | L37: 1.8712453e-06 | M37: 3.4714733e-07
A38: 36 | B38: Calanoids to Postflex | C38: (mmol N m-2 d-1) | D38: 6.3621107e-05 | E38: 9.5883951e-07 | L38: 1.348966e-05 | M38: 3.1841642e-07
A39: 37 | B39: Poecilastomatoids to Preflex | C39: (mmol N m-2 d-1) | D39: 0 | E39: 1e-08 | L39: 0 | M39: 1e-08
A40: 38 | B40: Poecilastomatoids to Postflex | C40: (mmol N m-2 d-1) | D40: 1.743044e-06 | E40: 2.6262841e-06 | L40: 8.9269811e-07 | M40: 3.1366214e-08
...

Sheet InputCRD
A1: See Bvec of N15InverseModel matrix file
