Workbook

Sheet Sheet1
A1: Flow | B1: Units | C1: Cycle 1 | D1: σ | E1: Cycle 2 | F1: σ | G1: Cycle 3 | H1: σ | I1: Cycle 4 | J1: σ | K1: Cycle 5 | L1: σ
A2: Upwelling | B2: (mmol N m-2 d-1) | C2: 3.0751036 | D2: 0.65225304 | E2: 3.1533335 | F2: 0.36897539 | G2: 1.421977 | H2: 0.51586102 | I2: 2.3084207 | J2: 0.43843939 | K2: 0.83924824 | L2: 0.24943797
A3: NH4->NO3 | B3: (mmol N m-2 d-1) | C3: 4.4003391 | D3: 2.4750406 | E3: 2.270995 | F3: 1.4667713 | G3: 2.5621042 | H3: 2.1471049 | I3: 3.2219721 | J3: 1.8688173 | K3: 1.7982934 | L3: 1.1338468
A4: NH4->Pico | B4: (mmol N m-2 d-1) | C4: 1.823113 | D4: 1.1623745 | E4: 2.2187304 | F4: 1.4391126 | G4: 6.1417979 | H4: 2.3934277 | I4: 1.2818726 | J4: 0.75396335 | K4: 1.9227376 | L4: 1.0901564
A5: NH4->dtm | B5: (mmol N m-2 d-1) | C5: 3.1122117 | D5: 1.9924542 | E5: 0.67287565 | F5: 0.43198107 | G5: 0.36179112 | H5: 0.25622932 | I5: 0.27941919 | J5: 0.17154886 | K5: 0.31774766 | L5: 0.20829808
A6: NH4->flag | B6: (mmol N m-2 d-1) | C6: 1.7878143 | D6: 1.1314409 | E6: 1.0710812 | F6: 0.72412296 | G6: 0.34832865 | H6: 0.24944091 | I6: 2.8345974 | J6: 1.7982159 | K6: 0.55084332 | L6: 0.38935023
A7: NO3->Pico | B7: (mmol N m-2 d-1) | C7: 2.161388 | D7: 1.1794541 | E7: 3.3546223 | F7: 1.4698327 | G7: 3.0830095 | H7: 2.3860288 | I7: 1.3282893 | J7: 0.75366186 | K7: 1.7353847 | L7: 1.0945226
A8: NO3->dtm | B8: (mmol N m-2 d-1) | C8: 3.4786813 | D8: 2.0170319 | E8: 0.70196115 | F8: 0.43640191 | G8: 0.52353857 | H8: 0.2655566 | I8: 0.28344147 | J8: 0.17256359 | K8: 0.35011512 | L8: 0.21264113
A9: NO3->flag | B9: (mmol N m-2 d-1) | C9: 1.8353734 | D9: 1.1451956 | E9: 1.367745 | F9: 0.76597254 | G9: 0.37753321 | H9: 0.25732433 | I9: 3.9186621 | J9: 1.817312 | K9: 0.55204179 | L9: 0.37884509
A10: bac->flag | B10: (mmol N m-2 d-1) | C10: 0.30611166 | D10: 0.21491478 | E10: 0.35015217 | F10: 0.22730866 | G10: 0.21151008 | H10: 0.16672916 | I10: 0.2801009 | J10: 0.21221125 | K10: 0.18153871 | L10: 0.13006241
A11: bac->hnf | B11: (mmol N m-2 d-1) | C11: 0.40415001 | D11: 0.24164104 | E11: 0.38909184 | F11: 0.23543649 | G11: 0.56065742 | H11: 0.24204102 | I11: 0.47572538 | J11: 0.26749239 | K11: 0.22377717 | L11: 0.14425268
A12: bac->mic | B12: (mmol N m-2 d-1) | C12: 0.17791992 | D12: 0.15442811 | E12: 0.089796137 | F12: 0.073454491 | G12: 0.1451672 | H12: 0.10632517 | I12: 0.22511632 | J12: 0.18955601 | K12: 0.1321965 | L12: 0.10858483
A13: bac->nh4 | B13: (mmol N m-2 d-1) | C13: 6.6405301 | D13: 1.5038193 | E13: 3.3560146 | F13: 0.70030389 | G13: 3.7772836 | H13: 0.60031434 | I13: 3.647757 | J13: 0.68192699 | K13: 2.3918395 | L13: 0.51480102
... A21: dtm->Meso | B21: (mmol N m-2 d-1) | C21: 0.55396005 | D21: 0.30209441 | E21: 0.15281537 | F21: 0.13702624 | G21: 0.082758924 | H21: 0.071175208 | I21: 0.088628176 | J21: 0.070681175 | K21: 0.095964328 | L21: 0.082227382
A22: dtm->VMMeso | B22: (mmol N m-2 d-1) | C22: NA | D22: NA | E22: 0.14182331 | F22: 0.12477668 | G22: 0.05668001 | H22: 0.043736298 | I22: 0.062661759 | J22: 0.052597013 | K22: 0.089680991 | L22: 0.075859328
A23: dtm->Macro | B23: (mmol N m-2 d-1) | C23: 0.019054763 | D23: 0.015013024 | E23: 0.041826496 | F23: 0.035221665 | G23: 0.0073051238 | H23: 0.0057981847 | I23: 0.01012874 | J23: 0.0081987162 | K23: 0.020417337 | L23: 0.016246767
A24: dtm->VMMacro | B24: (mmol N m-2 d-1) | C24: 0.010172609 | D24: 0.008075452 | E24: 0.032995876 | F24: 0.02717185 | G24: 0.005109371 | H24: 0.0040820943 | I24: 0.00653512 | J24: 0.0054413087 | K24: 0.00079731363 | L24: 0.00069690498
A25: dtm->Salp | B25: (mmol N m-2 d-1) | C25: 1.003764 | D25: 0.41091759 | E25: 0.15147863 | F25: 0.13199435 | G25: 1.9514412e-05 | H25: 1.1860666e-05 | I25: 9.5877195e-06 | J25: 4.6946075e-06 | K25: 0.0015206025 | L25: 0.0010548759
A26: dtm->dom | B26: (mmol N m-2 d-1) | C26: 1.5607629 | D26: 0.84049177 | E26: 0.3260091 | F26: 0.17067369 | G26: 0.12406767 | H26: 0.080851723 | I26: 0.11102807 | J26: 0.060498391 | K26: 0.145756 | L26: 0.078583934
A27: dtm->mdet | B27: (mmol N m-2 d-1) | C27: 2.5760375 | D27: 0.99841295 | E27: 0.46011622 | F27: 0.23490147 | G27: 0.5143681 | H27: 0.17329502 | I27: 0.15112556 | J27: 0.10337358 | K27: 0.21823983 | L27: 0.13499113
A28: flag->mic | B28: (mmol N m-2 d-1) | C28: 0.49355459 | D28: 0.3662485 | E28: 0.099398314 | F28: 0.078115787 | G28: 0.4277316 | H28: 0.1833272 | I28: 3.5182983 | J28: 0.58966564 | K28: 0.58767767 | L28: 0.27128277
A29: flag->Meso | B29: (mmol N m-2 d-1) | C29: 0.42976581 | D29: 0.28739947 | E29: 0.84531807 | F29: 0.29308505 | G29: 0.25486422 | H29: 0.10906262 | I29: 0.29069849 | J29: 0.12524803 | K29: 0.34868125 | L29: 0.15423013
A30: flag->VMMeso | B30: (mmol N m-2 d-1) | C30: NA | D30: NA | E30: 0.51214973 | F30: 0.22256238 | G30: 0.094587728 | H30: 0.049919149 | I30: 0.11208254 | J30: 0.078707614 | K30: 0.2518445 | L30: 0.12735167
A31: flag->Macro | B31: (mmol N m-2 d-1) | C31: 0.018917871 | D31: 0.014826334 | E31: 0.05601731 | F31: 0.04120112 | G31: 0.0088530367 | H31: 0.0068831946 | I31: 0.0096195764 | J31: 0.0076848203 | K31: 0.023525244 | L31: 0.017732286
A32: flag->VMMacro | B32: (mmol N m-2 d-1) | C32: 0.010201352 | D32: 0.0080675476 | E32: 0.039351417 | F32: 0.03053033 | G32: 0.0056474761 | H32: 0.004332805 | I32: 0.0064353934 | J32: 0.005286067 | K32: 0.00075714427 | L32: 0.00066381514
A33: flag->Salp | B33: (mmol N m-2 d-1) | C33: 2.4194455 | D33: 0.63065886 | E33: 1.1946319 | F33: 0.36930689 | G33: 0.042374606 | H33: 0.014452192 | I33: 1.800267 | J33: 0.40560443 | K33: 0.0078412245 | L33: 0.0018214512
A34: flag->dom | B34: (mmol N m-2 d-1) | C34: 0.86569478 | D34: 0.45626795 | E34: 0.60983672 | F34: 0.27724727 | G34: 0.18095659 | H34: 0.096083102 | I34: 1.4766285 | J34: 0.65545748 | K34: 0.27368345 | L34: 0.14947264
A35: flag->sdet | B35: (mmol N m-2 d-1) | C35: 0.25108183 | D35: 0.15772667 | E35: 0.2833052 | F35: 0.15923227 | G35: 0.16101834 | H35: 0.10742418 | I35: 0.20713773 | J35: 0.13456954 | K35: 0.18052441 | L35: 0.11706376
A36: hnf->mic | B36: (mmol N m-2 d-1) | C36: 0.20034488 | D36: 0.17710621 | E36: 0.06437964 | F36: 0.055351942 | G36: 0.083832069 | H36: 0.076014191 | I36: 0.17379385 | J36: 0.16237786 | K36: 0.12577028 | L36: 0.11702005
A37: hnf->Meso | B37: (mmol N m-2 d-1) | C37: 0.33108825 | D37: 0.25467755 | E37: 0.29235065 | F37: 0.24632398 | G37: 1.9839975 | H37: 0.79160889 | I37: 0.3020373 | J37: 0.23593134 | K37: 0.30695145 | L37: 0.22538879
A38: hnf->VMMeso | B38: (mmol N m-2 d-1) | C38: NA | D38: NA | E38: 0.90245195 | F38: 0.37155753 | G38: 2.1096993 | H38: 0.80073886 | I38: 0.32226761 | J38: 0.24832669 | K38: 0.62101846 | L38: 0.28760048
A39: hnf->Macro | B39: (mmol N m-2 d-1) | C39: 0.026647168 | D39: 0.021760709 | E39: 0.086824125 | F39: 0.06701255 | G39: 0.016757872 | H39: 0.013841723 | I39: 0.020734993 | J39: 0.018023397 | K39: 0.10929121 | L39: 0.088494311
A40: hnf->VMMacro | B40: (mmol N m-2 d-1) | C40: 0.15695419 | D40: 0.10662934 | E40: 0.28277704 | F40: 0.17767093 | G40: 0.053066831 | H40: 0.028085547 | I40: 0.046827574 | J40: 0.0363979 | K40: 0.00085697668 | L40: 0.00073855024
A41: hnf->Salp | B41: (mmol N m-2 d-1) | C41: 0.34496307 | D41: 0.26366219 | E41: 0.16570415 | F41: 0.15244082 | G41: 0.0098404421 | H41: 0.0071236956 | I41: 0.14338672 | J41: 0.12896587 | K41: 0.00064543548 | L41: 0.00052157248
A42: hnf->nh4 | B42: (mmol N m-2 d-1) | C42: 0.99308233 | D42: 0.30230558 | E42: 1.1091851 | F42: 0.20433003 | G42: 2.8038842 | H42: 0.40081262 | I42: 0.79753005 | J42: 0.23066856 | K42: 0.83315214 | L42: 0.17762229
A43: hnf->dom | B43: (mmol N m-2 d-1) | C43: 0.54632654 | D43: 0.18730703 | E43: 0.62303316 | F43: 0.14660942 | G43: 1.5544714 | H43: 0.30931277 | I43: 0.45069424 | J43: 0.15116459 | K43: 0.47074488 | L43: 0.12461343
A44: hnf->sdet | B44: (mmol N m-2 d-1) | C44: 0.80113169 | D44: 0.35778798 | E44: 1.2297542 | F44: 0.33627372 | G44: 3.1993512 | H44: 1.0022767 | I44: 0.76523376 | J44: 0.33326746 | K44: 0.87832714 | L44: 0.32525419
A45: mic->Meso | B45: (mmol N m-2 d-1) | C45: 0.31247013 | D45: 0.21514635 | E45: 0.038259881 | F45: 0.032852448 | G45: 0.081967536 | H45: 0.05625228 | I45: 0.82996952 | J45: 0.47866569 | K45: 0.16722519 | L45: 0.123081
A46: mic->VMMeso | B46: (mmol N m-2 d-1) | C46: NA | D46: NA | E46: 0.04516077 | F46: 0.037169657 | G46: 0.15113991 | H46: 0.042911638 | I46: 0.92982355 | J46: 0.49541301 | K46: 0.22544952 | L46: 0.13920197
A47: mic->Macro | B47: (mmol N m-2 d-1) | C47: 0.026080718 | D47: 0.021439228 | E47: 0.033184399 | F47: 0.028710672 | G47: 0.016694445 | H47: 0.013648757 | I47: 0.025274543 | J47: 0.022601233 | K47: 0.09286676 | L47: 0.074805683
...

Sheet Sheet1 (2)
A1: Flow | B1: Units | C1: Cycle 1 | D1: σ | E1: Cycle 2 | F1: σ | G1: Cycle 3 | H1: σ | I1: Cycle 4 | J1: σ | K1: Cycle 5 | L1: σ
A2: Upwelling | B2: (µmol N m-2 d-1) | C2: =ROUND(Sheet1!C2*1000,1) -> 3075.1 | D2: =ROUND(Sheet1!D2*1000,1) -> 652.3 | E2: =ROUND(Sheet1!E2*1000,1) -> 3153.3 | F2: =ROUND(Sheet1!F2*1000,1) -> 369 | G2: =ROUND(Sheet1!G2*1000,1) -> 1422 | H2: =ROUND(Sheet1!H2*1000,1) -> 515.9 | I2: =ROUND(Sheet1!I2*1000,1) -> 2308.4 | J2: =ROUND(Sheet1!J2*1000,1) -> 438.4 | ... L2: =ROUND(Sheet1!L2*1000,1) -> 249.4
A3: NH4->NO3 | B3: (µmol N m-2 d-1) | C3: =ROUND(Sheet1!C3*1000,1) -> 4400.3 | D3: =ROUND(Sheet1!D3*1000,1) -> 2475 | E3: =ROUND(Sheet1!E3*1000,1) -> 2271 | F3: =ROUND(Sheet1!F3*1000,1) -> 1466.8 | G3: =ROUND(Sheet1!G3*1000,1) -> 2562.1 | H3: =ROUND(Sheet1!H3*1000,1) -> 2147.1 | I3: =ROUND(Sheet1!I3*1000,1) -> 3222 | J3: =ROUND(Sheet1!J3*1000,1) -> 1868.8 | ... L3: =ROUND(Sheet1!L3*1000,1) -> 1133.8
A4: NH4->Pico | B4: (µmol N m-2 d-1) | C4: =ROUND(Sheet1!C4*1000,1) -> 1823.1 | D4: =ROUND(Sheet1!D4*1000,1) -> 1162.4 | E4: =ROUND(Sheet1!E4*1000,1) -> 2218.7 | F4: =ROUND(Sheet1!F4*1000,1) -> 1439.1 | G4: =ROUND(Sheet1!G4*1000,1) -> 6141.8 | H4: =ROUND(Sheet1!H4*1000,1) -> 2393.4 | I4: =ROUND(Sheet1!I4*1000,1) -> 1281.9 | J4: =ROUND(Sheet1!J4*1000,1) -> 754 | ... L4: =ROUND(Sheet1!L4*1000,1) -> 1090.2
A5: NH4->dtm | B5: (µmol N m-2 d-1) | C5: =ROUND(Sheet1!C5*1000,1) -> 3112.2 | D5: =ROUND(Sheet1!D5*1000,1) -> 1992.5 | E5: =ROUND(Sheet1!E5*1000,1) -> 672.9 | F5: =ROUND(Sheet1!F5*1000,1) -> 432 | G5: =ROUND(Sheet1!G5*1000,1) -> 361.8 | H5: =ROUND(Sheet1!H5*1000,1) -> 256.2 | I5: =ROUND(Sheet1!I5*1000,1) -> 279.4 | J5: =ROUND(Sheet1!J5*1000,1) -> 171.5 | ... L5: =ROUND(Sheet1!L5*1000,1) -> 208.3
A6: NH4->flag | B6: (µmol N m-2 d-1) | C6: =ROUND(Sheet1!C6*1000,1) -> 1787.8 | D6: =ROUND(Sheet1!D6*1000,1) -> 1131.4 | E6: =ROUND(Sheet1!E6*1000,1) -> 1071.1 | F6: =ROUND(Sheet1!F6*1000,1) -> 724.1 | G6: =ROUND(Sheet1!G6*1000,1) -> 348.3 | H6: =ROUND(Sheet1!H6*1000,1) -> 249.4 | I6: =ROUND(Sheet1!I6*1000,1) -> 2834.6 | J6: =ROUND(Sheet1!J6*1000,1) -> 1798.2 | ... L6: =ROUND(Sheet1!L6*1000,1) -> 389.4
A7: NO3->Pico | B7: (µmol N m-2 d-1) | C7: =ROUND(Sheet1!C7*1000,1) -> 2161.4 | D7: =ROUND(Sheet1!D7*1000,1) -> 1179.5 | E7: =ROUND(Sheet1!E7*1000,1) -> 3354.6 | F7: =ROUND(Sheet1!F7*1000,1) -> 1469.8 | G7: =ROUND(Sheet1!G7*1000,1) -> 3083 | H7: =ROUND(Sheet1!H7*1000,1) -> 2386 | I7: =ROUND(Sheet1!I7*1000,1) -> 1328.3 | J7: =ROUND(Sheet1!J7*1000,1) -> 753.7 | ... L7: =ROUND(Sheet1!L7*1000,1) -> 1094.5
A8: NO3->dtm | B8: (µmol N m-2 d-1) | C8: =ROUND(Sheet1!C8*1000,1) -> 3478.7 | D8: =ROUND(Sheet1!D8*1000,1) -> 2017 | E8: =ROUND(Sheet1!E8*1000,1) -> 702 | F8: =ROUND(Sheet1!F8*1000,1) -> 436.4 | G8: =ROUND(Sheet1!G8*1000,1) -> 523.5 | H8: =ROUND(Sheet1!H8*1000,1) -> 265.6 | I8: =ROUND(Sheet1!I8*1000,1) -> 283.4 | J8: =ROUND(Sheet1!J8*1000,1) -> 172.6 | ... L8: =ROUND(Sheet1!L8*1000,1) -> 212.6
A9: NO3->flag | B9: (µmol N m-2 d-1) | C9: =ROUND(Sheet1!C9*1000,1) -> 1835.4 | D9: =ROUND(Sheet1!D9*1000,1) -> 1145.2 | E9: =ROUND(Sheet1!E9*1000,1) -> 1367.7 | F9: =ROUND(Sheet1!F9*1000,1) -> 766 | G9: =ROUND(Sheet1!G9*1000,1) -> 377.5 | H9: =ROUND(Sheet1!H9*1000,1) -> 257.3 | I9: =ROUND(Sheet1!I9*1000,1) -> 3918.7 | J9: =ROUND(Sheet1!J9*1000,1) -> 1817.3 | ... L9: =ROUND(Sheet1!L9*1000,1) -> 378.8
A10: bac->flag | B10: (µmol N m-2 d-1) | C10: =ROUND(Sheet1!C10*1000,1) -> 306.1 | D10: =ROUND(Sheet1!D10*1000,1) -> 214.9 | E10: =ROUND(Sheet1!E10*1000,1) -> 350.2 | F10: =ROUND(Sheet1!F10*1000,1) -> 227.3 | G10: =ROUND(Sheet1!G10*1000,1) -> 211.5 | H10: =ROUND(Sheet1!H10*1000,1) -> 166.7 | I10: =ROUND(Sheet1!I10*1000,1) -> 280.1 | J10: =ROUND(Sheet1!J10*1000,1) -> 212.2 | ... L10: =ROUND(Sheet1!L10*1000,1) -> 130.1
A11: bac->hnf | B11: (µmol N m-2 d-1) | C11: =ROUND(Sheet1!C11*1000,1) -> 404.2 | D11: =ROUND(Sheet1!D11*1000,1) -> 241.6 | E11: =ROUND(Sheet1!E11*1000,1) -> 389.1 | F11: =ROUND(Sheet1!F11*1000,1) -> 235.4 | G11: =ROUND(Sheet1!G11*1000,1) -> 560.7 | H11: =ROUND(Sheet1!H11*1000,1) -> 242 | I11: =ROUND(Sheet1!I11*1000,1) -> 475.7 | J11: =ROUND(Sheet1!J11*1000,1) -> 267.5 | ... L11: =ROUND(Sheet1!L11*1000,1) -> 144.3
A12: bac->mic | B12: (µmol N m-2 d-1) | C12: =ROUND(Sheet1!C12*1000,1) -> 177.9 | D12: =ROUND(Sheet1!D12*1000,1) -> 154.4 | E12: =ROUND(Sheet1!E12*1000,1) -> 89.8 | F12: =ROUND(Sheet1!F12*1000,1) -> 73.5 | G12: =ROUND(Sheet1!G12*1000,1) -> 145.2 | H12: =ROUND(Sheet1!H12*1000,1) -> 106.3 | I12: =ROUND(Sheet1!I12*1000,1) -> 225.1 | J12: =ROUND(Sheet1!J12*1000,1) -> 189.6 | ... L12: =ROUND(Sheet1!L12*1000,1) -> 108.6
A13: bac->nh4 | B13: (µmol N m-2 d-1) | C13: =ROUND(Sheet1!C13*1000,1) -> 6640.5 | D13: =ROUND(Sheet1!D13*1000,1) -> 1503.8 | E13: =ROUND(Sheet1!E13*1000,1) -> 3356 | F13: =ROUND(Sheet1!F13*1000,1) -> 700.3 | G13: =ROUND(Sheet1!G13*1000,1) -> 3777.3 | H13: =ROUND(Sheet1!H13*1000,1) -> 600.3 | I13: =ROUND(Sheet1!I13*1000,1) -> 3647.8 | J13: =ROUND(Sheet1!J13*1000,1) -> 681.9 | ... L13: =ROUND(Sheet1!L13*1000,1) -> 514.8
... A24: dtm->VMMacro | B24: (µmol N m-2 d-1) | C24: =ROUND(Sheet1!C24*1000,1) -> 10.2 | D24: =ROUND(Sheet1!D24*1000,1) -> 8.1 | E24: =ROUND(Sheet1!E24*1000,1) -> 33 | F24: =ROUND(Sheet1!F24*1000,1) -> 27.2 | G24: =ROUND(Sheet1!G24*1000,1) -> 5.1 | H24: =ROUND(Sheet1!H24*1000,1) -> 4.1 | I24: =ROUND(Sheet1!I24*1000,1) -> 6.5 | J24: =ROUND(Sheet1!J24*1000,1) -> 5.4 | ... L24: =ROUND(Sheet1!L24*1000,1) -> 0.7
A25: dtm->Salp | B25: (µmol N m-2 d-1) | C25: =ROUND(Sheet1!C25*1000,1) -> 1003.8 | D25: =ROUND(Sheet1!D25*1000,1) -> 410.9 | E25: =ROUND(Sheet1!E25*1000,1) -> 151.5 | F25: =ROUND(Sheet1!F25*1000,1) -> 132 | G25: =ROUND(Sheet1!G25*1000,2) -> 0.02 | H25: =ROUND(Sheet1!H25*1000,2) -> 0.01 | I25: =ROUND(Sheet1!I25*1000,2) -> 0.01 | J25: =ROUND(Sheet1!J25*1000,3) -> 0.005 | K25: =ROUND(Sheet1!K25*1000,1) -> 1.5 | L25: =ROUND(Sheet1!L25*1000,1) -> 1.1
A26: dtm->dom | B26: (µmol N m-2 d-1) | C26: =ROUND(Sheet1!C26*1000,1) -> 1560.8 | D26: =ROUND(Sheet1!D26*1000,1) -> 840.5 | E26: =ROUND(Sheet1!E26*1000,1) -> 326 | F26: =ROUND(Sheet1!F26*1000,1) -> 170.7 | G26: =ROUND(Sheet1!G26*1000,1) -> 124.1 | H26: =ROUND(Sheet1!H26*1000,1) -> 80.9 | I26: =ROUND(Sheet1!I26*1000,1) -> 111 | J26: =ROUND(Sheet1!J26*1000,1) -> 60.5 | ... L26: =ROUND(Sheet1!L26*1000,1) -> 78.6
A27: dtm->mdet | B27: (µmol N m-2 d-1) | C27: =ROUND(Sheet1!C27*1000,1) -> 2576 | D27: =ROUND(Sheet1!D27*1000,1) -> 998.4 | E27: =ROUND(Sheet1!E27*1000,1) -> 460.1 | F27: =ROUND(Sheet1!F27*1000,1) -> 234.9 | G27: =ROUND(Sheet1!G27*1000,1) -> 514.4 | H27: =ROUND(Sheet1!H27*1000,1) -> 173.3 | I27: =ROUND(Sheet1!I27*1000,1) -> 151.1 | J27: =ROUND(Sheet1!J27*1000,1) -> 103.4 | ... L27: =ROUND(Sheet1!L27*1000,1) -> 135
A28: flag->mic | B28: (µmol N m-2 d-1) | C28: =ROUND(Sheet1!C28*1000,1) -> 493.6 | D28: =ROUND(Sheet1!D28*1000,1) -> 366.2 | E28: =ROUND(Sheet1!E28*1000,1) -> 99.4 | F28: =ROUND(Sheet1!F28*1000,1) -> 78.1 | G28: =ROUND(Sheet1!G28*1000,1) -> 427.7 | H28: =ROUND(Sheet1!H28*1000,1) -> 183.3 | I28: =ROUND(Sheet1!I28*1000,1) -> 3518.3 | J28: =ROUND(Sheet1!J28*1000,1) -> 589.7 | ... L28: =ROUND(Sheet1!L28*1000,1) -> 271.3
A29: flag->Meso | B29: (µmol N m-2 d-1) | C29: =ROUND(Sheet1!C29*1000,1) -> 429.8 | D29: =ROUND(Sheet1!D29*1000,1) -> 287.4 | E29: =ROUND(Sheet1!E29*1000,1) -> 845.3 | F29: =ROUND(Sheet1!F29*1000,1) -> 293.1 | G29: =ROUND(Sheet1!G29*1000,1) -> 254.9 | H29: =ROUND(Sheet1!H29*1000,1) -> 109.1 | I29: =ROUND(Sheet1!I29*1000,1) -> 290.7 | J29: =ROUND(Sheet1!J29*1000,1) -> 125.2 | ... L29: =ROUND(Sheet1!L29*1000,1) -> 154.2
A30: flag->VMMeso | B30: (µmol N m-2 d-1) | C30: =ROUND(Sheet1!C30*1000,1) -> #VALUE! | D30: =ROUND(Sheet1!D30*1000,1) -> #VALUE! | E30: =ROUND(Sheet1!E30*1000,1) -> 512.1 | F30: =ROUND(Sheet1!F30*1000,1) -> 222.6 | G30: =ROUND(Sheet1!G30*1000,1) -> 94.6 | H30: =ROUND(Sheet1!H30*1000,1) -> 49.9 | I30: =ROUND(Sheet1!I30*1000,1) -> 112.1 | J30: =ROUND(Sheet1!J30*1000,1) -> 78.7 | ... L30: =ROUND(Sheet1!L30*1000,1) -> 127.4
A31: flag->Macro | B31: (µmol N m-2 d-1) | C31: =ROUND(Sheet1!C31*1000,1) -> 18.9 | D31: =ROUND(Sheet1!D31*1000,1) -> 14.8 | E31: =ROUND(Sheet1!E31*1000,1) -> 56 | F31: =ROUND(Sheet1!F31*1000,1) -> 41.2 | G31: =ROUND(Sheet1!G31*1000,1) -> 8.9 | H31: =ROUND(Sheet1!H31*1000,1) -> 6.9 | I31: =ROUND(Sheet1!I31*1000,1) -> 9.6 | J31: =ROUND(Sheet1!J31*1000,1) -> 7.7 | ... L31: =ROUND(Sheet1!L31*1000,1) -> 17.7
A32: flag->VMMacro | B32: (µmol N m-2 d-1) | C32: =ROUND(Sheet1!C32*1000,1) -> 10.2 | D32: =ROUND(Sheet1!D32*1000,1) -> 8.1 | E32: =ROUND(Sheet1!E32*1000,1) -> 39.4 | F32: =ROUND(Sheet1!F32*1000,1) -> 30.5 | G32: =ROUND(Sheet1!G32*1000,1) -> 5.6 | H32: =ROUND(Sheet1!H32*1000,1) -> 4.3 | I32: =ROUND(Sheet1!I32*1000,1) -> 6.4 | J32: =ROUND(Sheet1!J32*1000,1) -> 5.3 | ... L32: =ROUND(Sheet1!L32*1000,1) -> 0.7
A33: flag->Salp | B33: (µmol N m-2 d-1) | C33: =ROUND(Sheet1!C33*1000,1) -> 2419.4 | D33: =ROUND(Sheet1!D33*1000,1) -> 630.7 | E33: =ROUND(Sheet1!E33*1000,1) -> 1194.6 | F33: =ROUND(Sheet1!F33*1000,1) -> 369.3 | G33: =ROUND(Sheet1!G33*1000,1) -> 42.4 | H33: =ROUND(Sheet1!H33*1000,1) -> 14.5 | I33: =ROUND(Sheet1!I33*1000,1) -> 1800.3 | J33: =ROUND(Sheet1!J33*1000,1) -> 405.6 | ... L33: =ROUND(Sheet1!L33*1000,1) -> 1.8
A34: flag->dom | B34: (µmol N m-2 d-1) | C34: =ROUND(Sheet1!C34*1000,1) -> 865.7 | D34: =ROUND(Sheet1!D34*1000,1) -> 456.3 | E34: =ROUND(Sheet1!E34*1000,1) -> 609.8 | F34: =ROUND(Sheet1!F34*1000,1) -> 277.2 | G34: =ROUND(Sheet1!G34*1000,1) -> 181 | H34: =ROUND(Sheet1!H34*1000,1) -> 96.1 | I34: =ROUND(Sheet1!I34*1000,1) -> 1476.6 | J34: =ROUND(Sheet1!J34*1000,1) -> 655.5 | ... L34: =ROUND(Sheet1!L34*1000,1) -> 149.5
A35: flag->sdet | B35: (µmol N m-2 d-1) | C35: =ROUND(Sheet1!C35*1000,1) -> 251.1 | D35: =ROUND(Sheet1!D35*1000,1) -> 157.7 | E35: =ROUND(Sheet1!E35*1000,1) -> 283.3 | F35: =ROUND(Sheet1!F35*1000,1) -> 159.2 | G35: =ROUND(Sheet1!G35*1000,1) -> 161 | H35: =ROUND(Sheet1!H35*1000,1) -> 107.4 | I35: =ROUND(Sheet1!I35*1000,1) -> 207.1 | J35: =ROUND(Sheet1!J35*1000,1) -> 134.6 | ... L35: =ROUND(Sheet1!L35*1000,1) -> 117.1
A36: hnf->mic | B36: (µmol N m-2 d-1) | C36: =ROUND(Sheet1!C36*1000,1) -> 200.3 | D36: =ROUND(Sheet1!D36*1000,1) -> 177.1 | E36: =ROUND(Sheet1!E36*1000,1) -> 64.4 | F36: =ROUND(Sheet1!F36*1000,1) -> 55.4 | G36: =ROUND(Sheet1!G36*1000,1) -> 83.8 | H36: =ROUND(Sheet1!H36*1000,1) -> 76 | I36: =ROUND(Sheet1!I36*1000,1) -> 173.8 | J36: =ROUND(Sheet1!J36*1000,1) -> 162.4 | ... L36: =ROUND(Sheet1!L36*1000,1) -> 117
A37: hnf->Meso | B37: (µmol N m-2 d-1) | C37: =ROUND(Sheet1!C37*1000,1) -> 331.1 | D37: =ROUND(Sheet1!D37*1000,1) -> 254.7 | E37: =ROUND(Sheet1!E37*1000,1) -> 292.4 | F37: =ROUND(Sheet1!F37*1000,1) -> 246.3 | G37: =ROUND(Sheet1!G37*1000,1) -> 1984 | H37: =ROUND(Sheet1!H37*1000,1) -> 791.6 | I37: =ROUND(Sheet1!I37*1000,1) -> 302 | J37: =ROUND(Sheet1!J37*1000,1) -> 235.9 | ... L37: =ROUND(Sheet1!L37*1000,1) -> 225.4
... A80: Macro->ldet | B80: (µmol N m-2 d-1) | C80: =ROUND(Sheet1!C80*1000,1) -> 40.8 | D80: =ROUND(Sheet1!D80*1000,1) -> 17 | E80: =ROUND(Sheet1!E80*1000,1) -> 117.3 | F80: =ROUND(Sheet1!F80*1000,1) -> 51.3 | G80: =ROUND(Sheet1!G80*1000,1) -> 25.4 | H80: =ROUND(Sheet1!H80*1000,1) -> 12 | I80: =ROUND(Sheet1!I80*1000,1) -> 37.4 | J80: =ROUND(Sheet1!J80*1000,1) -> 17.6 | ... L80: =ROUND(Sheet1!L80*1000,1) -> 65.3
A81: VMMacro->PiscivFish | B81: (µmol N m-2 d-1) | C81: =ROUND(Sheet1!C81*1000,1) -> 2.4 | D81: =ROUND(Sheet1!D81*1000,1) -> 1 | E81: =ROUND(Sheet1!E81*1000,1) -> 1.8 | F81: =ROUND(Sheet1!F81*1000,1) -> 0.8 | G81: =ROUND(Sheet1!G81*1000,1) -> 1.4 | H81: =ROUND(Sheet1!H81*1000,1) -> 0.6 | I81: =ROUND(Sheet1!I81*1000,1) -> 0.7 | J81: =ROUND(Sheet1!J81*1000,1) -> 0.3 | K81: =ROUND(Sheet1!K81*1000,2) -> 0.02 | L81: =ROUND(Sheet1!L81*1000,2) -> 0.01
A82: VMMacro->gel | B82: (µmol N m-2 d-1) | C82: =ROUND(Sheet1!C82*1000,1) -> 31 | D82: =ROUND(Sheet1!D82*1000,1) -> 11.6 | E82: =ROUND(Sheet1!E82*1000,1) -> 112 | F82: =ROUND(Sheet1!F82*1000,1) -> 40.4 | G82: =ROUND(Sheet1!G82*1000,1) -> 3.6 | H82: =ROUND(Sheet1!H82*1000,1) -> 2.7 | I82: =ROUND(Sheet1!I82*1000,1) -> 17.5 | J82: =ROUND(Sheet1!J82*1000,1) -> 6.1 | ... L82: =ROUND(Sheet1!L82*1000,1) -> 0.4
A83: VMMacro->Myct | B83: (µmol N m-2 d-1) | C83: =ROUND(Sheet1!C83*1000,1) -> 33.8 | D83: =ROUND(Sheet1!D83*1000,1) -> 10.1 | E83: =ROUND(Sheet1!E83*1000,1) -> 19.4 | F83: =ROUND(Sheet1!F83*1000,1) -> 8.3 | G83: =ROUND(Sheet1!G83*1000,1) -> 23.2 | H83: =ROUND(Sheet1!H83*1000,1) -> 5.1 | I83: =ROUND(Sheet1!I83*1000,1) -> 10.2 | J83: =ROUND(Sheet1!J83*1000,1) -> 3.3 | ... L83: =ROUND(Sheet1!L83*1000,1) -> 0.1
A84: VMMacro->HTL | B84: (µmol N m-2 d-1) | C84: =ROUND(Sheet1!C84*1000,1) -> 8.2 | D84: =ROUND(Sheet1!D84*1000,1) -> 3.4 | E84: =ROUND(Sheet1!E84*1000,1) -> 5.8 | F84: =ROUND(Sheet1!F84*1000,1) -> 2.7 | G84: =ROUND(Sheet1!G84*1000,1) -> 5.1 | H84: =ROUND(Sheet1!H84*1000,1) -> 2 | I84: =ROUND(Sheet1!I84*1000,1) -> 2.6 | J84: =ROUND(Sheet1!J84*1000,1) -> 1.1 | K84: =ROUND(Sheet1!K84*1000,1) -> 0.1 | L84: =ROUND(Sheet1!L84*1000,2) -> 0.03
A85: VMMacro->nh4 | B85: (µmol N m-2 d-1) | C85: =ROUND(Sheet1!C85*1000,1) -> 84.2 | D85: =ROUND(Sheet1!D85*1000,1) -> 57.1 | E85: =ROUND(Sheet1!E85*1000,1) -> 93.6 | F85: =ROUND(Sheet1!F85*1000,1) -> 63.6 | G85: =ROUND(Sheet1!G85*1000,1) -> 44.6 | H85: =ROUND(Sheet1!H85*1000,1) -> 26.6 | I85: =ROUND(Sheet1!I85*1000,1) -> 36.6 | J85: =ROUND(Sheet1!J85*1000,1) -> 24.6 | K85: =ROUND(Sheet1!K85*1000,1) -> 1.2 | L85: 3.1e-14
A86: VMMacro->dom | B86: (µmol N m-2 d-1) | C86: =ROUND(Sheet1!C86*1000,1) -> 44.7 | D86: =ROUND(Sheet1!D86*1000,1) -> 32.4 | E86: =ROUND(Sheet1!E86*1000,1) -> 56.5 | F86: =ROUND(Sheet1!F86*1000,1) -> 41.4 | G86: =ROUND(Sheet1!G86*1000,1) -> 20.8 | H86: =ROUND(Sheet1!H86*1000,1) -> 14.9 | I86: =ROUND(Sheet1!I86*1000,1) -> 19.1 | J86: =ROUND(Sheet1!J86*1000,1) -> 13.9 | K86: =ROUND(Sheet1!K86*1000,1) -> 0.6 | L86: 3.9e-15
A87: VMMacro->ldet | B87: (µmol N m-2 d-1) | C87: =ROUND(Sheet1!C87*1000,1) -> 109.5 | D87: =ROUND(Sheet1!D87*1000,1) -> 52.5 | E87: =ROUND(Sheet1!E87*1000,1) -> 206 | F87: =ROUND(Sheet1!F87*1000,1) -> 109.1 | G87: =ROUND(Sheet1!G87*1000,1) -> 45.1 | H87: =ROUND(Sheet1!H87*1000,1) -> 21.2 | I87: =ROUND(Sheet1!I87*1000,1) -> 46.3 | J87: =ROUND(Sheet1!J87*1000,1) -> 22.7 | ... L87: =ROUND(Sheet1!L87*1000,1) -> 0.5
A88: VMMacro->dnh4 | B88: (µmol N m-2 d-1) | C88: =ROUND(Sheet1!C88*1000,1) -> 83.5 | D88: =ROUND(Sheet1!D88*1000,1) -> 56.8 | E88: =ROUND(Sheet1!E88*1000,1) -> 96.3 | F88: =ROUND(Sheet1!F88*1000,1) -> 66.4 | G88: =ROUND(Sheet1!G88*1000,1) -> 37.2 | H88: =ROUND(Sheet1!H88*1000,1) -> 23.8 | I88: =ROUND(Sheet1!I88*1000,1) -> 33.3 | J88: =ROUND(Sheet1!J88*1000,1) -> 23.8 | K88: =ROUND(Sheet1!K88*1000,2) -> 0.04 | L88: 2.4e-16
A89: VMMacro->ddom | B89: (µmol N m-2 d-1) | C89: =ROUND(Sheet1!C89*1000,1) -> 44.9 | D89: =ROUND(Sheet1!D89*1000,1) -> 32.4 | E89: =ROUND(Sheet1!E89*1000,1) -> 52.9 | F89: =ROUND(Sheet1!F89*1000,1) -> 39.4 | G89: =ROUND(Sheet1!G89*1000,1) -> 20 | H89: =ROUND(Sheet1!H89*1000,1) -> 14.5 | I89: =ROUND(Sheet1!I89*1000,1) -> 18.5 | J89: =ROUND(Sheet1!J89*1000,1) -> 13.7 | K89: =ROUND(Sheet1!K89*1000,2) -> 0.03 | L89: 2.9e-16
A90: gel->Amph | B90: (µmol N m-2 d-1) | C90: =ROUND(Sheet1!C90*1000,1) -> 14.4 | D90: =ROUND(Sheet1!D90*1000,1) -> 4 | E90: =ROUND(Sheet1!E90*1000,1) -> 0.6 | F90: =ROUND(Sheet1!F90*1000,1) -> 0.3 | G90: =ROUND(Sheet1!G90*1000,2) -> 0.03 | H90: =ROUND(Sheet1!H90*1000,2) -> 0.01 | I90: =ROUND(Sheet1!I90*1000,1) -> 4.5 | J90: =ROUND(Sheet1!J90*1000,1) -> 0.4 | K90: =ROUND(Sheet1!K90*1000,1) -> 23.8 | L90: =ROUND(Sheet1!L90*1000,1) -> 3.9
A91: gel->Myct | B91: (µmol N m-2 d-1) | C91: =ROUND(Sheet1!C91*1000,1) -> 0.2 | D91: =ROUND(Sheet1!D91*1000,1) -> 0.1 | E91: =ROUND(Sheet1!E91*1000,1) -> 24.2 | F91: =ROUND(Sheet1!F91*1000,1) -> 2.8 | G91: =ROUND(Sheet1!G91*1000,1) -> 1.7 | H91: =ROUND(Sheet1!H91*1000,1) -> 0.1 | I91: =ROUND(Sheet1!I91*1000,1) -> 1.1 | J91: =ROUND(Sheet1!J91*1000,1) -> 0.3 | ... L91: =ROUND(Sheet1!L91*1000,1) -> 0.2
A92: gel->GelativFish | B92: (µmol N m-2 d-1) | C92: =ROUND(Sheet1!C92*1000,1) -> 0.1 | D92: =ROUND(Sheet1!D92*1000,2) -> 0.05 | E92: =ROUND(Sheet1!E92*1000,1) -> 9.5 | F92: =ROUND(Sheet1!F92*1000,1) -> 2.1 | G92: =ROUND(Sheet1!G92*1000,1) -> 0.6 | H92: =ROUND(Sheet1!H92*1000,1) -> 0.1 | I92: =ROUND(Sheet1!I92*1000,1) -> 0.5 | J92: =ROUND(Sheet1!J92*1000,1) -> 0.2 | K92: =ROUND(Sheet1!K92*1000,1) -> 0.3 | L92: =ROUND(Sheet1!L92*1000,1) -> 0.1
...

Sheet Sheet1 (3)
A1: Flow | B1: Units | C1: Cycle 1 | D1: Cycle 2 | E1: Cycle 3 | F1: Cycle 4 | G1: Cycle 5
A2: Upwelling | B2: (µmol N m-2 d-1) | C2: ='Sheet1 (2)'!C2&"±"&'Sheet1 (2)'!D2 -> 3075.1±652.3 | D2: ='Sheet1 (2)'!E2&"±"&'Sheet1 (2)'!F2 -> 3153.3±369 | E2: ='Sheet1 (2)'!G2&"±"&'Sheet1 (2)'!H2 -> 1422±515.9 | F2: ='Sheet1 (2)'!I2&"±"&'Sheet1 (2)'!J2 -> 2308.4±438.4 | G2: ='Sheet1 (2)'!K2&"±"&'Sheet1 (2)'!L2 -> 839.2±249.4
A3: NH4->NO3 | B3: (µmol N m-2 d-1) | C3: ='Sheet1 (2)'!C3&"±"&'Sheet1 (2)'!D3 -> 4400.3±2475 | D3: ='Sheet1 (2)'!E3&"±"&'Sheet1 (2)'!F3 -> 2271±1466.8 | E3: ='Sheet1 (2)'!G3&"±"&'Sheet1 (2)'!H3 -> 2562.1±2147.1 | F3: ='Sheet1 (2)'!I3&"±"&'Sheet1 (2)'!J3 -> 3222±1868.8 | G3: ='Sheet1 (2)'!K3&"±"&'Sheet1 (2)'!L3 -> 1798.3±1133.8
A4: NH4->Pico | B4: (µmol N m-2 d-1) | C4: ='Sheet1 (2)'!C4&"±"&'Sheet1 (2)'!D4 -> 1823.1±1162.4 | D4: ='Sheet1 (2)'!E4&"±"&'Sheet1 (2)'!F4 -> 2218.7±1439.1 | E4: ='Sheet1 (2)'!G4&"±"&'Sheet1 (2)'!H4 -> 6141.8±2393.4 | F4: ='Sheet1 (2)'!I4&"±"&'Sheet1 (2)'!J4 -> 1281.9±754 | G4: ='Sheet1 (2)'!K4&"±"&'Sheet1 (2)'!L4 -> 1922.7±1090.2
A5: NH4->dtm | B5: (µmol N m-2 d-1) | C5: ='Sheet1 (2)'!C5&"±"&'Sheet1 (2)'!D5 -> 3112.2±1992.5 | D5: ='Sheet1 (2)'!E5&"±"&'Sheet1 (2)'!F5 -> 672.9±432 | E5: ='Sheet1 (2)'!G5&"±"&'Sheet1 (2)'!H5 -> 361.8±256.2 | F5: ='Sheet1 (2)'!I5&"±"&'Sheet1 (2)'!J5 -> 279.4±171.5 | G5: ='Sheet1 (2)'!K5&"±"&'Sheet1 (2)'!L5 -> 317.7±208.3
A6: NH4->flag | B6: (µmol N m-2 d-1) | C6: ='Sheet1 (2)'!C6&"±"&'Sheet1 (2)'!D6 -> 1787.8±1131.4 | D6: ='Sheet1 (2)'!E6&"±"&'Sheet1 (2)'!F6 -> 1071.1±724.1 | E6: ='Sheet1 (2)'!G6&"±"&'Sheet1 (2)'!H6 -> 348.3±249.4 | F6: ='Sheet1 (2)'!I6&"±"&'Sheet1 (2)'!J6 -> 2834.6±1798.2 | G6: ='Sheet1 (2)'!K6&"±"&'Sheet1 (2)'!L6 -> 550.8±389.4
A7: NO3->Pico | B7: (µmol N m-2 d-1) | C7: ='Sheet1 (2)'!C7&"±"&'Sheet1 (2)'!D7 -> 2161.4±1179.5 | D7: ='Sheet1 (2)'!E7&"±"&'Sheet1 (2)'!F7 -> 3354.6±1469.8 | E7: ='Sheet1 (2)'!G7&"±"&'Sheet1 (2)'!H7 -> 3083±2386 | F7: ='Sheet1 (2)'!I7&"±"&'Sheet1 (2)'!J7 -> 1328.3±753.7 | G7: ='Sheet1 (2)'!K7&"±"&'Sheet1 (2)'!L7 -> 1735.4±1094.5
A8: NO3->dtm | B8: (µmol N m-2 d-1) | C8: ='Sheet1 (2)'!C8&"±"&'Sheet1 (2)'!D8 -> 3478.7±2017 | D8: ='Sheet1 (2)'!E8&"±"&'Sheet1 (2)'!F8 -> 702±436.4 | E8: ='Sheet1 (2)'!G8&"±"&'Sheet1 (2)'!H8 -> 523.5±265.6 | F8: ='Sheet1 (2)'!I8&"±"&'Sheet1 (2)'!J8 -> 283.4±172.6 | G8: ='Sheet1 (2)'!K8&"±"&'Sheet1 (2)'!L8 -> 350.1±212.6
A9: NO3->flag | B9: (µmol N m-2 d-1) | C9: ='Sheet1 (2)'!C9&"±"&'Sheet1 (2)'!D9 -> 1835.4±1145.2 | D9: ='Sheet1 (2)'!E9&"±"&'Sheet1 (2)'!F9 -> 1367.7±766 | E9: ='Sheet1 (2)'!G9&"±"&'Sheet1 (2)'!H9 -> 377.5±257.3 | F9: ='Sheet1 (2)'!I9&"±"&'Sheet1 (2)'!J9 -> 3918.7±1817.3 | G9: ='Sheet1 (2)'!K9&"±"&'Sheet1 (2)'!L9 -> 552±378.8
A10: bac->flag | B10: (µmol N m-2 d-1) | C10: ='Sheet1 (2)'!C10&"±"&'Sheet1 (2)'!D10 -> 306.1±214.9 | D10: ='Sheet1 (2)'!E10&"±"&'Sheet1 (2)'!F10 -> 350.2±227.3 | E10: ='Sheet1 (2)'!G10&"±"&'Sheet1 (2)'!H10 -> 211.5±166.7 | F10: ='Sheet1 (2)'!I10&"±"&'Sheet1 (2)'!J10 -> 280.1±212.2 | G10: ='Sheet1 (2)'!K10&"±"&'Sheet1 (2)'!L10 -> 181.5±130.1
A11: bac->hnf | B11: (µmol N m-2 d-1) | C11: ='Sheet1 (2)'!C11&"±"&'Sheet1 (2)'!D11 -> 404.2±241.6 | D11: ='Sheet1 (2)'!E11&"±"&'Sheet1 (2)'!F11 -> 389.1±235.4 | E11: ='Sheet1 (2)'!G11&"±"&'Sheet1 (2)'!H11 -> 560.7±242 | F11: ='Sheet1 (2)'!I11&"±"&'Sheet1 (2)'!J11 -> 475.7±267.5 | G11: ='Sheet1 (2)'!K11&"±"&'Sheet1 (2)'!L11 -> 223.8±144.3
A12: bac->mic | B12: (µmol N m-2 d-1) | C12: ='Sheet1 (2)'!C12&"±"&'Sheet1 (2)'!D12 -> 177.9±154.4 | D12: ='Sheet1 (2)'!E12&"±"&'Sheet1 (2)'!F12 -> 89.8±73.5 | E12: ='Sheet1 (2)'!G12&"±"&'Sheet1 (2)'!H12 -> 145.2±106.3 | F12: ='Sheet1 (2)'!I12&"±"&'Sheet1 (2)'!J12 -> 225.1±189.6 | G12: ='Sheet1 (2)'!K12&"±"&'Sheet1 (2)'!L12 -> 132.2±108.6
A13: bac->nh4 | B13: (µmol N m-2 d-1) | C13: ='Sheet1 (2)'!C13&"±"&'Sheet1 (2)'!D13 -> 6640.5±1503.8 | D13: ='Sheet1 (2)'!E13&"±"&'Sheet1 (2)'!F13 -> 3356±700.3 | E13: ='Sheet1 (2)'!G13&"±"&'Sheet1 (2)'!H13 -> 3777.3±600.3 | F13: ='Sheet1 (2)'!I13&"±"&'Sheet1 (2)'!J13 -> 3647.8±681.9 | G13: ='Sheet1 (2)'!K13&"±"&'Sheet1 (2)'!L13 -> 2391.8±514.8
... A21: dtm->Meso | B21: (µmol N m-2 d-1) | C21: ='Sheet1 (2)'!C21&"±"&'Sheet1 (2)'!D21 -> 554±302.1 | D21: ='Sheet1 (2)'!E21&"±"&'Sheet1 (2)'!F21 -> 152.8±137 | E21: ='Sheet1 (2)'!G21&"±"&'Sheet1 (2)'!H21 -> 82.8±71.2 | F21: ='Sheet1 (2)'!I21&"±"&'Sheet1 (2)'!J21 -> 88.6±70.7 | G21: ='Sheet1 (2)'!K21&"±"&'Sheet1 (2)'!L21 -> 96±82.2
A22: dtm->VMMeso | B22: (µmol N m-2 d-1) | C22: NA | D22: ='Sheet1 (2)'!E22&"±"&'Sheet1 (2)'!F22 -> 141.8±124.8 | E22: ='Sheet1 (2)'!G22&"±"&'Sheet1 (2)'!H22 -> 56.7±43.7 | F22: ='Sheet1 (2)'!I22&"±"&'Sheet1 (2)'!J22 -> 62.7±52.6 | G22: ='Sheet1 (2)'!K22&"±"&'Sheet1 (2)'!L22 -> 89.7±75.9
A23: dtm->Macro | B23: (µmol N m-2 d-1) | C23: ='Sheet1 (2)'!C23&"±"&'Sheet1 (2)'!D23 -> 19.1±15 | D23: ='Sheet1 (2)'!E23&"±"&'Sheet1 (2)'!F23 -> 41.8±35.2 | E23: ='Sheet1 (2)'!G23&"±"&'Sheet1 (2)'!H23 -> 7.3±5.8 | F23: ='Sheet1 (2)'!I23&"±"&'Sheet1 (2)'!J23 -> 10.1±8.2 | G23: ='Sheet1 (2)'!K23&"±"&'Sheet1 (2)'!L23 -> 20.4±16.2
A24: dtm->VMMacro | B24: (µmol N m-2 d-1) | C24: ='Sheet1 (2)'!C24&"±"&'Sheet1 (2)'!D24 -> 10.2±8.1 | D24: ='Sheet1 (2)'!E24&"±"&'Sheet1 (2)'!F24 -> 33±27.2 | E24: ='Sheet1 (2)'!G24&"±"&'Sheet1 (2)'!H24 -> 5.1±4.1 | F24: ='Sheet1 (2)'!I24&"±"&'Sheet1 (2)'!J24 -> 6.5±5.4 | G24: ='Sheet1 (2)'!K24&"±"&'Sheet1 (2)'!L24 -> 0.8±0.7
A25: dtm->Salp | B25: (µmol N m-2 d-1) | C25: ='Sheet1 (2)'!C25&"±"&'Sheet1 (2)'!D25 -> 1003.8±410.9 | D25: ='Sheet1 (2)'!E25&"±"&'Sheet1 (2)'!F25 -> 151.5±132 | E25: ='Sheet1 (2)'!G25&"±"&'Sheet1 (2)'!H25 -> 0.02±0.01 | F25: ='Sheet1 (2)'!I25&"±"&'Sheet1 (2)'!J25 -> 0.01±0.005 | G25: ='Sheet1 (2)'!K25&"±"&'Sheet1 (2)'!L25 -> 1.5±1.1
A26: dtm->dom | B26: (µmol N m-2 d-1) | C26: ='Sheet1 (2)'!C26&"±"&'Sheet1 (2)'!D26 -> 1560.8±840.5 | D26: ='Sheet1 (2)'!E26&"±"&'Sheet1 (2)'!F26 -> 326±170.7 | E26: ='Sheet1 (2)'!G26&"±"&'Sheet1 (2)'!H26 -> 124.1±80.9 | F26: ='Sheet1 (2)'!I26&"±"&'Sheet1 (2)'!J26 -> 111±60.5 | G26: ='Sheet1 (2)'!K26&"±"&'Sheet1 (2)'!L26 -> 145.8±78.6
A27: dtm->mdet | B27: (µmol N m-2 d-1) | C27: ='Sheet1 (2)'!C27&"±"&'Sheet1 (2)'!D27 -> 2576±998.4 | D27: ='Sheet1 (2)'!E27&"±"&'Sheet1 (2)'!F27 -> 460.1±234.9 | E27: ='Sheet1 (2)'!G27&"±"&'Sheet1 (2)'!H27 -> 514.4±173.3 | F27: ='Sheet1 (2)'!I27&"±"&'Sheet1 (2)'!J27 -> 151.1±103.4 | G27: ='Sheet1 (2)'!K27&"±"&'Sheet1 (2)'!L27 -> 218.2±135
A28: flag->mic | B28: (µmol N m-2 d-1) | C28: ='Sheet1 (2)'!C28&"±"&'Sheet1 (2)'!D28 -> 493.6±366.2 | D28: ='Sheet1 (2)'!E28&"±"&'Sheet1 (2)'!F28 -> 99.4±78.1 | E28: ='Sheet1 (2)'!G28&"±"&'Sheet1 (2)'!H28 -> 427.7±183.3 | F28: ='Sheet1 (2)'!I28&"±"&'Sheet1 (2)'!J28 -> 3518.3±589.7 | G28: ='Sheet1 (2)'!K28&"±"&'Sheet1 (2)'!L28 -> 587.7±271.3
A29: flag->Meso | B29: (µmol N m-2 d-1) | C29: ='Sheet1 (2)'!C29&"±"&'Sheet1 (2)'!D29 -> 429.8±287.4 | D29: ='Sheet1 (2)'!E29&"±"&'Sheet1 (2)'!F29 -> 845.3±293.1 | E29: ='Sheet1 (2)'!G29&"±"&'Sheet1 (2)'!H29 -> 254.9±109.1 | F29: ='Sheet1 (2)'!I29&"±"&'Sheet1 (2)'!J29 -> 290.7±125.2 | G29: ='Sheet1 (2)'!K29&"±"&'Sheet1 (2)'!L29 -> 348.7±154.2
A30: flag->VMMeso | B30: (µmol N m-2 d-1) | C30: NA | D30: ='Sheet1 (2)'!E30&"±"&'Sheet1 (2)'!F30 -> 512.1±222.6 | E30: ='Sheet1 (2)'!G30&"±"&'Sheet1 (2)'!H30 -> 94.6±49.9 | F30: ='Sheet1 (2)'!I30&"±"&'Sheet1 (2)'!J30 -> 112.1±78.7 | G30: ='Sheet1 (2)'!K30&"±"&'Sheet1 (2)'!L30 -> 251.8±127.4
A31: flag->Macro | B31: (µmol N m-2 d-1) | C31: ='Sheet1 (2)'!C31&"±"&'Sheet1 (2)'!D31 -> 18.9±14.8 | D31: ='Sheet1 (2)'!E31&"±"&'Sheet1 (2)'!F31 -> 56±41.2 | E31: ='Sheet1 (2)'!G31&"±"&'Sheet1 (2)'!H31 -> 8.9±6.9 | F31: ='Sheet1 (2)'!I31&"±"&'Sheet1 (2)'!J31 -> 9.6±7.7 | G31: ='Sheet1 (2)'!K31&"±"&'Sheet1 (2)'!L31 -> 23.5±17.7
A32: flag->VMMacro | B32: (µmol N m-2 d-1) | C32: ='Sheet1 (2)'!C32&"±"&'Sheet1 (2)'!D32 -> 10.2±8.1 | D32: ='Sheet1 (2)'!E32&"±"&'Sheet1 (2)'!F32 -> 39.4±30.5 | E32: ='Sheet1 (2)'!G32&"±"&'Sheet1 (2)'!H32 -> 5.6±4.3 | F32: ='Sheet1 (2)'!I32&"±"&'Sheet1 (2)'!J32 -> 6.4±5.3 | G32: ='Sheet1 (2)'!K32&"±"&'Sheet1 (2)'!L32 -> 0.8±0.7
A33: flag->Salp | B33: (µmol N m-2 d-1) | C33: ='Sheet1 (2)'!C33&"±"&'Sheet1 (2)'!D33 -> 2419.4±630.7 | D33: ='Sheet1 (2)'!E33&"±"&'Sheet1 (2)'!F33 -> 1194.6±369.3 | E33: ='Sheet1 (2)'!G33&"±"&'Sheet1 (2)'!H33 -> 42.4±14.5 | F33: ='Sheet1 (2)'!I33&"±"&'Sheet1 (2)'!J33 -> 1800.3±405.6 | G33: ='Sheet1 (2)'!K33&"±"&'Sheet1 (2)'!L33 -> 7.8±1.8
A34: flag->dom | B34: (µmol N m-2 d-1) | C34: ='Sheet1 (2)'!C34&"±"&'Sheet1 (2)'!D34 -> 865.7±456.3 | D34: ='Sheet1 (2)'!E34&"±"&'Sheet1 (2)'!F34 -> 609.8±277.2 | E34: ='Sheet1 (2)'!G34&"±"&'Sheet1 (2)'!H34 -> 181±96.1 | F34: ='Sheet1 (2)'!I34&"±"&'Sheet1 (2)'!J34 -> 1476.6±655.5 | G34: ='Sheet1 (2)'!K34&"±"&'Sheet1 (2)'!L34 -> 273.7±149.5
A35: flag->sdet | B35: (µmol N m-2 d-1) | C35: ='Sheet1 (2)'!C35&"±"&'Sheet1 (2)'!D35 -> 251.1±157.7 | D35: ='Sheet1 (2)'!E35&"±"&'Sheet1 (2)'!F35 -> 283.3±159.2 | E35: ='Sheet1 (2)'!G35&"±"&'Sheet1 (2)'!H35 -> 161±107.4 | F35: ='Sheet1 (2)'!I35&"±"&'Sheet1 (2)'!J35 -> 207.1±134.6 | G35: ='Sheet1 (2)'!K35&"±"&'Sheet1 (2)'!L35 -> 180.5±117.1
A36: hnf->mic | B36: (µmol N m-2 d-1) | C36: ='Sheet1 (2)'!C36&"±"&'Sheet1 (2)'!D36 -> 200.3±177.1 | D36: ='Sheet1 (2)'!E36&"±"&'Sheet1 (2)'!F36 -> 64.4±55.4 | E36: ='Sheet1 (2)'!G36&"±"&'Sheet1 (2)'!H36 -> 83.8±76 | F36: ='Sheet1 (2)'!I36&"±"&'Sheet1 (2)'!J36 -> 173.8±162.4 | G36: ='Sheet1 (2)'!K36&"±"&'Sheet1 (2)'!L36 -> 125.8±117
A37: hnf->Meso | B37: (µmol N m-2 d-1) | C37: ='Sheet1 (2)'!C37&"±"&'Sheet1 (2)'!D37 -> 331.1±254.7 | D37: ='Sheet1 (2)'!E37&"±"&'Sheet1 (2)'!F37 -> 292.4±246.3 | E37: ='Sheet1 (2)'!G37&"±"&'Sheet1 (2)'!H37 -> 1984±791.6 | F37: ='Sheet1 (2)'!I37&"±"&'Sheet1 (2)'!J37 -> 302±235.9 | G37: ='Sheet1 (2)'!K37&"±"&'Sheet1 (2)'!L37 -> 307±225.4
A38: hnf->VMMeso | B38: (µmol N m-2 d-1) | C38: NA | D38: ='Sheet1 (2)'!E38&"±"&'Sheet1 (2)'!F38 -> 902.5±371.6 | E38: ='Sheet1 (2)'!G38&"±"&'Sheet1 (2)'!H38 -> 2109.7±800.7 | F38: ='Sheet1 (2)'!I38&"±"&'Sheet1 (2)'!J38 -> 322.3±248.3 | G38: ='Sheet1 (2)'!K38&"±"&'Sheet1 (2)'!L38 -> 621±287.6
A39: hnf->Macro | B39: (µmol N m-2 d-1) | C39: ='Sheet1 (2)'!C39&"±"&'Sheet1 (2)'!D39 -> 26.6±21.8 | D39: ='Sheet1 (2)'!E39&"±"&'Sheet1 (2)'!F39 -> 86.8±67 | E39: ='Sheet1 (2)'!G39&"±"&'Sheet1 (2)'!H39 -> 16.8±13.8 | F39: ='Sheet1 (2)'!I39&"±"&'Sheet1 (2)'!J39 -> 20.7±18 | G39: ='Sheet1 (2)'!K39&"±"&'Sheet1 (2)'!L39 -> 109.3±88.5
A40: hnf->VMMacro | B40: (µmol N m-2 d-1) | C40: ='Sheet1 (2)'!C40&"±"&'Sheet1 (2)'!D40 -> 157±106.6 | D40: ='Sheet1 (2)'!E40&"±"&'Sheet1 (2)'!F40 -> 282.8±177.7 | E40: ='Sheet1 (2)'!G40&"±"&'Sheet1 (2)'!H40 -> 53.1±28.1 | F40: ='Sheet1 (2)'!I40&"±"&'Sheet1 (2)'!J40 -> 46.8±36.4 | G40: ='Sheet1 (2)'!K40&"±"&'Sheet1 (2)'!L40 -> 0.9±0.7
A41: hnf->Salp | B41: (µmol N m-2 d-1) | C41: ='Sheet1 (2)'!C41&"±"&'Sheet1 (2)'!D41 -> 345±263.7 | D41: ='Sheet1 (2)'!E41&"±"&'Sheet1 (2)'!F41 -> 165.7±152.4 | E41: ='Sheet1 (2)'!G41&"±"&'Sheet1 (2)'!H41 -> 9.8±7.1 | F41: ='Sheet1 (2)'!I41&"±"&'Sheet1 (2)'!J41 -> 143.4±129 | G41: ='Sheet1 (2)'!K41&"±"&'Sheet1 (2)'!L41 -> 0.6±0.5
A42: hnf->nh4 | B42: (µmol N m-2 d-1) | C42: ='Sheet1 (2)'!C42&"±"&'Sheet1 (2)'!D42 -> 993.1±302.3 | D42: ='Sheet1 (2)'!E42&"±"&'Sheet1 (2)'!F42 -> 1109.2±204.3 | E42: ='Sheet1 (2)'!G42&"±"&'Sheet1 (2)'!H42 -> 2803.9±400.8 | F42: ='Sheet1 (2)'!I42&"±"&'Sheet1 (2)'!J42 -> 797.5±230.7 | G42: ='Sheet1 (2)'!K42&"±"&'Sheet1 (2)'!L42 -> 833.2±177.6
A43: hnf->dom | B43: (µmol N m-2 d-1) | C43: ='Sheet1 (2)'!C43&"±"&'Sheet1 (2)'!D43 -> 546.3±187.3 | D43: ='Sheet1 (2)'!E43&"±"&'Sheet1 (2)'!F43 -> 623±146.6 | E43: ='Sheet1 (2)'!G43&"±"&'Sheet1 (2)'!H43 -> 1554.5±309.3 | F43: ='Sheet1 (2)'!I43&"±"&'Sheet1 (2)'!J43 -> 450.7±151.2 | G43: ='Sheet1 (2)'!K43&"±"&'Sheet1 (2)'!L43 -> 470.7±124.6
A44: hnf->sdet | B44: (µmol N m-2 d-1) | C44: ='Sheet1 (2)'!C44&"±"&'Sheet1 (2)'!D44 -> 801.1±357.8 | D44: ='Sheet1 (2)'!E44&"±"&'Sheet1 (2)'!F44 -> 1229.8±336.3 | E44: ='Sheet1 (2)'!G44&"±"&'Sheet1 (2)'!H44 -> 3199.4±1002.3 | F44: ='Sheet1 (2)'!I44&"±"&'Sheet1 (2)'!J44 -> 765.2±333.3 | G44: ='Sheet1 (2)'!K44&"±"&'Sheet1 (2)'!L44 -> 878.3±325.3
A45: mic->Meso | B45: (µmol N m-2 d-1) | C45: ='Sheet1 (2)'!C45&"±"&'Sheet1 (2)'!D45 -> 312.5±215.1 | D45: ='Sheet1 (2)'!E45&"±"&'Sheet1 (2)'!F45 -> 38.3±32.9 | E45: ='Sheet1 (2)'!G45&"±"&'Sheet1 (2)'!H45 -> 82±56.3 | F45: ='Sheet1 (2)'!I45&"±"&'Sheet1 (2)'!J45 -> 830±478.7 | G45: ='Sheet1 (2)'!K45&"±"&'Sheet1 (2)'!L45 -> 167.2±123.1
A46: mic->VMMeso | B46: (µmol N m-2 d-1) | C46: NA | D46: ='Sheet1 (2)'!E46&"±"&'Sheet1 (2)'!F46 -> 45.2±37.2 | E46: ='Sheet1 (2)'!G46&"±"&'Sheet1 (2)'!H46 -> 151.1±42.9 | F46: ='Sheet1 (2)'!I46&"±"&'Sheet1 (2)'!J46 -> 929.8±495.4 | G46: ='Sheet1 (2)'!K46&"±"&'Sheet1 (2)'!L46 -> 225.4±139.2
A47: mic->Macro | B47: (µmol N m-2 d-1) | C47: ='Sheet1 (2)'!C47&"±"&'Sheet1 (2)'!D47 -> 26.1±21.4 | D47: ='Sheet1 (2)'!E47&"±"&'Sheet1 (2)'!F47 -> 33.2±28.7 | E47: ='Sheet1 (2)'!G47&"±"&'Sheet1 (2)'!H47 -> 16.7±13.6 | F47: ='Sheet1 (2)'!I47&"±"&'Sheet1 (2)'!J47 -> 25.3±22.6 | G47: ='Sheet1 (2)'!K47&"±"&'Sheet1 (2)'!L47 -> 92.9±74.8
...
